File: Book1 Processed.csv
Time (s),Temp. (Cel),Displacement (m),Load (N),Displacement Rate (m/s),Strain,Strain Rate (1/s),Stress (Pa)
8.0,23.1932773590088,6.609562635421749e-07,0.0011520144647695102,0.0001781845092773436,6.1030125904171275e-05,0.016452863275839665,88.48037363821123
14.0,23.2702388763428,6.83119654655457e-07,0.0007627363302417099,0.0001101150512695314,6.307660707806619e-05,0.010167594761729582,58.58189940412519
20.0,23.3557357788086,6.266239881515499e-07,0.0005690049158746374,2.323150634765628e-05,5.786001737318096e-05,0.0021451067726367752,43.702374491139594
26.0,23.430233001709,5.92768549919128e-07,0.00010539817413669121,-7.74078369140628e-05,5.47339381273433e-05,-0.007147538034539501,8.095097859960923
32.0,23.4968700408936,5.319050550460819e-07,-0.00010819910256736905,-7.614898681640638e-05,4.911404017046001e-05,-0.007031300721736507,-8.310222931441556
41.0,23.5889701843262,6.05762214660645e-05,0.046752908527779594,0.03134186279296877,0.005593372249867451,2.8939854841153063,3590.8531895376036
49.0,23.6838970184326,0.000130132431030273,0.09981455713477126,0.03124071899414064,0.01201592160944349,2.8846462598467806,7666.248627862617
58.0,23.7662525177002,0.00020094026184081998,0.15278995369172121,0.025482945556640636,0.018554040797859644,2.3529958962733732,11735.019484771216
66.0,23.8486080169678,0.000271320190429688,0.20433325291423798,0.03141052734375,0.02505264916248273,2.900325701177285,15693.7982269
75.0,23.917760848999,0.00034139093017578103,0.2550052965412137,0.025108247680664036,0.03152270823414414,2.3183977544472794,19585.660256621635
83.0,23.9941425323486,0.0004129521484375,0.3059674126630781,0.031915085449218776,0.03813039228416435,2.946914630583451,23499.801279806306
92.0,24.0598373413086,0.00048303143310546895,0.3551005083541872,0.02551256652832032,0.04460124036061578,2.355730981377684,27273.464543332353
100.0,24.1198749542236,0.000554601806640625,0.40460882033672285,0.031823503417968774,0.05120976977291089,2.938458302674863,31075.946262421112
109.0,24.1755123138428,0.000625584411621094,0.45297483626155893,0.025583992309570317,0.05776402692715549,2.3623261597017833,34790.6940293056
117.0,24.2305202484131,0.00069503125,0.4995108217018131,0.0313522998046875,0.06417647737765465,2.8949491971087253,38364.88645943265
125.00000000000001,24.2789268493652,0.000765082214355469,0.5460731059509277,0.03125306030273436,0.0706447104668023,2.8857858081933845,41941.09876735236
134.0,24.3238754272461,0.000836163818359375,0.5932381678773884,0.03190528198242186,0.0772081088051131,2.946009416659451,45563.60736385472
142.0,24.3641109466553,0.000906977783203125,0.6396674617061616,0.03210183471679686,0.08374679438625345,2.9641583302674843,49129.605353775856
151.0,24.4062309265137,0.000976955871582031,0.6847032927593233,0.032521625976562496,0.0902082983916926,3.00292021944252,52588.57855294342
158.0,24.4367198944092,0.00100017401123047,0.6967083436149598,-0.0003578338623046878,0.09235217093540812,-0.0330409845156683,53510.625469658975
164.0,24.459981918335,0.000999943359375,0.6948618904033664,-4.57763671875e-07,0.09233087344182823,-4.226811374653739e-05,53368.8087867409
172.0,24.4983291625977,0.000945190734863281,0.6542390219226839,-0.03160771362304686,0.08727522944259287,-2.918533113854742,50248.772805121655
181.0,24.522533416748,0.000875123107910156,0.6048274132415776,-0.024504402465820318,0.08080545779410488,-2.2626410402419497,46453.71837492916
189.0,24.5536518096924,0.0008048348388671879,0.55545399955883,-0.03130897338867186,0.07431531291479111,-2.890948604678842,42661.59750835868
198.0,24.5743980407715,0.000733605773925781,0.505637060018539,-0.025307191772460963,0.06773829860810535,-2.336767476681529,38835.41167577105
206.0,24.5957717895508,0.000663289855957031,0.45628597974815377,-0.031749792480468775,0.06124560073472123,-2.931652121926941,35045.00612505022
214.0,24.6221752166748,0.000593733947753906,0.40701690088462833,-0.032071640624999995,0.054823079201653364,-2.9613703254847636,31260.898685455326
223.0,24.6400928497314,0.000523832763671875,0.35766447387580885,-0.031720488281249994,0.04836867623932363,-2.92894628635734,27470.389698602834
231.0,24.6542377471924,0.00045355322265625,0.30770317145729104,-0.031813410644531276,0.041879337272045236,-2.93752637530298,23633.116087349543
240,24.6759262084961,0.000384062103271484,0.2577291872518541,-0.02509201538085936,0.0354627980860096,-2.316898927133828,19794.86845252336
248.00000000000003,24.6897563934326,0.00031404516601562496,0.20708972721309651,-0.03125184448242186,0.0289977069266505,-2.885673544083274,15905.509002541976
256.0,24.6988735198975,0.00024391200256347698,0.1556360235058312,-0.03193884155273436,0.022521883893211168,-2.9491081766144376,11953.611636392567
265.0,24.7073593139648,0.000173808517456055,0.10391232679963137,-0.031851416015624995,0.016048801242479684,-2.9410356431786697,7980.97748077046
273.0,24.7164745330811,0.000103041938781738,0.051119721928024296,-0.031827004394531275,0.009514491115580608,-2.938781569208797,3926.24592381139
282.0,24.7186756134033,3.3647167205810495e-05,-0.0012559604308038997,-0.025451304931640637,0.0031068483107858256,-2.3500743242512128,-96.46393477756527
289.0,24.7259044647217,4.92499232292175e-07,-0.025352463245201115,0.0002779312133789064,4.547546004544552e-05,0.025663085261210188,-1947.1937976344943
295.0,24.7281055450439,4.4498717784881594e-07,-0.024260616102755025,-9.986114501953139e-05,4.108838207283619e-05,-0.009220789013807145,-1863.3345701040728
300,24.7359638214111,4.5381820201873797e-07,-0.023505918848192732,-0.0001314697265625,4.190380443386315e-05,-0.012139402268005538,-1805.3701112283206
306.0,24.7299919128418,4.3669021129608195e-07,-0.02278343342592717,-0.00014389801025390642,4.032227251118023e-05,-0.013286981556224044,-1749.879679410689
312.0,24.7334499359131,5.38599848747253e-07,-0.022003683563172845,3.45611572265625e-05,4.973221133400304e-05,0.0031912425878635733,-1689.9910570793277
318.0,24.7299919128418,6.020573377609249e-07,-0.021563419337773282,3.440093994140628e-05,5.5591628602116794e-05,0.0031764487480522878,-1656.1766004434166
324.0,24.7318782806396,4.6491897106170697e-07,-0.021494693592071505,-9.13009643554686e-05,4.29288061922167e-05,-0.00843037528674687,-1650.8981253511142
329.0,24.7315635681152,6.12643122673035e-07,-0.020856751077842715,1.7601013183593777e-05,5.6569078732505534e-05,0.0016252089735543651,-1601.901004442605
335.0,24.7243328094482,5.13937830924988e-07,-0.020754361547470054,-7.76824951171878e-05,4.74550167059084e-05,-0.007172898902787423,-1594.036985212754
341.0,24.7218189239502,5.65989375114441e-07,-0.020411974343454837,-6.27822875976564e-05,5.2261253473170906e-05,-0.005797071800337617,-1567.7399649350875
347.0,24.7249622344971,5.75602412223816e-07,-0.02000262431175711,5.26885986328125e-05,5.314888386184819e-05,0.004865059892226454,-1536.2998703346475
353.0,24.7243328094482,5.10599970817566e-07,-0.019896447079539324,-7.73849487304686e-05,4.714681170983988e-05,-0.007145424628852133,-1528.1449369845873
358.0,24.7255916595459,5.512455701827999e-07,-0.01979680714013581,-9.1278076171875e-05,5.0899867976251144e-05,-0.008428261881059556,-1520.4920998568211
364.0,24.7202472686768,6.191281080245969e-07,-0.01937438369185332,0.0002691650390625,5.716787701058143e-05,0.024853650882963988,-1488.0479026001015
370.0,24.7145900726318,5.333737134933469e-07,-0.019555614703750647,-7.305908203124999e-05,4.924965036873009e-05,-0.006745990953947367,-1501.9673351575
376.0,24.7083034515381,6.8725860118866e-07,-0.019054402380913465,0.00015545654296874998,6.345878127319114e-05,0.014354251428324097,-1463.4717650471173
382.0,24.6976146697998,6.68528437614441e-07,-0.018974368474733858,0.0002142333984375,6.17293109523953e-05,0.0197814772333795,-1457.3247676446897
387.0,24.6925868988037,6.400707960128779e-07,-0.019018145657140065,5.257415771484378e-05,5.9101643214485494e-05,0.004854492863789822,-1460.6870704408652
393.0,24.6866130828857,6.778935194015499e-07,-0.01869002195627689,0.00029376983642578143,6.259404611279315e-05,0.027125561996840387,-1435.4855573177335
399.0,24.6866130828857,5.353382825851441e-07,-0.018799518103784368,-4.2572021484374995e-06,4.9431051023559e-05,-0.0003930934578427977,-1443.8953996762189
406.0,24.6840991973877,1.9286242723465e-06,-0.01765938126994375,0.001156831398010254,0.0001780816502628347,0.10681730360205484,-1356.3272864780147
414.0,24.6671257019043,7.15924453735352e-05,0.03683826927770372,0.031701229248046865,0.006610567439846278,2.927167982275795,2829.360159577859
423.0,24.6561241149902,0.00014249430847167998,0.09100069652161599,0.0317011962890625,0.01315736920329455,2.927164938971606,6989.300808111828
431.0,24.6407222747803,0.00021355722045898398,0.14449047234148973,0.032017565917968775,0.019719041593627328,2.9563772777441155,11097.578520851746
440.0,24.6281490325928,0.00028292352294921895,0.19559364996194886,0.031236906738281275,0.026124055673981433,2.8842942509955005,15022.553760518347
448.0,24.623119354248,0.000353193939208984,0.2468813213954921,0.03198652954101564,0.03261255209685909,2.9535114996320995,18961.699031911838
457.0,24.6130599975586,0.00042411395263671896,0.2978074870830539,0.02613307067871096,0.039161029791017446,2.4130259167784818,22873.078885027182
465.0,24.5986003875732,0.000494028533935547,0.34712785423526726,0.031767989501953135,0.04561666980014284,2.933332363984592,26661.125517301636
474.0,24.5872859954834,0.00056513427734375,0.3966266642299648,0.02608467590332032,0.05218229707698522,2.4085573317931965,30462.87743701727
482.0,24.5665397644043,0.000635787170410156,0.44478995861110654,0.03174042114257814,0.058706109917835265,2.930786809102321,34162.05519286533
491.0,24.553337097168,0.0007060223999023439,0.49255806008071934,0.02543177673339846,0.06519135733170303,2.3482711665187863,37830.88019053144
499.0,24.5363636016846,0.0007762186889648439,0.5396258949741367,0.031761533203125,0.07167300913802806,2.9327362145083096,41445.921272975174
506.99999999999994,24.5178184509277,0.0008463218383789059,0.5861865706190111,0.031087375488281273,0.07814606079214274,2.8704871180315115,45022.010032182116
516.0,24.504301071167,0.0009165087280273439,0.632480666872787,0.031172259521484363,0.08462684469319888,2.8783249788997565,48577.62418377781
524.0,24.4882717132568,0.000986731384277344,0.6780998601242068,0.03187924072265627,0.0911109311428757,2.9436048682046416,52081.40246729699
533.0,24.477897644043,0.0010582990722656299,0.7243595771385188,0.032527119140625,0.09771921258223729,3.003427436807479,55634.376124310205
541.0,24.4568386077881,0.0011284172363281299,0.7689343747344974,0.03187683837890627,0.1041936506304829,2.9433830451436997,59057.93968774942
550.0,24.4417495727539,0.00119857653808594,0.8131299906425477,0.02552724792480468,0.11067188717321698,2.3570866043217618,62452.38023368262
558.0,24.4260330200195,0.0012693808593749998,0.8576874302764896,0.03189584106445314,0.11720968230609416,2.945137679081545,65874.61062031411
567.0,24.4052867889404,0.0013410318603515599,0.9025020221324919,0.03198223754882814,0.12382565654215695,2.9531151937976117,69316.59156163533
575.0,24.3933429718018,0.001411078125,0.9458325830532069,0.031211433105468776,0.13029345567867034,2.8819421150017335,72644.59163235077
584.0,24.3769969940186,0.00148132214355469,0.9891121175510439,0.024988124999999996,0.13677951464032223,2.3073060941828247,75968.67262296805
592.0,24.3600234985352,0.00155150048828125,1.0322586242191323,0.032050371093749995,0.14325950953658817,2.959406379847645,79282.5364223604
600,24.3392772674561,0.00162096826171875,1.0745656639301346,0.03145402587890628,0.1496738930488227,2.9043421864179386,82531.92503303646
609.0,24.3235607147217,0.0016910316162109399,1.1174379596893336,0.031359730224609354,0.15614327019491595,2.895635293131057,85824.72808673838
617.0,24.3087882995605,0.00176114855957031,1.1598933650844587,0.031266760253906276,0.1626175955281911,2.887050808301595,89085.51191124876
626.0,24.2971572875977,0.0018313717041015599,1.202072614281844,0.024990514526367177,0.16910172706385593,2.3075267337365815,92325.0855823229
634.0,24.2786121368408,0.00190137854003906,1.2441942530017824,0.03054434692382814,0.17556588550683838,2.820345976346088,95560.23448554397
643.0,24.2654094696045,0.00197232763671875,1.2869100278274523,0.025556401977539035,0.18211704863515696,2.3597785759500494,98841.01596216993
650.0,24.2493801116943,0.00200006823730469,1.3003365611000053,-0.0005844726562499999,0.18467850759969434,-0.053967927631578934,99872.23971582223
655.0,24.2368068695068,0.00200006030273438,1.2975178375579859,-0.00014089965820312497,0.18467777495238963,-0.013010125411184207,99655.74789231844
664.0,24.2160606384277,0.00195141479492188,1.2617816843032874,-0.030905815429687497,0.1801860383122696,-2.8537225696849027,96911.03566077477
672.0,24.1981430053711,0.00188111755371094,1.2136259092117296,-0.032024022216796864,0.1736950649779261,-2.9569734272203934,93212.43542332793
681.0,24.1887130737305,0.0018110290527343798,1.1668271227298745,-0.025524871215820318,0.1672233659034515,-2.3568671482751906,89618.05858140359
689.0,24.1701679229736,0.0017394840087890599,1.1198192176967636,-0.0318278466796875,0.160617175326783,-2.9388593425380884,86007.62040681748
698.0,24.1412487030029,0.00166930603027344,1.0735098958168023,-0.025467824707031277,0.15413721424500829,-2.351599695940099,82450.83685228898
706.0,24.1198749542236,0.00159846008300781,1.027406550098421,-0.031853063964843775,0.14759557553165373,-2.9411878083881597,78909.87327944863
715.0,24.1073017120361,0.00152754174804688,0.9809199824768114,-0.026187163696289036,0.14104725282057987,-2.4180206552436783,75339.47638070749
723.0,24.0915851593018,0.001458169921875,0.936057731044006,-0.03133744995117186,0.13464172870498614,-2.8935780194987863,71893.83494961644
731.0,24.0746116638184,0.00138735083007813,0.8905661038497927,-0.031192825927734362,0.12810256972097228,-2.8802240007141604,68399.85436634353
740.0,24.0541801452637,0.00131718725585938,0.8451927651813503,-0.031400621337890636,0.12162393867584301,-2.899411019195811,64914.9589232988
748.0,24.0381488800049,0.00124710144042969,0.7994875303077701,-0.031279892578125,0.11515248757430192,-2.8882633959487536,61404.572220258844
757.0,24.0177173614502,0.0011777027587890599,0.7544946452468869,-0.024965081176757817,0.1087444837293684,-2.305178317336825,57948.897484399924
765.0,24.0029430389404,0.00110752795410156,0.7091531045692447,-0.031141446533203138,0.10226481570651523,-2.8754798276272515,54466.44428335213
774.0,23.9812545776367,0.00103668786621094,0.662856651523209,-0.0249756005859375,0.09572371802501753,-2.30614963859072,50910.649118526046
782.0,23.969310760498,0.000966638366699219,0.6166609794033046,-0.03187066040039063,0.08925562019383369,-2.942812594680575,47362.59442421694
790.0,23.9473075866699,0.0008965011596679689,0.5704828522924422,-0.031775712890625,0.08277942379205622,-2.934045511599723,43815.88727284503
799.0,23.9334774017334,0.0008270249633789059,0.5241307340578083,-0.031226832275390637,0.0763642625465287,-2.8833640143481656,40255.816747911544
807.0,23.9224758148193,0.000756825744628906,0.47716165998287186,-0.031350032958984364,0.06988234022427571,-2.8947398854094515,36648.360981787395
816.0,23.9014148712158,0.0006854247436523439,0.42897064523563394,-0.03181236328125,0.06328945001406684,-2.9374296658587253,32947.054165563284
824.0,23.8878993988037,0.000615253295898438,0.3813187373653412,-0.03130578002929686,0.056810091957381154,-2.890653742317346,29287.153407476286
833.0,23.8668384552002,0.000545176330566406,0.3334645568641666,-0.024976506958007818,0.05033945803937267,-2.3062333294559387,25611.71711706349
841.0,23.8398056030273,0.00047574212646484394,0.28523899453515966,-0.03124686401367186,0.04392817418881292,-2.885213667005712,21907.756876740375
849.0,23.8247184753418,0.000404925201416016,0.23581311416759518,-0.031747115478515636,0.03738921527387036,-2.9314049379977503,18111.606310875206
858.0,23.8055438995361,0.00033547299194335896,0.1866892585985181,-0.03130926269531249,0.030976268877503134,-2.8909753181267304,14338.652734141177
866.0,23.7772541046143,0.000265321655273438,0.13629259492421172,-0.032006993408203135,0.024498767799948105,-2.955401053389024,10467.94123841872
875.0,23.7665672302246,0.00019589100646972697,0.08643521582150462,-0.024561134033203137,0.018087812231738408,-2.267879412114786,6638.64944865627
883.0,23.7426776885986,0.000125248687744141,0.03487709780004027,-0.031763474121093774,0.01156497578431588,-2.9329154313105974,2678.7325499262884
891.0,23.7257041931152,5.50663757324219e-05,-0.017181925085747198,-0.03189402099609378,0.00508461456439722,-2.9449696210612903,-1319.6563045888786
900,23.7169017791748,3.39644312858582e-07,-0.05746010568425653,-0.018613031616210963,3.136143239691431e-05,-1.7186548122078449,-4413.218562538905
906.0,23.7059001922607,4.93929743766785e-07,-0.05523772072644234,0.00015818023681640642,4.5607547900903506e-05,0.014605746705116012,-4242.528473613083
911.0,23.6898708343506,4.4195449352264395e-07,-0.05396785861153604,-0.00010789489746093781,4.080835581926537e-05,-0.009962594410058891,-4144.996821162523
917.0,23.684211730957,6.06749415397644e-07,-0.05277279659380917,0.00014797210693359358,5.6024876768018835e-05,0.013663167768568197,-4053.2101838563117
923.0,23.6691246032715,5.60171961784363e-07,-0.05203775330326552,7.164001464843779e-06,5.172409619430867e-05,0.0006614959801333128,-3996.7552460265383
929.0,23.6518363952637,5.0272262096405e-07,-0.05107407778270246,3.0349731445312498e-05,4.641944791911818e-05,0.002802375941395429,-3922.740229086211
935.0,23.6537227630615,4.54657435417175e-07,-0.05042089093759057,-0.00024444580078125,4.198129597573176e-05,-0.022571172740650968,-3872.5722686321487
940.0,23.6336040496826,4.5826232433319093e-07,-0.04981422735872268,-0.00018196105957031278,4.231415737148577e-05,-0.01680157521424864,-3825.9775237114195
946.0,23.6222896575928,5.40640711784363e-07,-0.04903551326875686,4.72412109375e-05,4.992065667445641e-05,0.004362069338642659,-3766.168453821572
952.0,23.605001449585,5.83861231803894e-07,-0.04850561845679284,8.66317749023436e-05,5.391147108069196e-05,0.007999240526532187,-3725.4699275570542
958.0,23.5930557250977,5.294636487960819e-07,-0.04802012392756943,5.591583251953128e-05,4.888861023047848e-05,0.005163050094139546,-3688.1815612572527
964.0,23.5735683441162,4.2736327648162797e-07,-0.04746668457388877,-0.00020986175537109357,3.9461059693594455e-05,-0.01937781674710005,-3645.6746984553592
968.9999999999999,23.566967010498,4.3255126476287797e-07,-0.04722087207648756,-0.0002456817626953128,3.994009831605521e-05,-0.022685296647766647,-3626.795090360028
975.0,23.5499935150146,5.080631971359249e-07,-0.04650735789618488,-3.08990478515625e-05,4.6912575912827784e-05,-0.0028530976778912737,-3571.9936940234165
981.0000000000001,23.5361614227295,5.16188502311707e-07,-0.046168031248784026,-6.0150146484374996e-05,4.7662834931828894e-05,-0.005554030146295013,-3545.931739537944
987.0,23.523588180542,4.90134119987488e-07,-0.04573616777198312,-0.00010748291015625,4.5257074791088454e-05,-0.009924553107686978,-3512.7625016884117
993.0,23.5160446166992,4.64804530143738e-07,-0.04547391851904387,-0.0002837905883789064,4.291823916378005e-05,-0.02620411711716587,-3492.6204699726477
998.0,23.5053577423096,5.91605067253113e-07,-0.04483758928523062,5.889129638671878e-05,5.4626506671570905e-05,0.005437792833492038,-3443.7472569301553
1004.0,23.4896411895752,6.521061658859249e-07,-0.04451916046442983,8.960723876953139e-05,6.021294237173821e-05,0.008273983265884707,-3419.2903582511394
1009.9999999999999,23.4811534881592,5.11629939079285e-07,-0.044282171909475344,-7.24868774414064e-05,4.7241914965769617e-05,-0.00669315581176421,-3401.0884723099343
1016.0,23.4761257171631,6.473759412765499e-07,-0.04375736009986398,6.88018798828128e-05,5.9776171863023994e-05,0.006352897496104598,-3360.780345611673
1024.0,23.457893371582,4.86398582458496e-05,-0.005818166054767373,0.030689296875,0.004491214981149547,2.8337300900277005,-446.86375228628066
1033.0,23.4472064971924,0.000120288200378418,0.04981173495738508,0.02594579406738282,0.011106943709918559,2.3957335242274067,3825.7860950372565
1041.0,23.4333763122559,0.00018988163757324198,0.10236833794698667,0.031209217529296864,0.017532930523845056,2.8817375373311966,7862.3915473876095
1049.0,23.4176597595215,0.00026069589233398396,0.15499009408450085,0.031389616699218775,0.02407164287479076,2.8983948937413455,11904.001081758899
1058.0,23.3994274139404,0.000332328826904297,0.2076533372476576,0.03261737915039063,0.030685948929297966,3.011761694403567,15948.797023629619
1067.0,23.3855972290039,0.000403183013916016,0.25883100633773765,0.0255681298828125,0.03722834846869954,2.360861485024238,19879.49357432701
1075.0,23.3607654571533,0.000473228576660156,0.30832121217021896,0.03104377075195314,0.04369608279410489,2.8664608265884706,23680.58465209055
1084.0,23.3378200531006,0.000544189514160156,0.3583539665445326,0.025512236938476537,0.05024833925763213,2.3557005483357836,27523.34612477209
1092.0,23.3255596160889,0.0006151141357421879,0.40729739657287645,0.0318586083984375,0.056797242450802206,2.941699759781856,31282.44213309343
1100.0,23.3095302581787,0.0006851486816406249,0.4549570481891629,0.0318466259765625,0.0632639595236034,2.9405933496364263,34942.937648937244
1109.0,23.2975845336914,0.0007552666015625,0.5022633680135729,0.031020959472656272,0.06973837502885502,2.8643545219442537,38576.29554635737
1117.0,23.2821826934814,0.000825478271484375,0.5492531668966295,0.0311600390625,0.07622144704380193,2.87719658933518,42185.343079618244
1126.0,23.2677230834961,0.000895757751464844,0.5957649484544751,0.02496229431152346,0.08271078037533185,2.3049209890603377,45757.67653260178
1134.0,23.2494983673096,0.000965828918457031,0.6417698700389859,0.031849628906250003,0.08918087889723277,2.940870628462604,49291.0806481556
1143.0,23.2422332763672,0.0010360579833984399,0.6875037605136874,0.025595830078125,0.09566555710050229,2.3634192131232683,52803.6682422187
1151.0,23.2213878631592,0.0011068275146484399,0.7327844735054014,0.03180530639648436,0.10220013985673497,2.936778060617207,56281.44957798783
1159.0,23.20654296875,0.00117620666503906,0.7770273748962402,0.031085742187499998,0.10860634026214773,2.8703363054016617,59679.52188143166
1168.0,23.1923294067383,0.00124712658691406,0.8219195538497927,0.03178491577148436,0.11515480950268328,2.934895269758482,63127.46189322525
1176.0,23.1784324645996,0.0013172487792968799,0.86609197592926,0.03111053100585936,0.12162961951033054,2.8726252082972628,66520.12103911368
1185.0,23.1639041900635,0.00138815710449219,0.9104269792652132,0.031216962890625,0.12817701795865094,2.8824527138157894,69925.26722467075
1193.0,23.1519031524658,0.0014591589355468799,0.9546474350154877,0.03213654418945314,0.1347330503736731,2.9673632677242043,73321.61559258739
1202.0,23.1370582580566,0.00152974877929688,0.9983256040897378,0.031753637695312496,0.14125104148632314,2.9320071740824094,76676.31367816727
1210.0,23.1174755096436,0.00159938818359375,1.041253565037533,0.031287480468750004,0.14768127272333795,2.888964032202216,79973.39209197642
1219.0,23.1143169403076,0.0016707746582031299,1.0851412267570477,0.03241517944335936,0.1542728216254044,2.993091361344354,83344.1802424768
1227.0,23.0937881469727,0.00174037976074219,1.1280287107330298,0.031321673583984355,0.16069988557176268,2.8921212912266254,86638.14982588556
1236.0,23.0833644866943,0.0018104427490234398,1.170632556631085,0.025045171508789037,0.1671692289033647,2.3125735465179162,89910.33461068242
1244.0,23.0694675445557,0.00188127392578125,1.213567550546267,0.031174577636718777,0.1737095037655817,2.8785390246277722,93207.95319095755
1255.0,23.0479907989502,0.0019505780029296898,1.2529438629688285,0.017838015747070318,0.1801087722003407,1.6470928667654954,96232.24753984858
1269.0,23.0201969146729,0.0020652961425781297,1.322710674889372,0.03001428588867186,0.19070139820666016,2.7714022057868752,101590.68163512842
1283.0,22.9984035491943,0.00218062622070313,1.3923125113517743,0.02974870422363282,0.2013505282274358,2.746879429698321,106936.44480428375
1297.0,22.9696617126465,0.00229583227539063,1.4621088766990618,0.02968931945800782,0.21198820640726035,2.7413960718382104,112297.14874800782
1310.0,22.9557647705078,0.0024116591796874997,1.5319598597717334,0.03459017211914064,0.22268321142082173,3.193921709985285,117662.04760151563
1324.0,22.9232330322266,0.00252743383789063,1.6018997275810272,0.02985617065429686,0.2333733922336685,2.756802461153911,123033.77323971024
1338.0,22.8973331451416,0.00264271118164063,1.671938655484006,0.029434132690429677,0.2440176529677405,2.717833120076609,128413.1071800312
1352.0,22.8783836364746,0.00275810717773438,1.742795801804356,0.029568744506835963,0.2546728695968956,2.730262650677374,133855.28431677082
1366.0,22.8581695556641,0.00287344140625,1.8135621180992132,0.02960086120605468,0.26532238284856874,2.733228181537828,139290.4852610763
1380,22.838903427124,0.00298751782226563,1.8826436646133458,0.028864024658203136,0.2758557545951643,2.665191565854398,144596.28760471166
1387.0,22.8269004821777,0.0030000473632812497,1.8882788671333282,-0.0006557235717773459,0.2770126835901431,-0.06054695953622769,145029.09885816654
1395.0,22.8212146759033,0.002960173828125,1.8543193611480688,-0.031492053222656274,0.2733309167243767,-2.9078534831630907,142420.84187005137
1403.0,22.8111095428467,0.0028899316406249998,1.802623609264372,-0.03202477661132814,0.26684502683518,-2.95704308507185,138450.3540141607
1412.0,22.7905788421631,0.0028198242187499997,1.7526103825973522,-0.0325884375,0.26037158067867033,-3.0090893351800547,134609.09236538806
1421.0,22.7804718017578,0.0027488789062499997,1.7036407285789446,-0.025030669555664038,0.2538207669667589,-2.311234492674426,130847.9822257254
1432.0,22.7634162902832,0.0026785126953125,1.657784584181972,-0.01769215209960936,0.24732342523661124,-1.6336243859288422,127326.00492949095
1443.0,22.7479400634766,0.00256364892578125,1.5803487702499353,-0.052160621337890636,0.23671735233437208,-4.816308526121019,121378.55378263713
1451.0,22.7381496429443,0.00249288720703125,1.533803843962863,-0.0319379150390625,0.23018349095394733,-2.9490226259522156,117803.67465152558
1460.0,22.7302532196045,0.00242324951171875,1.488876500172428,-0.025099211425781278,0.2237534175178901,-2.3175633818819277,114353.03380740616
1468.0,22.7201461791992,0.002353205078125,1.4437612115516656,-0.03131786499023436,0.21728578745383192,-2.8917696205202548,110887.95787647202
1477.0,22.7027740478516,0.00228228100585938,1.3985908562927294,-0.025527315673828137,0.21073693498239887,-2.3570928600025978,107418.65255704528
1485.0,22.6974048614502,0.00221154443359375,1.3539978029090876,-0.03183061157226564,0.20420539553035547,-2.939114641945119,103993.68685937693
1493.0,22.6907730102539,0.0021413740234375,1.310039661878206,-0.0311648291015625,0.19772613328139424,-2.8776388828774233,100617.48555132152
1502.0,22.6756114959717,0.00207201684570313,1.2666763303222657,-0.03122828979492186,0.19132196174544133,-2.8834985960223323,97286.96853473624
1510.0,22.6642417907715,0.00199966381835938,1.2217073872779889,-0.03241902465820314,0.18464116513013662,-2.993446413499828,93833.13266344002
1519.0,22.6547660827637,0.00193029541015625,1.1785260150482202,-0.031219709472656277,0.17823595661645888,-2.882706322498271,90516.59101752844
1527.0,22.6402378082275,0.00185940942382813,1.1345767774547604,-0.031915341796875,0.17169062085208955,-2.946938300727147,87141.07353723199
1536.0,22.6354999542236,0.0017898382568359399,1.09169056539841,-0.025111928100585962,0.16526669038189656,-2.318737590081806,83847.20164350307
1544.0,22.6320266723633,0.0017191650390625,1.0480002008594533,-0.0312896923828125,0.1587410008367959,-2.8891682717278386,80491.56688628675
1553.0,22.6206550598145,0.0016483189697265599,1.0041364063377336,-0.02542857604980468,0.15219935085194458,-2.3479756278674677,77122.6118538966
1561.0,22.6099166870117,0.0015781898193359398,0.9604745477622982,-0.03189721435546877,0.1457238983689695,-2.9452644834227857,73769.16649480017
1569.0,22.6051788330078,0.00150871337890625,0.9173604376354215,-0.03127886352539064,0.1393087145804478,-2.8881683772290523,70457.79090901856
1578.0,22.6001262664795,0.0014386827392578099,0.8741135241352078,-0.031177082519531277,0.1328423581955503,-2.8787703157461935,67136.21537136774
1586.0,22.5928611755371,0.00136760534667969,0.829869575281143,-0.03204211303710936,0.1262793487238864,-2.958643863075656,63738.06261759932
1595.0,22.5862293243408,0.0012976074218749999,0.7861934263145443,-0.031344847412109356,0.11981601310018465,-2.89426107221693,60383.51968621692
1603.0,22.5808601379395,0.00122747863769531,0.7422621452335356,-0.031911035156249996,0.11334059443169989,-2.946540642313019,57009.381354342215
1612.0,22.5717010498047,0.0011573634033203099,0.6980735622928619,-0.025579775390625,0.10686642689938225,-2.36193678583795,53615.48097487419
1620,22.5748596191406,0.00108664672851563,0.6533924471794129,-0.03180934204101564,0.10033672470135085,-2.9371506963079996,50183.75170348794
1629.0,22.5758056640625,0.00101586340332031,0.608163022476387,-0.02635651428222654,0.09380086826595659,-2.4336578284604373,46709.90956039839
1637.0,22.580228805542,0.0009464095458984379,0.5634846382492068,-0.031766081542968776,0.08738776970438022,-2.933156190486498,43278.390034501295
1645.0,22.5748596191406,0.0008761141357421879,0.518037528242111,-0.03190408081054686,0.08089696544249195,-2.94589850512898,39787.82859002389
1654.0,22.5723323822021,0.0008054631958007809,0.4719870045978543,-0.031826817626953136,0.0743733329455938,-2.938764323818387,36250.92201212399
1662.0,22.5739116668701,0.000736035339355469,0.42636964440708147,-0.031153084716796862,0.06796263521287801,-2.876554452151141,32747.284516672928
1671.0,22.5761222839355,0.0006658717651367189,0.3797356837457653,-0.024978154907226536,0.06148400416774874,-2.3063854946654234,29165.567107969684
1679.0,22.5792808532715,0.000595758605957031,0.3328593849851604,-0.031194678955078138,0.055010028250880055,-2.880395102038609,25565.236942024607
1687.0,22.5770702362061,0.00052564990234375,0.28524314697866415,-0.03191990844726564,0.048536463743651885,-2.9473599674298834,21908.075804812917
1696.0,22.5805435180664,0.000455497619628906,0.2374634111853601,-0.0319174365234375,0.04205887531199501,-2.947131719615651,18238.357233898627
1704.0,22.5859127044678,0.000384736358642578,0.18869653482475313,-0.031846798095703135,0.03552505619968402,-2.940609242447196,14492.821415111608
1713.0,22.5897026062012,0.000313919708251953,0.13918535167069473,-0.03252085327148436,0.02898612264560969,-3.0028488708665146,10690.119175936616
1721.0,22.6013889312744,0.000244594467163086,0.09018534927577967,-0.031140021972656275,0.022584900015058723,-2.8753482892572735,6926.678131780313
1730.0,22.6045475006104,0.000174537399291992,0.04011661641011237,-0.02535531188964846,0.016116103351061124,-2.3412107007985647,3081.153334110013
1738.0,22.6102333068848,0.00010504845428466799,-0.010343104316610086,-0.030591621093749997,0.009699764938565834,-2.824711088988919,-794.4012531958592
1746.0,22.6149711608887,3.48800315856934e-05,-0.061952932651567455,-0.03137622802734378,0.0032206862036651338,-2.897158635950487,-4758.289758184905
1754.0,22.6193923950195,3.5671508312225294e-07,-0.08751961147890096,-0.000714134216308596,3.293768080537885e-05,-0.06594037085028587,-6721.9363655069865
1759.0,22.6238136291504,3.61788630485535e-07,-0.085632830933094,-7.628631591796859e-05,3.340615239940304e-05,-0.007043981155860442,-6577.022345091706
1765.0,22.621919631958,3.7418639659881597e-07,-0.08409780163197522,-0.0001449508666992186,3.455091381337174e-05,-0.013384198217841052,-6459.124549306854
1771.0,22.6263408660889,4.42221522331238e-07,-0.08283706741089823,-0.00013934326171875,4.0833012218950874e-05,-0.012866413824445982,-6362.293963970679
1777.0,22.6285514831543,4.9845016002655e-07,-0.08178149569692608,-2.197265625e-05,4.6024945524150497e-05,-0.0020288694598337947,-6281.220867659454
1783.0,22.6418170928955,4.3701446056366e-07,-0.080850216717577,-0.00012757873535156278,4.035221242508402e-05,-0.011780123301159996,-6209.694064330031
1788.0,22.640869140625,3.7895476818084696e-07,-0.07978395526728628,-8.39309692382814e-05,3.4991206664898144e-05,-0.0077498586554276445,-6127.799943723985
1794.0,22.6456069946289,6.05681300163269e-07,-0.07867289605937004,0.00013032531738281278,5.592625116927691e-05,0.012033731983639221,-6042.465135128268
1800,22.6585559844971,4.50384974479675e-07,-0.07808113077442642,-1.05743408203125e-05,4.1586793580764075e-05,-0.0009763934275450137,-5997.014652413704