File: PVC P2 Test_0.csv
Axial Displacement (mm),Axial Strain (pxl/pxl),Transverse Displacement (mm),Transverse Strain (pxl/pxl),Stress (MPa)
423.0756434,0,82.00609733,0,-2.00E-05
423.0756434,0,81.0246876,0.011967522,0.00078
424.075465,0.002363222,81.0061726,0.012193297,0.00158
425.0423508,0.004648595,81.0246876,0.011967522,0.00246
425.0423508,0.004648595,81.0061726,0.012193297,0.00339
427.0421525,0.009375414,81.0061726,0.012193297,0.00422
428.042054,0.011738824,81.0246876,0.011967522,0.00513
430.0418584,0.016465649,80.00624976,0.024386572,0.00601
432.0289342,0.021162388,80.00624976,0.024386572,0.00687
433.0288674,0.023525873,80.00624976,0.024386572,0.00776
435.0287347,0.028252847,80.00624976,0.024386572,0.00873
436.0286688,0.030616335,79.00632886,0.036579822,0.00957
439.0284729,0.037706802,79,0.036656998,0.01046
440.0284082,0.040070293,79,0.036656998,0.01133
442.0282796,0.044797276,79,0.036656998,0.01223
443.0282158,0.047160768,79,0.036656998,0.01309
445.028089,0.051887756,79.00632886,0.036579822,0.01395
447.0279633,0.056614746,79,0.036656998,0.01485
448.0279009,0.058978242,79.00632886,0.036579822,0.0157
451.017738,0.066045151,79,0.036656998,0.01663
452.0176988,0.068408702,79.00632886,0.036579822,0.01745
454.0176208,0.073135804,78,0.048851213,0.01836
455.0175821,0.075499356,78.00640999,0.048773048,0.01925
458.0174669,0.082590015,78,0.048851213,0.02007
459.0174289,0.084953568,77,0.061045428,0.02093
461.0173533,0.089680676,77,0.061045428,0.02182
463.0172783,0.094407786,77,0.061045428,0.0227
464.0172411,0.096771342,77.00649323,0.060966248,0.02355
466.0171671,0.101498454,77,0.061045428,0.02448
468.0170937,0.106225568,77.00649323,0.060966248,0.02532
470.017021,0.110952683,77,0.061045428,0.02618
472.0169488,0.115679799,77.00649323,0.060966248,0.02707
474.0168773,0.120406917,77,0.061045428,0.02793
475.0168418,0.122770477,76,0.073239644,0.02873
478.0167361,0.129861157,76,0.073239644,0.02963
479.0167012,0.132224718,76,0.073239644,0.03044
481.0166317,0.136951841,76,0.073239644,0.03126
483.0165629,0.141678966,76,0.073239644,0.03216
484.0165286,0.144042528,76,0.073239644,0.033
487.0164268,0.151133218,76,0.073239644,0.03378
488.0092212,0.15347983,76,0.073239644,0.0347
490.0163263,0.158223911,76,0.073239644,0.03547
492.0091463,0.162934227,76,0.073239644,0.03639
493.0091277,0.165297827,74,0.097628074,0.03715
496.0090725,0.172388627,74,0.097628074,0.03798
497.0090542,0.174752227,74,0.097628074,0.03889
499.009018,0.179479428,74,0.097628074,0.03968
501.008982,0.18420663,74,0.097628074,0.0406
503.0089462,0.188933833,74,0.097628074,0.04138
504.0089285,0.191297434,74,0.097628074,0.04224
506.0088932,0.196024638,74,0.097628074,0.04302
508.0088582,0.200751842,74,0.097628074,0.04387
510.0088235,0.205479047,74,0.097628074,0.04467
512.008789,0.210206253,74,0.097628074,0.04546
513.0087719,0.212569856,74,0.097628074,0.04634
516.0087209,0.219660666,74,0.097628074,0.04715
517.008704,0.222024269,74,0.097628074,0.048
519.0086704,0.226751477,74,0.097628074,0.0488
521.0086372,0.231478686,73.00684899,0.109738771,0.04958
522.0086206,0.23384229,73,0.109822289,0.05041
525.0085714,0.240933104,72,0.122016504,0.05129
526.0085551,0.243296709,72,0.122016504,0.05208
528.0085227,0.248023919,72,0.122016504,0.05291
530.0084905,0.25275113,72,0.122016504,0.05377
531.0084745,0.255114736,72,0.122016504,0.05458
534.0084269,0.262205554,72,0.122016504,0.05548
535.0084111,0.264569161,72,0.122016504,0.05624
536.0083955,0.266932767,72,0.122016504,0.0571
539.0083487,0.274023587,72.00694411,0.121931826,0.05784
540.0083333,0.276387194,72,0.122016504,0.05872
542.0083025,0.281114408,72.00694411,0.121931826,0.05953
544.008272,0.285841623,71,0.13421072,0.06035
545.0082568,0.288205231,71,0.13421072,0.06119
548.0082116,0.295296055,71,0.13421072,0.06203
549.0081967,0.297659663,71,0.13421072,0.06291
552.0081521,0.304750488,71,0.13421072,0.0638
553.0081374,0.307114097,71.0070419,0.134124849,0.06462
554.0081227,0.309477705,71,0.13421072,0.06548
557.0080789,0.316568533,71,0.13421072,0.06629
558.0080645,0.318932142,71,0.13421072,0.06711
560.0035714,0.323648809,70,0.146404935,0.06796
562.0080071,0.32838658,70,0.146404935,0.06884
563.0035524,0.330739694,70,0.146404935,0.06965
565.0035398,0.335466952,70,0.146404935,0.07047
567.0035273,0.340194209,70,0.146404935,0.07131
568.0035211,0.342557838,70,0.146404935,0.07211
570.0035088,0.347285096,70,0.146404935,0.07303
572.0034965,0.352012354,70,0.146404935,0.07385
574.0034843,0.356739612,70,0.146404935,0.07468
576.0034722,0.361466871,69,0.15859915,0.07553
577.0034662,0.3638305,69,0.15859915,0.07636
578.0034602,0.366194129,69.007246,0.158510791,0.07721
581.0034423,0.373285018,69,0.15859915,0.07809
582.0034364,0.375648647,69,0.15859915,0.07893
583.0034305,0.378012277,69,0.15859915,0.07977
586.003413,0.385103166,69,0.15859915,0.08061
587.0034071,0.387466796,69,0.15859915,0.08149
589.0033956,0.392194055,69,0.15859915,0.08234
591.0033841,0.396921315,69,0.15859915,0.08318
592.0033784,0.399284945,69.007246,0.158510791,0.08403
594.003367,0.404012205,69,0.15859915,0.08485
596.0033557,0.408739466,69.007246,0.158510791,0.08577
598.0033445,0.413466726,68,0.170793365,0.08661
599.0033389,0.415830356,68,0.170793365,0.08747
600.0033333,0.418193987,67,0.18298758,0.08834
603.0033167,0.425284878,68,0.170793365,0.08922
604.0033112,0.427648509,67,0.18298758,0.09011
605.0033058,0.430012139,67.00746227,0.182896584,0.09096
608.0032895,0.437103031,67,0.18298758,0.09185
609.0032841,0.439466662,67,0.18298758,0.09276
610.0032787,0.441830293,67,0.18298758,0.09364
612.003268,0.446557554,67,0.18298758,0.09451
614.0032573,0.451284816,67,0.18298758,0.09542
615.003252,0.453648447,67,0.18298758,0.09624
617.0032415,0.458375709,67,0.18298758,0.09719
619.003231,0.463102972,67,0.18298758,0.09807
620.0032258,0.465466603,67,0.18298758,0.09894
622.0032154,0.470193865,67,0.18298758,0.09981
623.0032103,0.472557497,67,0.18298758,0.1008
624.0032051,0.474921128,67,0.18298758,0.10165
626.0031949,0.479648391,67,0.18298758,0.10252
628.0031847,0.484375654,67,0.18298758,0.10342
630.0031746,0.489102917,67,0.18298758,0.10436
631.0031696,0.491466549,66,0.195181796,0.10525
632.0031645,0.49383018,66.00757532,0.195089421,0.10616
635.0031496,0.500921075,66,0.195181796,0.10714
636.0031446,0.503284707,66.00757532,0.195089421,0.10802
637.0007849,0.505642773,66,0.195181796,0.1089
639.0031299,0.510375603,66.00757532,0.195089421,0.10981
641.0031201,0.515102867,66,0.195181796,0.11075
642.0031153,0.517466499,65,0.207376011,0.11161
644.0031056,0.522193763,65,0.207376011,0.11258
646.000774,0.526915539,65.00769185,0.207282215,0.11362
647.0007728,0.52927918,65,0.207376011,0.1145
648.0007716,0.53164282,65.00769185,0.207282215,0.11541
650.0007692,0.536370102,65,0.207376011,0.11631
652.0007669,0.541097383,65.00769185,0.207282215,0.11728
653.0007657,0.543461024,65,0.207376011,0.11818
654.0030581,0.545830086,65.00769185,0.207282215,0.11913
656.0030488,0.550557351,65,0.207376011,0.1201
658.0030395,0.555284616,65,0.207376011,0.12103
659.0030349,0.557648249,65,0.207376011,0.12196
660.0030303,0.560011881,65,0.207376011,0.12287
662.0030211,0.564739147,65,0.207376011,0.12383
664.000753,0.569461073,65,0.207376011,0.12482
665.0030075,0.571830045,65,0.207376011,0.12575
667.0007496,0.576551995,65,0.207376011,0.1267
668.0007485,0.578915636,64.00781202,0.219474965,0.12775
670.0007463,0.583642918,64,0.219570226,0.12866
671.0007452,0.586006559,64.00781202,0.219474965,0.12963
673.0029718,0.590739109,64,0.219570226,0.13057
675.0007407,0.595461122,64.00781202,0.219474965,0.13157
676.0007396,0.597824763,64,0.219570226,0.13254
677.0007386,0.600188404,64.00781202,0.219474965,0.13352
678.0007375,0.602552045,64,0.219570226,0.13448
680.0007353,0.607279327,63,0.231764441,0.13549
682.0007331,0.612006609,64,0.219570226,0.13645
683.0007321,0.61437025,63.00793601,0.231667668,0.13743
685.0007299,0.619097532,63,0.231764441,0.13843
686.0007289,0.621461173,63.00793601,0.231667668,0.13941
688.0007267,0.626188455,63,0.231764441,0.14044
689.0007257,0.628552096,63,0.231764441,0.14141
691.0007236,0.633279378,63,0.231764441,0.14242
692.0007225,0.635643019,63.00793601,0.231667668,0.14334
694.0007205,0.640370301,63,0.231764441,0.14434
695.0007194,0.642733942,63,0.231764441,0.1453
697.0007174,0.647461224,63,0.231764441,0.14638
698.0028653,0.649829945,63,0.231764441,0.14733
699.0007153,0.652188506,63.00793601,0.231667668,0.1483
700.0007143,0.654552148,63,0.231764441,0.14937
703.0007112,0.661643071,63.00793601,0.231667668,0.1504
704,0.664005033,63,0.231764441,0.15139
705.0007092,0.666370353,63,0.231764441,0.15241
706.0007082,0.668733994,63,0.231764441,0.15346
709.0007052,0.675824918,63,0.231764441,0.15446
710.0007042,0.678188559,63,0.231764441,0.15552
711.0007032,0.6805522,63,0.231764441,0.15653
712.0007022,0.682915841,63,0.231764441,0.15757
715.0006993,0.690006765,63.00793601,0.231667668,0.15861
716.0006983,0.692370406,63,0.231764441,0.15957
717.0006973,0.694734047,62.00806399,0.243860322,0.16062
719.0006954,0.69946133,62,0.243958657,0.16162
721,0.704186973,62.00806399,0.243860322,0.16269
722,0.706550617,62,0.243958657,0.16378
723,0.70891426,61,0.256152872,0.16479
725,0.713641547,61,0.256152872,0.16584
726,0.716005191,61,0.256152872,0.16686
728.0006868,0.720734101,61,0.256152872,0.16787
729,0.723096121,61,0.256152872,0.16894
731,0.727823408,61,0.256152872,0.17
732,0.730187052,61,0.256152872,0.17107
734,0.734914339,61,0.256152872,0.1721
734,0.734914339,61,0.256152872,0.17318
737,0.742005269,61,0.256152872,0.17421
738,0.744368913,61,0.256152872,0.17525
739,0.746732556,61.00819617,0.256052926,0.17626
741,0.751459843,61,0.256152872,0.17736
742,0.753823487,61,0.256152872,0.1784
744,0.758550774,61,0.256152872,0.17942
745,0.760914417,61,0.256152872,0.18049
747,0.765641704,61,0.256152872,0.18156
748,0.768005348,61,0.256152872,0.18265
750,0.772732635,61,0.256152872,0.18366
751,0.775096278,61,0.256152872,0.18478
752,0.777459922,61,0.256152872,0.18579
753,0.779823565,61,0.256152872,0.18685
756,0.786914496,61,0.256152872,0.18793
757,0.789278139,61,0.256152872,0.18894
758,0.791641783,61,0.256152872,0.19004
760,0.79636907,61,0.256152872,0.19116
762,0.801096357,60.00833275,0.268245476,0.19226
763,0.803460001,60,0.268347087,0.19333
764,0.805823644,59,0.280541302,0.19439
766,0.810550931,60,0.268347087,0.19551
767,0.812914575,60,0.268347087,0.1966
768,0.815278218,59,0.280541302,0.1977
770,0.820005505,59.00847397,0.280437969,0.1988
772,0.824732792,60,0.268347087,0.19983
773,0.827096436,59,0.280541302,0.20094
774,0.829460079,59,0.280541302,0.20199
776,0.834187366,59,0.280541302,0.20306
778,0.838914653,59,0.280541302,0.20419
779,0.841278297,59,0.280541302,0.20528
780,0.84364194,59,0.280541302,0.20634
782,0.848369227,59,0.280541302,0.2074
784,0.853096514,59.00847397,0.280437969,0.20853
785,0.855460158,59,0.280541302,0.20958
786,0.857823801,59.00847397,0.280437969,0.2107
788,0.862551088,59,0.280541302,0.21178
790,0.867278375,59,0.280541302,0.21291
791,0.869642019,59,0.280541302,0.21396
792,0.872005662,59.00847397,0.280437969,0.2151
794,0.876732949,59,0.280541302,0.21616
796,0.881460236,59,0.280541302,0.21724
797,0.88382388,59,0.280541302,0.2183
798,0.886187524,59.00847397,0.280437969,0.21938
801,0.893278454,58,0.292735517,0.22054
801,0.893278454,59,0.280541302,0.22162
803,0.898005741,58,0.292735517,0.22269
804,0.900369385,58,0.292735517,0.22379
807,0.907460315,59,0.280541302,0.22486
807,0.907460315,58,0.292735517,0.22598
809,0.912187602,58,0.292735517,0.22701
810,0.914551246,58,0.292735517,0.22819
812,0.919278533,58.00862005,0.292630403,0.22921
813,0.921642176,58,0.292735517,0.23033
815,0.926369463,58.00862005,0.292630403,0.23147
816,0.928733107,58,0.292735517,0.23262
818,0.933460394,58.00862005,0.292630403,0.2337
819,0.935824037,58,0.292735517,0.23481
820,0.938187681,58,0.292735517,0.23587
823.0006075,0.945280047,58,0.292735517,0.23697
824,0.947642255,58.00862005,0.292630403,0.23802
825.0006061,0.950007331,58,0.292735517,0.2391
827,0.954733185,58,0.292735517,0.24018
829,0.959460472,58,0.292735517,0.24132
830.0006024,0.96182554,57,0.304929733,0.2424
831.0006017,0.964189182,58,0.292735517,0.2436
832.000601,0.966552823,58,0.292735517,0.24463
835.0005988,0.973643749,57,0.304929733,0.24574
836.0005981,0.976007391,57,0.304929733,0.24688
837.0005974,0.978371033,57.00877125,0.304822774,0.24805
839.0005959,0.983098316,57,0.304929733,0.24911
841.0005945,0.9878256,57,0.304929733,0.25028
842.0005938,0.990189242,57,0.304929733,0.25141
843.0005931,0.992552884,57,0.304929733,0.25245
845.0005917,0.997280167,56,0.317123948,0.2536
846.000591,0.999643809,57,0.304929733,0.25469
848.0005896,1.004371093,57,0.304929733,0.25579
850.0005882,1.009098377,56,0.317123948,0.25689
851.0005875,1.011462018,56,0.317123948,0.25796
852.0005869,1.01382566,56,0.317123948,0.25908
854.0005855,1.018552944,56,0.317123948,0.26014
856.0005841,1.023280228,56,0.317123948,0.26135
857.0005834,1.02564387,56.00892786,0.31701508,0.26248
858.0005828,1.028007512,56,0.317123948,0.2636
860.0005814,1.032734796,56.00892786,0.31701508,0.26475
862.00058,1.037462079,56,0.317123948,0.26582
863.0005794,1.039825721,56,0.317123948,0.26692
865.000578,1.044553005,56,0.317123948,0.26802
866.0005774,1.046916647,56.00892786,0.31701508,0.26915
868.000576,1.051643931,56,0.317123948,0.27032
869.0005754,1.054007573,56.00892786,0.31701508,0.27147
871.0005741,1.058734857,56,0.317123948,0.27264
873.0005727,1.063462141,56,0.317123948,0.2738
874.0005721,1.065825783,56,0.317123948,0.27494
876.0005708,1.070553067,56,0.317123948,0.27605
877.0005701,1.072916709,56,0.317123948,0.27716
879.0005688,1.077643993,56,0.317123948,0.27835
881.0005675,1.082371277,56,0.317123948,0.27945
882.0005669,1.084734919,56,0.317123948,0.28062
883.0005663,1.087098561,56.00892786,0.31701508,0.28177
884.0005656,1.089462203,56,0.317123948,0.28292
886.0005643,1.094189487,56.00892786,0.31701508,0.28406
888.0005631,1.098916771,56,0.317123948,0.28526
889.0005624,1.101280413,56,0.317123948,0.28638
892.0005605,1.108371339,56,0.317123948,0.28749
893.0005599,1.110734981,55,0.329318163,0.28863
894.0005593,1.113098623,55,0.329318163,0.28977
896.000558,1.117825907,55.00909016,0.329207316,0.2909
898.0005568,1.122553191,55,0.329318163,0.29205
899.0005562,1.124916833,55.00909016,0.329207316,0.29319
900,1.127279162,55,0.329318163,0.29433
902.0005543,1.132007759,55.00909016,0.329207316,0.29535
904.0005531,1.136735043,55,0.329318163,0.29649
905,1.139097379,55,0.329318163,0.29756
907,1.143824666,55,0.329318163,0.29868
909.0005501,1.148553254,55,0.329318163,0.29977
909.0005501,1.148553254,55.00909016,0.329207316,0.30089
912,1.155642884,55,0.329318163,0.302
913,1.158006528,55.00909016,0.329207316,0.30314
914,1.160370171,55,0.329318163,0.30433
917.0005453,1.16746239,55,0.329318163,0.30541
918,1.169824745,55,0.329318163,0.30654
920.0005435,1.174553317,55,0.329318163,0.30769
921.0005429,1.176916959,55,0.329318163,0.30883
923,1.181642963,54,0.341512378,0.30991
924.0005411,1.184007885,54,0.341512378,0.31109
926,1.188733893,55,0.329318163,0.31218
928,1.19346118,55,0.329318163,0.3133
929,1.195824824,54,0.341512378,0.3144
931,1.200552111,54,0.341512378,0.31551
933,1.205279398,54,0.341512378,0.3166
934.0005353,1.207644307,54,0.341512378,0.31776
936.0005342,1.212371591,54,0.341512378,0.31879
938,1.217097615,54.00925847,0.341399479,0.31995
939.0005325,1.219462517,54,0.341512378,0.32109
940,1.221824902,53.00943312,0.353591564,0.32222
942.0005308,1.226553444,53,0.353706593,0.32323
944.0005297,1.231280728,53.00943312,0.353591564,0.32445
946.0005285,1.236008013,53,0.353706593,0.32557
947,1.238370407,53.00943312,0.353591564,0.32671
948.0005274,1.240735297,53,0.353706593,0.32782
951.0005258,1.247826224,53,0.353706593,0.32894
952.0005252,1.250189866,53,0.353706593,0.33002
953.0005247,1.252553508,53,0.353706593,0.33112
955.0005236,1.257280793,53.00943312,0.353591564,0.33231
957.0005225,1.262008077,53,0.353706593,0.3334
958.0005219,1.264371719,53.00943312,0.353591564,0.33453
961.0005203,1.271462646,53,0.353706593,0.33562
962.0005198,1.273826288,53,0.353706593,0.33667
963.0005192,1.27618993,53,0.353706593,0.3378
965.0005181,1.280917215,53.00943312,0.353591564,0.3389
967.0005171,1.285644499,53,0.353706593,0.34001
968.0005165,1.288008142,53.00943312,0.353591564,0.34114
970.0005155,1.292735426,53,0.353706593,0.34225
972.0005144,1.297462711,53.00943312,0.353591564,0.34339
973.0005139,1.299826353,53,0.353706593,0.34448
975.0005128,1.304553637,53,0.353706593,0.34558
976.0005123,1.30691728,53,0.353706593,0.34677
978.0005112,1.311644564,53,0.353706593,0.34786
980.0005102,1.316371849,53,0.353706593,0.34895
981.0005097,1.318735491,53,0.353706593,0.35004
984.0005081,1.325826418,53,0.353706593,0.35116
985.0005076,1.32819006,53,0.353706593,0.35224
986.0005071,1.330553703,52,0.365900809,0.35334
988.0005061,1.335280987,52,0.365900809,0.35449
990.0005051,1.340008272,52,0.365900809,0.35557
992.000504,1.344735556,52,0.365900809,0.35667
994.000503,1.349462841,52,0.365900809,0.35772
995.0005025,1.351826483,52,0.365900809,0.35887
997.0005015,1.356553768,52.0096145,0.365783567,0.35997
999.0005005,1.361281053,52,0.365900809,0.36107
1000.0005,1.363644695,52,0.365900809,0.36217
1002.000499,1.36837198,52,0.365900809,0.36328
1004.000498,1.373099264,52.0096145,0.365783567,0.36428
1005.000498,1.375462907,52,0.365900809,0.36539
1007.000497,1.380190191,52,0.365900809,0.3665
1008.000496,1.382553834,52,0.365900809,0.36752
1011.000495,1.389644761,52,0.365900809,0.36861
1012.000494,1.392008403,52,0.365900809,0.3697
1013.000494,1.394372046,52,0.365900809,0.37081
1016.000492,1.401462973,52.0096145,0.365783567,0.37192
1017.000492,1.403826615,52,0.365900809,0.373
1018.000491,1.406190257,52.0096145,0.365783567,0.37415
1020.00049,1.410917542,52,0.365900809,0.37527
1022.000489,1.415644827,52.0096145,0.365783567,0.37636
1024.000488,1.420372112,52,0.365900809,0.37744
1025.000488,1.422735754,52,0.365900809,0.37856
1028.000486,1.429826681,52.0096145,0.365783567,0.37965
1029.000486,1.432190324,52,0.365900809,0.38077
1030.000485,1.434553966,52,0.365900809,0.38187
1032.000484,1.439281251,51,0.378095024,0.38296
1034.000484,1.444008536,50.009999,0.390167309,0.38402
1035.000483,1.446372178,51,0.378095024,0.38512
1038.000482,1.453463105,50,0.390289239,0.38622
1039.000481,1.455826748,50,0.390289239,0.38742
1042.00048,1.462917675,50.009999,0.390167309,0.38842
1043.000479,1.465281317,50,0.390289239,0.38953
1044.000479,1.46764496,50.009999,0.390167309,0.39059
1047.000478,1.474735887,50,0.390289239,0.39169
1048.000477,1.47709953,50.009999,0.390167309,0.39278
1049.000477,1.479463172,50,0.390289239,0.39382
1051.000476,1.484190457,50.009999,0.390167309,0.39485
1054.000474,1.491281384,50,0.390289239,0.39593
1055.001896,1.493648387,50.009999,0.390167309,0.39695
1057.001892,1.498375666,50,0.390289239,0.39803
1058.00189,1.500739305,50.009999,0.390167309,0.39904
1060.001887,1.505466584,50.009999,0.390167309,0.40005
1063.00047,1.512554166,50,0.390289239,0.40114
1064.00188,1.514921141,50.009999,0.390167309,0.40226
1065.001878,1.51728478,50,0.390289239,0.4033
1067.001874,1.522012059,50.009999,0.390167309,0.40449
1069.001871,1.526739338,50,0.390289239,0.40557
1071.001867,1.531466617,50.009999,0.390167309,0.40667
1073.001864,1.536193895,50.009999,0.390167309,0.40784
1074.001862,1.538557535,50,0.390289239,0.40894
1076.001859,1.543284814,50.009999,0.390167309,0.41004
1078.001855,1.548012092,50,0.390289239,0.41109
1079.001854,1.550375732,50.009999,0.390167309,0.41217
1082.001848,1.55746665,50,0.390289239,0.41319
1083.001847,1.55983029,50,0.390289239,0.4143
1084.001845,1.562193929,50,0.390289239,0.41534
1087.00184,1.569284848,50.009999,0.390167309,0.41643
1088.001838,1.571648487,50,0.390289239,0.41743
1090.001835,1.576375766,49.01020302,0.402359037,0.41858
1092.001832,1.581103045,49,0.402483454,0.41957
1094.001828,1.585830325,49.01020302,0.402359037,0.42056
1095.001826,1.588193964,49,0.402483454,0.42164
1096.001825,1.590557604,49,0.402483454,0.42268
1099.00182,1.597648522,49,0.402483454,0.42369
1100.001818,1.600012162,49,0.402483454,0.42474
1103.001813,1.607103081,49,0.402483454,0.42578
1104.001812,1.609466721,49,0.402483454,0.42677
1106.001808,1.614194,49,0.402483454,0.42775
1108.001805,1.618921279,49,0.402483454,0.42874
1109.001803,1.621284919,49,0.402483454,0.42973
1112.001799,1.628375838,49,0.402483454,0.43072
1113.001797,1.630739478,49.01020302,0.402359037,0.43164
1115.001794,1.635466757,49,0.402483454,0.43268
1117.001791,1.640194036,49.01020302,0.402359037,0.43361
1119.001787,1.644921316,49,0.402483454,0.43463
1120.001786,1.647284956,49.01020302,0.402359037,0.43571
1123.001781,1.654375875,49,0.402483454,0.43671
1124.001779,1.656739515,49,0.402483454,0.43782
1125.001778,1.659103154,49.01020302,0.402359037,0.43892
1128.001773,1.666194074,49.01020302,0.402359037,0.43997
1129.001771,1.668557714,49,0.402483454,0.44107
1131.001768,1.673284993,49,0.402483454,0.4421
1133.001765,1.678012273,49.01020302,0.402359037,0.44318
1135.001762,1.682739552,49,0.402483454,0.44435
1136.001761,1.685103192,49.01020302,0.402359037,0.44533
1138.001757,1.689830472,49,0.402483454,0.44641
1140.001754,1.694557752,49.01020302,0.402359037,0.4474
1141.001753,1.696921392,49,0.402483454,0.44842
1144.001748,1.704012311,49,0.402483454,0.44934
1146.001745,1.708739591,48,0.41467767,0.45022
1147.001744,1.711103231,49.01020302,0.402359037,0.45128
1149.001741,1.715830511,47,0.426871885,0.45225
1150.001739,1.718194151,48,0.41467767,0.45326
1153.001735,1.725285071,47.01063709,0.426742174,0.45433
1154.001733,1.727648711,48,0.41467767,0.45542
1156.00173,1.732375991,48.01041554,0.41455066,0.45645
1158.001727,1.737103271,48.01041554,0.41455066,0.45751
1159.001726,1.739466911,47,0.426871885,0.45859
1161.001723,1.744194191,48.01041554,0.41455066,0.45956
1163.00172,1.748921471,48.01041554,0.41455066,0.46062
1164.001718,1.751285111,47,0.426871885,0.4617
1167.001714,1.758376031,48.01041554,0.41455066,0.46271
1169.001711,1.763103311,47,0.426871885,0.4637
1171.001708,1.767830591,47.01063709,0.426742174,0.46467
1172.001706,1.770194231,47,0.426871885,0.46567
1174.001704,1.774921511,47.01063709,0.426742174,0.46672
1176.001701,1.779648791,47,0.426871885,0.46771
1177.001699,1.782012431,47,0.426871885,0.4687
1179.001696,1.786739712,47.01063709,0.426742174,0.46976
1181.001693,1.791466992,47,0.426871885,0.47077
1183.001691,1.796194272,47.01063709,0.426742174,0.47181
1184.001689,1.798557912,47,0.426871885,0.4727
1187.003791,1.805653811,47.01063709,0.426742174,0.47367
1189.003785,1.810381083,47,0.426871885,0.47467
1191.003778,1.815108355,47,0.426871885,0.47573
1192.003775,1.817471991,47,0.426871885,0.47672
1193.003772,1.819835627,47.01063709,0.426742174,0.47761
1196.003763,1.826926535,47,0.426871885,0.47855
1197.003759,1.829290171,47,0.426871885,0.47958
1199.003753,1.834017443,47,0.426871885,0.4805
1201.003747,1.838744716,47.01063709,0.426742174,0.48144
1202.003744,1.841108352,47,0.426871885,0.48246
1205.003734,1.84819926,47,0.426871885,0.48343
1206.003731,1.850562896,47.01063709,0.426742174,0.48447
1208.003725,1.855290169,46.01086828,0.43893357,0.48546
1210.003719,1.860017441,46.01086828,0.43893357,0.48645
1212.003713,1.864744714,46.01086828,0.43893357,0.48745
1214.003707,1.869471986,46.01086828,0.43893357,0.48835
1216.003701,1.874199259,46,0.4390661,0.48944
1217.003698,1.876562895,46.01086828,0.43893357,0.49038
1219.003692,1.881290168,46,0.4390661,0.4915
1221.003685,1.886017441,46,0.4390661,0.49252
1222.003682,1.888381077,46,0.4390661,0.49354
1225.003673,1.895471986,46.01086828,0.43893357,0.49453
1226.00367,1.897835623,46.01086828,0.43893357,0.49544
1228.003664,1.902562896,46,0.4390661,0.4964
1230.003659,1.907290169,46,0.4390661,0.49747
1232.003653,1.912017442,46.01086828,0.43893357,0.49853
1233.00365,1.914381078,46,0.4390661,0.49955
1236.003641,1.921471988,46,0.4390661,0.50047
1237.003638,1.923835624,46.01086828,0.43893357,0.50141
1238.003635,1.926199261,46,0.4390661,0.50222
1241.003626,1.933290171,46.01086828,0.43893357,0.50316
1243.00362,1.938017444,46,0.4390661,0.50415
1244.003617,1.940381081,46.01086828,0.43893357,0.50514
1246.003612,1.945108354,46,0.4390661,0.50606
1248.003606,1.949835627,46.01086828,0.43893357,0.50716
1250.0036,1.954562901,46,0.4390661,0.50821
1251.003597,1.956926537,46.01086828,0.43893357,0.50924
1254.003589,1.964017447,46.01086828,0.43893357,0.51033
1255.003586,1.966381084,46,0.4390661,0.51132
1258.003577,1.973471995,46.01086828,0.43893357,0.51238
1259.003574,1.975835631,46.01086828,0.43893357,0.51332
1261.003569,1.980562905,46,0.4390661,0.51418
1263.003563,1.985290179,45,0.451260315,0.51514
1266.003554,1.992381089,45.01110974,0.451124841,0.51615
1267.003552,1.994744726,45,0.451260315,0.51708
1268.003549,1.997108363,46.01086828,0.43893357,0.51806
1270.003543,2.001835637,45.01110974,0.451124841,0.51895
1272.003538,2.006562911,45.01110974,0.451124841,0.51986
1274.003532,2.011290185,45.01110974,0.451124841,0.5208
1276.003527,2.016017459,45.01110974,0.451124841,0.52169
1278.003521,2.020744733,45,0.451260315,0.52272
1279.003518,2.02310837,45.01110974,0.451124841,0.52364
1281.003513,2.027835644,45,0.451260315,0.52464
1283.003507,2.032562918,45.01110974,0.451124841,0.52569
1284.003505,2.034926555,45.01110974,0.451124841,0.52672
1287.003496,2.042017466,45.01110974,0.451124841,0.52762
1289.003491,2.04674474,45.01110974,0.451124841,0.52861
1290.003488,2.049108377,45.01110974,0.451124841,0.52956
1292.003483,2.053835652,45.01110974,0.451124841,0.5307
1295.003475,2.060926563,45.01110974,0.451124841,0.53173
1296.006173,2.063296583,45.01110974,0.451124841,0.53272
1298.006163,2.068023848,45.01110974,0.451124841,0.53367
1299.006159,2.07038748,45.01110974,0.451124841,0.53466
1301.006149,2.075114745,45,0.451260315,0.53568
1302.006144,2.077478377,45.01110974,0.451124841,0.53667
1305.003448,2.084562935,45,0.451260315,0.5377
1307.006121,2.089296539,45.01110974,0.451124841,0.53869
1309.006112,2.094023804,45.01110974,0.451124841,0.53973
1311.006102,2.098751069,45.01110974,0.451124841,0.54075
1312.006098,2.101114702,45.01110974,0.451124841,0.54173
1314.003425,2.105835671,45,0.451260315,0.5427
1316.006079,2.110569232,45.01110974,0.451124841,0.54363
1319.006065,2.11766013,45,0.451260315,0.54457
1320.006061,2.120023762,45.01110974,0.451124841,0.54543
1321.006056,2.122387395,45,0.451260315,0.54635
1323.006047,2.127114661,45.01110974,0.451124841,0.54736
1325.006038,2.131841926,44,0.46345453,0.54825
1327.006029,2.136569192,45.01110974,0.451124841,0.5492
1329.00602,2.141296457,44,0.46345453,0.55016
1332.006006,2.148387356,44.01136217,0.463315978,0.55117
1333.006001,2.150750988,44,0.46345453,0.5521
1334.005997,2.153114621,44.01136217,0.463315978,0.55307
1337.005984,2.16020552,44.01136217,0.463315978,0.55405
1338.005979,2.162569153,44.01136217,0.463315978,0.55508
1341.005966,2.169660052,44.01136217,0.463315978,0.55609
1343.005957,2.174387318,44,0.46345453,0.5572
1344.005952,2.176750951,44.01136217,0.463315978,0.55827
1346.005944,2.181478217,44,0.46345453,0.55928
1348.005935,2.186205483,44.01136217,0.463315978,0.56028
1349.00593,2.188569116,44,0.46345453,0.56134
1352.005917,2.195660016,44.01136217,0.463315978,0.56236
1353.005913,2.198023649,44,0.46345453,0.56344
1356.0059,2.205114549,44.01136217,0.463315978,0.5644
1357.005895,2.207478182,44,0.46345453,0.56542
1359.003311,2.212199361,44.01136217,0.463315978,0.56642
1361.003306,2.216926637,44,0.46345453,0.56734
1362.005874,2.219296348,44.01136217,0.463315978,0.56823
1365.003297,2.226381188,44,0.46345453,0.56916
1366.003294,2.228744826,44.01136217,0.463315978,0.57005
1368.005848,2.233478148,44,0.46345453,0.57098
1370.005839,2.238205415,44,0.46345453,0.57188
1372.005831,2.242932682,44.01136217,0.463315978,0.57279
1374.005822,2.247659949,44.01136217,0.463315978,0.5736
1376.005814,2.252387216,44,0.46345453,0.57453
1378.003266,2.25710848,44.01136217,0.463315978,0.57545
1380.003261,2.261835756,44.01136217,0.463315978,0.57642
1382.003256,2.266563032,44,0.46345453,0.57724
1384.003251,2.271290307,44,0.46345453,0.57814
1385.003249,2.273653945,44,0.46345453,0.57915
1388.003242,2.280744859,44.01136217,0.463315978,0.58013
1389.00324,2.283108497,44.01136217,0.463315978,0.58113
1391.003235,2.287835773,44.01136217,0.463315978,0.58224
1394.003228,2.294926687,43.01162634,0.475506972,0.58329
1395.003226,2.297290326,43.01162634,0.475506972,0.58434
1397.003221,2.302017602,43,0.475648746,0.58534
1398.003219,2.30438124,43.01162634,0.475506972,0.58632
1401.003212,2.311472154,43.01162634,0.475506972,0.58755
1403.003207,2.31619943,43.01162634,0.475506972,0.58861
1405.003203,2.320926706,43.01162634,0.475506972,0.58959
1406.003201,2.323290345,43,0.475648746,0.59066
1408.005682,2.328023496,43,0.475648746,0.59153
1410.003191,2.332744897,43.01162634,0.475506972,0.59252
1412.003187,2.337472173,43.01162634,0.475506972,0.5934
1414.003182,2.34219945,43,0.475648746,0.59432
1415.00318,2.344563088,43.01162634,0.475506972,0.59515
1418.005642,2.351659837,43,0.475648746,0.59611
1418.003173,2.351654003,42.01190308,0.487697812,0.59702
1421.003167,2.358744917,43,0.475648746,0.59811
1422.003165,2.361108556,43.01162634,0.475506972,0.59906
1425.005614,2.368205276,43.0464865,0.475081879,0.6
1427.005606,2.372932544,43,0.475648746,0.60084
1429.005598,2.377659813,43.01162634,0.475506972,0.60165
1430.003147,2.380017662,43.01162634,0.475506972,0.60239
1432.005587,2.384750716,42.01190308,0.487697812,0.60324
1434.005579,2.389477984,43.01162634,0.475506972,0.60401
1436.005571,2.394205253,43.01162634,0.475506972,0.60483
1438.005563,2.398932522,43,0.475648746,0.60563
1440.005556,2.40365979,42.01190308,0.487697812,0.60656
1442.005548,2.408387059,43,0.475648746,0.60755
1443.005544,2.410750694,43.01162634,0.475506972,0.60856
1446.005532,2.417841597,42.01190308,0.487697812,0.60962
1448.005525,2.422568866,42.01190308,0.487697812,0.61058
1449.005521,2.4249325,43,0.475648746,0.61147
1451.005513,2.429659769,42.01190308,0.487697812,0.61231
1453.005506,2.434387038,42,0.487842961,0.61324
1455.005498,2.439114308,42.01190308,0.487697812,0.61427
1457.005491,2.443841577,42,0.487842961,0.61531
1458.005487,2.446205211,42.01190308,0.487697812,0.61641
1460.005479,2.450932481,42.01190308,0.487697812,0.6174
1462.005472,2.45565975,43,0.475648746,0.61828
1463.005468,2.458023385,42.01190308,0.487697812,0.61915
1466.005457,2.465114289,41.01219331,0.499888488,0.61993
1468.00545,2.469841558,42.01190308,0.487697812,0.62075
1470.005442,2.474568828,42,0.487842961,0.62155
1471.005438,2.476932462,42.01190308,0.487697812,0.62229
1474.005427,2.484023367,41,0.500037176,0.62303
1476.00542,2.488750637,42.01190308,0.487697812,0.62379
1478.005413,2.493477906,41,0.500037176,0.62456
1479.005409,2.495841541,41,0.500037176,0.62537
1481.005402,2.500568811,41.01219331,0.499888488,0.62625
1483.005394,2.505296081,41.01219331,0.499888488,0.62708
1486.005384,2.512386985,41.01219331,0.499888488,0.62794
1487.00538,2.51475062,41.01219331,0.499888488,0.62885
1489.005373,2.51947789,41,0.500037176,0.62968
1491.005366,2.52420516,41.01219331,0.499888488,0.63042
1493.005358,2.52893243,41.01219331,0.499888488,0.63134
1494.005355,2.531296065,41,0.500037176,0.63217
1496.005348,2.536023336,41.01219331,0.499888488,0.63312
1498.00534,2.540750606,41,0.500037176,0.63396
1499.005337,2.543114241,41.01219331,0.499888488,0.63491
1502.005326,2.550205146,41,0.500037176,0.63585
1504.005319,2.554932416,41.01219331,0.499888488,0.63674
1506.005312,2.559659687,41.01219331,0.499888488,0.63767
1507.005309,2.562023322,41.01219331,0.499888488,0.63852
1510.005298,2.569114227,41,0.500037176,0.63945
1511.005294,2.571477863,41.0487515,0.49944269,0.64034
1513.005287,2.576205133,41,0.500037176,0.64114
1515.005281,2.580932404,41.01219331,0.499888488,0.64203
1518.00527,2.58802331,41,0.500037176,0.64281
1519.005267,2.590386945,41.0487515,0.49944269,0.64365
1520.005263,2.59275058,41.01219331,0.499888488,0.64455
1523.005253,2.599841486,41.01219331,0.499888488,0.64537
1525.005246,2.604568757,41.01219331,0.499888488,0.64626
1527.005239,2.609296028,41.01219331,0.499888488,0.64713
1528.005236,2.611659663,41.01219331,0.499888488,0.64796
1530.005229,2.616386934,41.01219331,0.499888488,0.64898
1532.005222,2.621114205,41.01219331,0.499888488,0.64993
1534.005215,2.625841476,41.01219331,0.499888488,0.65089
1535.005212,2.628205111,41.01219331,0.499888488,0.6519
1538.005202,2.635296018,41.01219331,0.499888488,0.65286
1539.005198,2.637659653,41.01219331,0.499888488,0.65377
1541.005191,2.642386924,41.01219331,0.499888488,0.65483
1543.008101,2.647121089,40.01249805,0.512078987,0.65574
1546.008085,2.654211982,40.01249805,0.512078987,0.65669
1547.00808,2.656575613,41.01219331,0.499888488,0.65756
1549.00807,2.661302876,40,0.512231391,0.65861
1551.008059,2.666030138,40.01249805,0.512078987,0.65961
1552.008054,2.668393769,40.01249805,0.512078987,0.66062
1554.008044,2.673121032,40,0.512231391,0.66146
1556.008033,2.677848295,40.01249805,0.512078987,0.6622
1558.008023,2.682575557,40.01249805,0.512078987,0.66316
1560.008013,2.68730282,40.01249805,0.512078987,0.66403
1562.008003,2.692030083,40.01249805,0.512078987,0.66497
1564.007992,2.696757346,40.01249805,0.512078987,0.66587
1566.007982,2.701484608,40.01249805,0.512078987,0.66669
1568.007972,2.706211871,40.01249805,0.512078987,0.66742
1568.007972,2.706211871,40,0.512231391,0.66833
1571.007957,2.713302766,40.01249805,0.512078987,0.66918
1573.007947,2.718030029,40,0.512231391,0.66994
1575.007936,2.722757292,40.01249805,0.512078987,0.67072
1577.007926,2.727484556,40.01249805,0.512078987,0.67143
1579.007916,2.732211819,40.01249805,0.512078987,0.67223
1581.007906,2.736939082,40,0.512231391,0.67299
1583.007896,2.741666346,40.01249805,0.512078987,0.67384
1584.007891,2.744029977,40.04996879,0.511622061,0.67471
1587.007876,2.751120873,40.01249805,0.512078987,0.67569
1588.007872,2.753484504,40.04996879,0.511622061,0.67655
1589.007867,2.755848136,40.01249805,0.512078987,0.67734
1592.007852,2.762939032,40.01249805,0.512078987,0.67803
1594.007842,2.767666295,40.01249805,0.512078987,0.67878
1596.007832,2.772393559,40.01249805,0.512078987,0.67959
1597.007827,2.774757191,40.01249805,0.512078987,0.68037
1600.007812,2.781848087,40.01249805,0.512078987,0.68116
1602.007803,2.786575351,40.01249805,0.512078987,0.68192
1603.007798,2.788938983,40.01249805,0.512078987,0.68275
1605.007788,2.793666247,40.01249805,0.512078987,0.68354
1608.007774,2.800757143,40.01249805,0.512078987,0.68445
1609.007769,2.803120775,40.01249805,0.512078987,0.68543
1611.007759,2.80784804,40.01249805,0.512078987,0.6863
1613.00775,2.812575304,40.01249805,0.512078987,0.68725
1614.007745,2.814938936,40.01249805,0.512078987,0.68812
1617.00773,2.822029833,40.01249805,0.512078987,0.689
1619.007721,2.826757097,40.01249805,0.512078987,0.68992
1620.007716,2.829120729,40.04996879,0.511622061,0.6907
1622.007707,2.833847994,40.01249805,0.512078987,0.69175
1625.007692,2.840938891,40.01249805,0.512078987,0.69266
1627.007683,2.845666155,39.01281841,0.524269296,0.69363
1628.007678,2.848029788,39.01281841,0.524269296,0.69452
1630.007669,2.852757053,39.01281841,0.524269296,0.69553
1632.007659,2.857484317,39.01281841,0.524269296,0.69658
1634.00765,2.862211582,39.01281841,0.524269296,0.69743
1636.007641,2.866938847,39.01281841,0.524269296,0.69829
1638.007631,2.871666112,39.01281841,0.524269296,0.69919
1640.007622,2.876393377,39.01281841,0.524269296,0.70016
1641.007617,2.87875701,39.01281841,0.524269296,0.7012
1644.007603,2.885847907,39,0.524425607,0.70205
1645.007599,2.88821154,39.01281841,0.524269296,0.70288
1647.00759,2.892938805,39.01281841,0.524269296,0.70368
1648.007585,2.895302438,39.01281841,0.524269296,0.70447
1651.007571,2.902393336,39.01281841,0.524269296,0.70542
1653.007562,2.907120601,39.05124838,0.523800673,0.70644
1654.007557,2.909484234,39.01281841,0.524269296,0.70735
1656.007548,2.914211499,39.01281841,0.524269296,0.70816
1659.007535,2.921302398,39.01281841,0.524269296,0.70906
1660.010843,2.923673862,39.01281841,0.524269296,0.71
1661.010837,2.92603749,39.01281841,0.524269296,0.71111
1664.010817,2.933128374,39,0.524425607,0.71205
1665.010811,2.935492002,39.01281841,0.524269296,0.71298
1667.010798,2.940219259,39,0.524425607,0.71384
1669.010785,2.944946515,39.01281841,0.524269296,0.71471
1672.010766,2.9520374,39.01281841,0.524269296,0.71552
1673.010759,2.954401028,39.05124838,0.523800673,0.71641
1675.010746,2.959128285,39.01281841,0.524269296,0.7173
1677.010733,2.963855542,39.05124838,0.523800673,0.71824
1678.010727,2.96621917,39.01281841,0.524269296,0.71917
1680.010714,2.970946427,39.05124838,0.523800673,0.72014
1682.010702,2.975673684,39.01281841,0.524269296,0.72102
1684.010689,2.980400941,39.01281841,0.524269296,0.72195
1686.010676,2.985128198,39.01281841,0.524269296,0.72295
1688.010663,2.989855455,39.01281841,0.524269296,0.72394
1690.010651,2.994582712,39.01281841,0.524269296,0.72481
1692.010638,2.999309969,39,0.524425607,0.72571
1693.010632,3.001673598,39.01281841,0.524269296,0.72668
1696.010613,3.008764484,39.01281841,0.524269296,0.72764
1697.010607,3.011128113,39.01281841,0.524269296,0.72852
1700.010588,3.018218999,39.01281841,0.524269296,0.72938
1701.010582,3.020582628,39.01281841,0.524269296,0.7302
1703.01057,3.025309886,39.01281841,0.524269296,0.73092
1705.010557,3.030037143,39,0.524425607,0.73178
1707.010545,3.034764401,39.01281841,0.524269296,0.7326
1709.010532,3.039491659,39.01281841,0.524269296,0.7334
1711.01052,3.044218917,39.01281841,0.524269296,0.73416
1713.010508,3.048946175,39.05124838,0.523800673,0.73503
1714.010502,3.051309804,39.01281841,0.524269296,0.73594
1717.010483,3.058400691,39.01281841,0.524269296,0.73692
1718.010477,3.06076432,39.01281841,0.524269296,0.73787
1722.010453,3.070218837,39.05124838,0.523800673,0.73873
1722.010453,3.070218837,39.01281841,0.524269296,0.73968
1724.010441,3.074946095,39.01281841,0.524269296,0.74049
1726.010429,3.079673353,39.01281841,0.524269296,0.7415
1728.010417,3.084400612,38.01315562,0.536459399,0.74239
1730.010405,3.089127871,38.01315562,0.536459399,0.74334
1732.010393,3.093855129,38.01315562,0.536459399,0.74432
1733.010387,3.096218759,38.01315562,0.536459399,0.74527
1735.010375,3.100946017,39.01281841,0.524269296,0.74599
1737.010363,3.105673276,38.01315562,0.536459399,0.74697
1738.010357,3.108036905,38.05259518,0.535978465,0.74781
1741.010339,3.115127794,38.05259518,0.535978465,0.74853
1742.010333,3.117491423,38.01315562,0.536459399,0.74944
1745.010315,3.124582312,38.01315562,0.536459399,0.75038
1747.010303,3.129309571,38.05259518,0.535978465,0.75121
1748.010297,3.131673201,38.01315562,0.536459399,0.752
1750.010286,3.13640046,38.01315562,0.536459399,0.75285
1752.010274,3.141127719,38.01315562,0.536459399,0.75371
1754.010262,3.145854978,38.01315562,0.536459399,0.75456
1755.010256,3.148218608,38.01315562,0.536459399,0.7554
1758.010239,3.155309497,38.05259518,0.535978465,0.75622
1759.010233,3.157673127,38.01315562,0.536459399,0.75701
1761.010221,3.162400387,38.01315562,0.536459399,0.75773
1763.01021,3.167127646,38.05259518,0.535978465,0.75857
1765.010198,3.171854906,38.01315562,0.536459399,0.75925
1768.010181,3.178945795,38.01315562,0.536459399,0.76004
1769.010175,3.181309425,38.01315562,0.536459399,0.76078
1771.010164,3.186036685,38.01315562,0.536459399,0.76165
1773.010152,3.190763945,38.01315562,0.536459399,0.76233
1774.010147,3.193127575,38.01315562,0.536459399,0.76311
1777.010129,3.200218465,38.01315562,0.536459399,0.76384
1779.010118,3.204945725,38.05259518,0.535978465,0.76464
1780.010112,3.207309355,38.01315562,0.536459399,0.76552
1782.010101,3.212036616,38,0.536619822,0.76624
1784.013733,3.216772488,38.01315562,0.536459399,0.76709
1786.010078,3.221491136,38.01315562,0.536459399,0.768
1787.010073,3.223854766,38.01315562,0.536459399,0.76903
1790.010056,3.230945657,38.01315562,0.536459399,0.77004
1791.013679,3.233317865,38.01315562,0.536459399,0.77098
1794.013657,3.240408742,38.05259518,0.535978465,0.77184
1795.013649,3.242772367,38.01315562,0.536459399,0.77284
1797.010017,3.247491069,38.01315562,0.536459399,0.77374
1799.013619,3.25222687,38.05259518,0.535978465,0.77447
1800.013611,3.254590495,38.01315562,0.536459399,0.77525
1803.009983,3.261672851,38.05259518,0.535978465,0.77621
1804.013581,3.264044998,38.01315562,0.536459399,0.7772
1806.013566,3.26877225,38.05259518,0.535978465,0.77807
1808.013551,3.273499501,38.01315562,0.536459399,0.77891
1810.013536,3.278226753,38.01315562,0.536459399,0.77989
1812.013521,3.282954005,38.01315562,0.536459399,0.78079
1814.013506,3.287681256,38.05259518,0.535978465,0.78159
1815.013499,3.290044882,38.01315562,0.536459399,0.7824
1817.013484,3.294772134,37.01351105,0.54864928,0.78335
1818.013476,3.29713576,37.01351105,0.54864928,0.78442
1821.013454,3.304226638,37.01351105,0.54864928,0.78537
1822.013447,3.306590264,37.01351105,0.54864928,0.78631
1825.013425,3.313681143,37.01351105,0.54864928,0.78702
1827.01341,3.318408395,37.01351105,0.54864928,0.78767
1829.013395,3.323135647,37,0.548814037,0.7882
1830.013388,3.325499273,37.01351105,0.54864928,0.78891
1832.013373,3.330226526,37.01351105,0.54864928,0.78962
1833.013366,3.332590152,37.05401463,0.548155371,0.79033
1836.013344,3.339681031,37.01351105,0.54864928,0.79109
1838.01333,3.344408284,37.01351105,0.54864928,0.79193
1840.013315,3.349135537,37.01351105,0.54864928,0.79261
1841.013308,3.351499163,37.05401463,0.548155371,0.79337
1843.013293,3.356226416,37.05401463,0.548155371,0.79409
1845.013279,3.360953669,37.05401463,0.548155371,0.79483
1848.013258,3.368044548,37.01351105,0.54864928,0.79571
1849.01325,3.370408175,37,0.548814037,0.79652
1850.013243,3.372771802,37.01351105,0.54864928,0.79742
1853.013222,3.379862681,37.01351105,0.54864928,0.79827
1854.013215,3.382226308,37.01351105,0.54864928,0.79902
1857.013193,3.389317188,37.01351105,0.54864928,0.79985
1858.013186,3.391680815,37.05401463,0.548155371,0.80062
1861.013165,3.398771695,37.01351105,0.54864928,0.80147
1862.009667,3.401127071,37.01351105,0.54864928,0.8023
1863.009662,3.403490702,37.01351105,0.54864928,0.80307
1866.01313,3.410589829,37.01351105,0.54864928,0.80384
1869.013109,3.41768071,37.01351105,0.54864928,0.8046
1870.013102,3.420044337,37.05401463,0.548155371,0.80531
1871.00962,3.422399753,37.01351105,0.54864928,0.80619
1873.013081,3.427135218,37.01351105,0.54864928,0.80715
1875.013067,3.431862472,37.01351105,0.54864928,0.80798
1877.013053,3.436589726,37.01351105,0.54864928,0.80892
1878.013046,3.438953353,37.05401463,0.548155371,0.80997
1880.013032,3.443680607,37.01351105,0.54864928,0.81099
1882.013018,3.448407862,37.01351105,0.54864928,0.81202
1884.009554,3.453126961,37.01351105,0.54864928,0.81298
1886.01299,3.457862371,37.01351105,0.54864928,0.81403
1888.012977,3.462589625,37.05401463,0.548155371,0.81486
1889.01297,3.464953252,37.01351105,0.54864928,0.81565
1891.012956,3.469680507,37.05401463,0.548155371,0.81634
1893.012942,3.474407762,37.01351105,0.54864928,0.81716
1895.012929,3.479135016,37.05401463,0.548155371,0.8179
1897.012915,3.483862271,37.01351105,0.54864928,0.81864
1898.009484,3.486217804,37.05401463,0.548155371,0.81944
1900.012895,3.490953154,37.01351105,0.54864928,0.8201
1902.012881,3.495680408,37.05401463,0.548155371,0.82087
1904.012868,3.500407664,37.01351105,0.54864928,0.82167
1906.012854,3.505134919,37.01351105,0.54864928,0.82257
1909.012834,3.512225801,37.01351105,0.54864928,0.82334
1909.012834,3.512225801,37.05401463,0.548155371,0.82417
1912.012814,3.519316684,37.01351105,0.54864928,0.82495
1913.012807,3.521680312,37.01351105,0.54864928,0.82566
1915.012794,3.526407567,37.01351105,0.54864928,0.82636
1917.00939,3.531126809,37.05401463,0.548155371,0.8271
1919.012767,3.535862078,37.05401463,0.548155371,0.82789
1921.012754,3.540589334,37.05401463,0.548155371,0.82858
1923.01274,3.54531659,36.05551275,0.560331318,0.82939
1924.012734,3.547680218,37.05401463,0.548155371,0.83007
1926.012721,3.552407473,36.01388621,0.560838921,0.83075
1928.012707,3.557134729,36.05551275,0.560331318,0.83164
1930.012694,3.561861985,36,0.561008252,0.83234
1931.012688,3.564225613,36.05551275,0.560331318,0.83324
1934.009307,3.571308553,36.01388621,0.560838921,0.83415
1935.016537,3.573689287,36.01388621,0.560838921,0.83497
1936.012655,3.576043753,36.05551275,0.560331318,0.83586
1938.016512,3.580780157,36.01388621,0.560838921,0.83671
1940.012629,3.585498266,36.05551275,0.560331318,0.83747
1942.012616,3.590225522,36.01388621,0.560838921,0.83824
1944.009259,3.594944875,36.01388621,0.560838921,0.83909
1946.01259,3.599680035,36.05551275,0.560331318,0.83991
1947.012583,3.602043663,36.01388621,0.560838921,0.84071
1950.012564,3.609134548,36.01388621,0.560838921,0.84138
1951.016402,3.611507262,36.01388621,0.560838921,0.84218
1953.016385,3.616234509,36.01388621,0.560838921,0.84284
1955.012532,3.620952689,36.01388621,0.560838921,0.84369
1957.016351,3.625689004,36.05551275,0.560331318,0.84453
1959.016335,3.630416252,36.05551275,0.560331318,0.84533
1961.016318,3.6351435,36.01388621,0.560838921,0.84633
1963.016302,3.639870747,36.01388621,0.560838921,0.8472
1964.016293,3.642234371,35.0142828,0.5730283,0.8481
1966.016277,3.646961619,35.0142828,0.5730283,0.84902
1967.016268,3.649325243,36.05551275,0.560331318,0.84987
1970.016244,3.656416115,35.0142828,0.5730283,0.85067
1971.016235,3.658779739,36.01388621,0.560838921,0.85146
1974.016211,3.665870611,36.05551275,0.560331318,0.85228
1975.016202,3.668234235,36.05551275,0.560331318,0.85292
1976.016194,3.67059786,36.05551275,0.560331318,0.85376
1979.01617,3.677688732,36.05551275,0.560331318,0.85449
1980.012374,3.680043403,35.05709629,0.572506223,0.85525
1982.016145,3.684779605,36.05551275,0.560331318,0.8561
1984.012349,3.689497918,36.01388621,0.560838921,0.85691
1985.012343,3.691861547,36.05551275,0.560331318,0.85759
1988.016097,3.698961351,36.05551275,0.560331318,0.85826
1990.01608,3.703688599,35.0142828,0.5730283,0.859
1991.016072,3.706052224,35.05709629,0.572506223,0.85983
1993.012293,3.710770578,35.0142828,0.5730283,0.86074
1994.016048,3.713143097,35.05709629,0.572506223,0.86159
1996.016032,3.717870346,35.05709629,0.572506223,0.86245
1997.016024,3.720233971,35.0142828,0.5730283,0.86328
2000.016,3.727324845,35.05709629,0.572506223,0.86417
2001.015992,3.729688469,35.0142828,0.5730283,0.86492
2004.015968,3.736779343,35.0142828,0.5730283,0.86562
2006.015952,3.741506592,35.0142828,0.5730283,0.8662
2007.015944,3.743870217,35.05709629,0.572506223,0.86709
2008.015936,3.746233842,35.0142828,0.5730283,0.8677
2011.015912,3.753324716,35.05709629,0.572506223,0.86863
2012.015905,3.755688341,35.05709629,0.572506223,0.86948
2014.015889,3.760415591,35.05709629,0.572506223,0.87039
2016.015873,3.765142841,35.0142828,0.5730283,0.87119
2018.015857,3.76987009,35.05709629,0.572506223,0.87198
2020.015842,3.77459734,35.0142828,0.5730283,0.87299
2022.015826,3.77932459,35.0142828,0.5730283,0.87384
2023.015818,3.781688215,35.12833614,0.571637509,0.87466
2024.01581,3.78405184,35.05709629,0.572506223,0.87551
2027.015787,3.791142716,35.0142828,0.5730283,0.87635
2028.015779,3.793506341,35.05709629,0.572506223,0.87722
2031.015756,3.800597216,35,0.573202467,0.87804
2032.015748,3.802960841,35.0142828,0.5730283,0.87883
2033.01574,3.805324467,35.05709629,0.572506223,0.87968
2035.015725,3.810051717,35.05709629,0.572506223,0.88068
2037.015709,3.814778968,35.12833614,0.571637509,0.88158
2038.015702,3.817142593,35.05709629,0.572506223,0.88233
2040.015686,3.821869844,35.0142828,0.5730283,0.8832
2042.015671,3.826597094,35.05709629,0.572506223,0.88408
2044.015656,3.831324345,35.05709629,0.572506223,0.88505
2045.015648,3.83368797,35.0142828,0.5730283,0.88595
2047.015633,3.838415221,35.05709629,0.572506223,0.88691
2048.015625,3.840778847,35.05709629,0.572506223,0.88782
2051.015602,3.847869723,35.0142828,0.5730283,0.8888
2053.015587,3.852596974,35.05709629,0.572506223,0.88968
2054.015579,3.8549606,34.0147027,0.585217395,0.89058
2056.015564,3.859687851,35.05709629,0.572506223,0.89152
2057.015557,3.862051477,35.12833614,0.571637509,0.89231
2058.015549,3.864415102,35.05709629,0.572506223,0.89269