File: PVC P2 Test_1.csv
Axial Displacement (mm),Axial Strain (pxl/pxl),Transverse Displacement (mm),Transverse Strain (pxl/pxl),Stress (MPa)
403.0310162,0,85.0940656,0,7.00E-05
405.0197526,0.00493445,84.09518417,0.011738556,0.00086
408.0196074,0.012377686,85.0940656,0,0.00197
409.0195594,0.014858765,84.09518417,0.011738556,0.00308
411.0194643,0.019820926,84.09518417,0.011738556,0.00416
413.01937,0.02478309,84.09518417,0.011738556,0.00552
415.0192767,0.029745255,84.05355436,0.012227777,0.00658
416.0192303,0.032226339,83.05419917,0.0239719,0.00779
419.0107397,0.039648868,84.05355436,0.012227777,0.009
421.0106887,0.044611139,83.05419917,0.0239719,0.01026
423.0189121,0.04959394,83.05419917,0.0239719,0.01144
425.0188231,0.054556116,83.05419917,0.0239719,0.01255
427.0105385,0.059497958,83.05419917,0.0239719,0.01373
428.0105139,0.061979095,83.05419917,0.0239719,0.01493
431.0104407,0.069422509,83.05419917,0.0239719,0.01606
432.0104165,0.071903648,82.0548597,0.035715838,0.01724
435.0045977,0.079332806,82.0548597,0.035715838,0.01842
436.010321,0.081828205,82.0548597,0.035715838,0.01952
438.0102739,0.086790486,82.02438662,0.036073949,0.02073
440.0102272,0.091752767,82.0548597,0.035715838,0.02185
442.0101809,0.09671505,82.0548597,0.035715838,0.02301
443.0101579,0.099196191,81.05553652,0.047459585,0.02407
446.0044843,0.10662571,81.05553652,0.047459585,0.02522
448.0044643,0.111588057,81.05553652,0.047459585,0.02631
449.0044543,0.114069231,81.05553652,0.047459585,0.02746
452.0044248,0.121512754,80.05623024,0.059203134,0.02852
453.0099337,0.124007621,80.02499609,0.059570188,0.02962
455.00989,0.12896991,81.05553652,0.047459585,0.03072
457.0043763,0.133918627,81.05553652,0.047459585,0.03186
459.0043573,0.138880977,80.02499609,0.059570188,0.0329
461.0043384,0.143843327,80.05623024,0.059203134,0.03399
463.0043196,0.148805678,80.05623024,0.059203134,0.03511
465.0043011,0.153768029,80.02499609,0.059570188,0.03622
466.0042918,0.156249204,80.05623024,0.059203134,0.03733
469.0042644,0.163692732,79.0253124,0.071318172,0.03842
470.0095744,0.166187106,79.0253124,0.071318172,0.03944
472.0042373,0.171136261,79.0569415,0.070946476,0.04061
475.0010526,0.178571955,79.0253124,0.071318172,0.04169
476.0094537,0.181073998,79.0253124,0.071318172,0.04271
478.0041841,0.186023321,79.0569415,0.070946476,0.04374
480.0041666,0.190985675,79.0253124,0.071318172,0.04482
482.0041494,0.195948029,78.02563681,0.08306606,0.04593
484.0041322,0.200910384,78.02563681,0.08306606,0.04692
486.0041152,0.205872739,78.05767099,0.082689604,0.04794
487.0041068,0.208353916,78.02563681,0.08306606,0.04902
490.0040816,0.21579745,78.02563681,0.08306606,0.05006
491.0040733,0.218278628,78.02563681,0.08306606,0.05115
493.0040568,0.223240984,77.02596965,0.09481385,0.05222
496.0040322,0.230684519,77.02596965,0.09481385,0.05327
497.0040241,0.233165697,77.0584194,0.09443251,0.05435
499.004008,0.238128055,77.02596965,0.09481385,0.05533
501.003992,0.243090412,77.02596965,0.09481385,0.05642
503.000994,0.248045371,77.0584194,0.09443251,0.05744
505.0039604,0.253015128,77.02596965,0.09481385,0.05846
507.0039448,0.257977487,77.02596965,0.09481385,0.05953
509.0039293,0.262939845,76.02631123,0.106561536,0.06056
511.0039139,0.267902204,76.02631123,0.106561536,0.06154
512.0039062,0.270383384,76.02631123,0.106561536,0.06259
514.003891,0.275345744,76.02631123,0.106561536,0.06366
517.0038685,0.282789283,75.02666193,0.118309116,0.06463
518.003861,0.285270464,76.02631123,0.106561536,0.06567
520.0038461,0.290232824,76.02631123,0.106561536,0.0667
522.0038314,0.295195185,75.02666193,0.118309116,0.06773
523.0038241,0.297676365,74.02702209,0.130056584,0.06879
526.0038023,0.305119907,74.02702209,0.130056584,0.06984
527.0037951,0.307601088,74.02702209,0.130056584,0.07085
529.0037807,0.312563449,74.02702209,0.130056584,0.07193
531.0037665,0.317525811,74.02702209,0.130056584,0.07289
533.0037523,0.322488173,74.02702209,0.130056584,0.07392
535.0037383,0.327450536,74.02702209,0.130056584,0.07505
536.0037313,0.329931717,74.02702209,0.130056584,0.07603
539.0009276,0.337368356,74.02702209,0.130056584,0.07708
541.0009242,0.342330745,73.02739212,0.141803937,0.07815
542.0009225,0.344811939,73.02739212,0.141803937,0.07915
544.0009191,0.349774328,73.02739212,0.141803937,0.08019
547.0009141,0.357217912,73.02739212,0.141803937,0.08124
547.0009141,0.357217912,73.02739212,0.141803937,0.08228
550.0009091,0.364661495,73.02739212,0.141803937,0.0833
552.0036232,0.369630626,73.00684899,0.142045353,0.08432
553.0009042,0.372105079,73.02739212,0.141803937,0.08535
555.0036036,0.377074174,73.02739212,0.141803937,0.08641
556.0035971,0.379555356,73.02739212,0.141803937,0.08745
559.0035778,0.386998904,72.00694411,0.153795936,0.08852
561.0035651,0.39196127,72.02777242,0.153551168,0.08952
562.0035587,0.394442453,72.02777242,0.153551168,0.09053
564.0035461,0.399404819,72.02777242,0.153551168,0.09162
565.0035398,0.401886002,72.00694411,0.153795936,0.09262
568.0035211,0.409329551,72.02777242,0.153551168,0.09367
570.0035088,0.414291918,72.02777242,0.153551168,0.09474
571.0035026,0.416773101,72.00694411,0.153795936,0.09577
573.0034904,0.421735468,72.02777242,0.153551168,0.09686
574.0034843,0.424216652,71.02816343,0.165298274,0.09785
577.0034662,0.431660202,71.0070419,0.165546488,0.09894
578.0034602,0.434141386,71.02816343,0.165298274,0.10003
580.0034483,0.439103754,71.02816343,0.165298274,0.10111
582.0034364,0.444066122,71.02816343,0.165298274,0.10218
583.0034305,0.446547306,71.0070419,0.165546488,0.1032
585.0034188,0.451509674,71.02816343,0.165298274,0.10432
587.0034071,0.456472042,71.02816343,0.165298274,0.10537
589.0033956,0.461434411,71.02816343,0.165298274,0.10642
590.0033898,0.463915595,71.0070419,0.165546488,0.10752
592.0008446,0.468871677,71.02816343,0.165298274,0.10852
594.003367,0.473840333,70.0285656,0.177045249,0.10963
595.007563,0.476331942,70.00714249,0.177297007,0.11075
597.0033501,0.481283887,70.0285656,0.177045249,0.11184
599.0033389,0.486246256,70.0285656,0.177045249,0.11295
601.0033278,0.491208626,70.0285656,0.177045249,0.11407
603.0033167,0.496170996,70.00714249,0.177297007,0.11515
604.0033112,0.498652181,70.0285656,0.177045249,0.11621
606.0033003,0.503614551,70.0285656,0.177045249,0.1173
607.0032949,0.506095736,70.00714249,0.177297007,0.11842
609.0032841,0.511058106,70.0285656,0.177045249,0.11949
611.0032733,0.516020477,70.0285656,0.177045249,0.12061
613.0032626,0.520982848,70.00714249,0.177297007,0.12164
615.003252,0.525945218,70.0285656,0.177045249,0.12282
616.0032467,0.528426404,70.0285656,0.177045249,0.12389
618.0032362,0.533388775,69.02897942,0.188792086,0.12501
619.003231,0.535869961,69.007246,0.189047491,0.12611
621.0032206,0.540832332,69.02897942,0.188792086,0.12727
623.0032103,0.545794704,68.02940541,0.200538781,0.12838
624.0032051,0.54827589,68.02940541,0.200538781,0.12951
626.0031949,0.553238261,68.02940541,0.200538781,0.13065
628.0031847,0.558200633,68.02940541,0.200538781,0.13171
629.0031796,0.56068182,68.02940541,0.200538781,0.13292
631.0031696,0.565644192,68.02940541,0.200538781,0.13398
632.0031645,0.568125378,68.00735254,0.20079794,0.13518
634.0031546,0.57308775,69.02897942,0.188792086,0.13638
635.0070866,0.575578705,69.02897942,0.188792086,0.13751
638.0070533,0.583022218,68.02940541,0.200538781,0.1387
639.0070422,0.585503389,67.0298441,0.212285326,0.13976
641.0031201,0.590456055,67.0298441,0.212285326,0.14094
642.0031153,0.592937242,67.00746227,0.212548351,0.1421
644.0069875,0.597909247,67.00746227,0.212548351,0.14323
646.0069659,0.60287159,67.0298441,0.212285326,0.14434
647.0030912,0.605343175,67.0298441,0.212285326,0.14553
649.0030817,0.610305549,67.00746227,0.212548351,0.14676
650.0030769,0.612786736,67.0298441,0.212285326,0.14791
653.0030628,0.620230296,67.0298441,0.212285326,0.14897
654.0030581,0.622711483,67.0298441,0.212285326,0.1502
655.0030534,0.62519267,67.00746227,0.212548351,0.15133
657.0030441,0.630155045,67.0298441,0.212285326,0.15249
659.0030349,0.635117419,67.0298441,0.212285326,0.15364
660.0030303,0.637598606,67.00746227,0.212548351,0.15486
662.0030211,0.642560981,67.00746227,0.212548351,0.15602
663.0030166,0.645042168,66.03029608,0.224031716,0.15726
665.0030075,0.650004543,66.03029608,0.224031716,0.15848
666.003003,0.65248573,66.00757532,0.224298723,0.15967
668.002994,0.657448105,66.03029608,0.224031716,0.16092
669.0029895,0.659929292,66.03029608,0.224031716,0.16205
670.0029851,0.66241048,66.03029608,0.224031716,0.16327
672.0029762,0.667372855,66.00757532,0.224298723,0.16456
674.0029674,0.672335231,66.03029608,0.224031716,0.16569
676.0029586,0.677297606,66.03029608,0.224031716,0.16691
678.0029498,0.682259982,66.03029608,0.224031716,0.16811
679.0029455,0.684741169,66.03029608,0.224031716,0.16929
681.0029369,0.689703545,66.03029608,0.224031716,0.17049
682.0029325,0.692184733,66.03029608,0.224031716,0.17171
684.002924,0.697147109,66.03029608,0.224031716,0.17295
685.0029197,0.699628297,66.03029608,0.224031716,0.1742
687.0029112,0.704590673,66.03029608,0.224031716,0.17543
688.002907,0.707071861,65.00769185,0.236049055,0.17671
690.0028985,0.712034238,65.03076195,0.235777942,0.17799
691.0065123,0.714524403,65.03076195,0.235777942,0.17924
693.0064935,0.719486753,65.03076195,0.235777942,0.18054
692.0028902,0.716996614,65.00769185,0.236049055,0.18179
694.0028818,0.721958991,66.03029608,0.224031716,0.18306
696.0028736,0.726921367,66.03029608,0.224031716,0.18428
697.0028694,0.729402556,66.03029608,0.224031716,0.18548
698.0028653,0.731883744,65.03076195,0.235777942,0.18675
700.0028571,0.736846121,64.03124237,0.247523997,0.18797
701.0028531,0.73932731,64.00781202,0.247799343,0.18929
703.0028449,0.744289687,65.00769185,0.236049055,0.19056
704.0028409,0.746770875,64.03124237,0.247523997,0.19185
706.0028329,0.751733253,64.03124237,0.247523997,0.19314
708.0028249,0.75669563,64.00781202,0.247799343,0.19441
709.0028209,0.759176819,64.03124237,0.247523997,0.19569
710.0028169,0.761658007,64.03124237,0.247523997,0.19691
712.002809,0.766620385,64.03124237,0.247523997,0.19822
714.0028011,0.771582763,64.00781202,0.247799343,0.19939
715.0027972,0.774063952,64.03124237,0.247523997,0.20077
717.0027894,0.77902633,64.03124237,0.247523997,0.19895
718.0027855,0.781507519,64.03124237,0.247523997,0.2003
719.0027816,0.783988708,64.03124237,0.247523997,0.20169
721.0027739,0.788951086,64.03124237,0.247523997,0.2031
722.0027701,0.791432275,64.03124237,0.247523997,0.20443
724.0027624,0.796394653,64.00781202,0.247799343,0.20579
726.0027548,0.801357031,64.03124237,0.247523997,0.20716
727.002751,0.803838221,63.03173804,0.259269873,0.20852
729.0027435,0.808800599,63.00793601,0.259549587,0.20988
731.002736,0.813762978,63.03173804,0.259269873,0.21118
732.0027322,0.816244167,63.03173804,0.259269873,0.21251
734.0027248,0.821206546,63.03173804,0.259269873,0.21385
735.0027211,0.823687735,63.03173804,0.259269873,0.21516
737.0006784,0.828645064,63.03173804,0.259269873,0.21645
738.00271,0.831131304,63.03173804,0.259269873,0.21778
740.0027027,0.836093683,63.00793601,0.259549587,0.21907
741.0006748,0.83856985,63.03173804,0.259269873,0.22041
743.0026918,0.843537251,63.03173804,0.259269873,0.22184
744.0026882,0.846018441,63.03173804,0.259269873,0.22313
746.0060321,0.850989135,63.00793601,0.259549587,0.2244
747.0060241,0.853470314,63.07138812,0.258803917,0.22577
749.0026702,0.85842439,63.03173804,0.259269873,0.22707
750.0026667,0.860905579,63.03173804,0.259269873,0.22839
751.0026631,0.863386769,63.00793601,0.259549587,0.22974
753.002656,0.868349149,63.03173804,0.259269873,0.2311
755.002649,0.873311529,63.03173804,0.259269873,0.23241
756.0026455,0.875792719,62.00806399,0.271299784,0.23377
759.002635,0.883236288,62.03224968,0.271015561,0.23511
760.0026316,0.885717478,62.03224968,0.271015561,0.23651
761.0026281,0.888198669,62.03224968,0.271015561,0.23782
763.0026212,0.893161049,62.00806399,0.271299784,0.2392
765.0026144,0.898123429,62.03224968,0.271015561,0.24052
766.002611,0.900604619,62.03224968,0.271015561,0.2419
768.0026042,0.905566999,62.03224968,0.271015561,0.2433
769.0026008,0.90804819,62.00806399,0.271299784,0.24456
770.0025974,0.91052938,62.03224968,0.271015561,0.2459
772.0025907,0.91549176,62.03224968,0.271015561,0.24728
773.0025873,0.917972951,62.03224968,0.271015561,0.24866
775.0025806,0.922935331,62.00806399,0.271299784,0.24999
776.0025773,0.925416522,62.03224968,0.271015561,0.25131
778.0025707,0.930378903,62.03224968,0.271015561,0.25265
779.0025674,0.932860093,62.07253821,0.270542102,0.25403
781.0025608,0.937822474,62.03224968,0.271015561,0.25536
782.0025575,0.940303664,62.03224968,0.271015561,0.25671
784.002551,0.945266045,62.03224968,0.271015561,0.25811
785.0025478,0.947747236,61.03277808,0.282761052,0.25946
788.0025381,0.955190808,61.03277808,0.282761052,0.26083
789.0025349,0.957671998,61.03277808,0.282761052,0.26218
791.0025284,0.96263438,61.03277808,0.282761052,0.26359
792.0025252,0.96511557,61.00819617,0.283049931,0.265
794.0025189,0.970077952,61.03277808,0.282761052,0.26632
795.0025157,0.972559143,61.03277808,0.282761052,0.26771
797.0025094,0.977521524,60.03332408,0.294506337,0.26913
798.0025063,0.980002715,61.03277808,0.282761052,0.27053
800.0025,0.984965097,60.03332408,0.294506337,0.2719
801.0024969,0.987446288,60.03332408,0.294506337,0.27334
803.0024907,0.992408669,60.07495318,0.294017124,0.27468
804.0024876,0.99488986,60.03332408,0.294506337,0.27608
806.0024814,0.999852242,60.03332408,0.294506337,0.2774
807.0024783,1.002333433,61.03277808,0.282761052,0.27884
809.0024722,1.007295815,60.00833275,0.294800027,0.28029
810.0024691,1.009777006,60.03332408,0.294506337,0.28154
812.0024631,1.014739388,60.03332408,0.294506337,0.28299
814.002457,1.019701771,60.03332408,0.294506337,0.28433
815.0055215,1.022190573,60.03332408,0.294506337,0.28577
817.0055079,1.027152936,60.03332408,0.294506337,0.28716
819.002442,1.032107727,59.03388857,0.306251404,0.28848
820.0054878,1.034596482,59.00847397,0.306550068,0.28987
822.0054744,1.039558846,59.03388857,0.306251404,0.29126
823.0054678,1.042040029,59.03388857,0.306251404,0.29259
825.0054545,1.047002393,59.03388857,0.306251404,0.29396
827.0054413,1.051964757,59.03388857,0.306251404,0.29528
829.0054282,1.056927122,59.03388857,0.306251404,0.29666
830.0054217,1.059408304,59.03388857,0.306251404,0.29805
831.0054151,1.061889487,59.07622195,0.305753914,0.29947
833.0054021,1.066851852,59.03388857,0.306251404,0.30083
835.0053892,1.071814217,59.03388857,0.306251404,0.30226
837.0053763,1.076776582,59.03388857,0.306251404,0.30364
838.0053699,1.079257765,59.03388857,0.306251404,0.30508
840.0053571,1.08422013,59.03388857,0.306251404,0.30641
841.0053508,1.086701313,59.03388857,0.306251404,0.30778
843.0053381,1.091663679,59.03388857,0.306251404,0.3092
844.0053317,1.094144862,59.03388857,0.306251404,0.31056
846.0053191,1.099107228,59.03388857,0.306251404,0.312
847.0053129,1.101588411,59.03388857,0.306251404,0.31334
850.0052941,1.10903196,59.03388857,0.306251404,0.31473
852.0052817,1.113994327,58.03447251,0.317996242,0.31615
853.0052755,1.11647551,58.03447251,0.317996242,0.31756
854.0052693,1.118956693,58.03447251,0.317996242,0.31894
856.005257,1.12391906,58.03447251,0.317996242,0.32038
857.0052509,1.126400243,58.03447251,0.317996242,0.32171
859.0052386,1.13136261,58.03447251,0.317996242,0.32315
861.0052265,1.136324977,58.03447251,0.317996242,0.32451
862.0052204,1.138806161,58.03447251,0.317996242,0.32589
863.0052144,1.141287344,58.03447251,0.317996242,0.32724
865.0052023,1.146249712,58.03447251,0.317996242,0.32864
867.0051903,1.151212079,58.00862005,0.318300053,0.33004
868.0051843,1.153693263,58.03447251,0.317996242,0.33151
870.0051724,1.158655631,58.03447251,0.317996242,0.33277
872.0051605,1.163617998,58.07753438,0.317490192,0.33422
874.0051487,1.168580366,58.03447251,0.317996242,0.33557
875.0051428,1.17106155,58.03447251,0.317996242,0.33694
877.0051311,1.176023919,58.03447251,0.317996242,0.33833
878.0051253,1.178505103,58.03447251,0.317996242,0.33972
880.0051136,1.183467471,58.03447251,0.317996242,0.3411
882.005102,1.188429839,58.03447251,0.317996242,0.3424
884.0022624,1.193385191,58.03447251,0.317996242,0.3438
885.0022599,1.195866383,58.03447251,0.317996242,0.34523
887.0050733,1.200835761,58.03447251,0.317996242,0.34656
889.0050619,1.20579813,57.03507693,0.32974084,0.34801
890.0022472,1.208272345,57.03507693,0.32974084,0.34946
892.0050448,1.213241684,57.03507693,0.32974084,0.35084
893.0050392,1.215722868,57.03507693,0.32974084,0.35216
894.0050335,1.218204053,57.07889277,0.329225929,0.3536
896.0050223,1.223166422,57.03507693,0.32974084,0.35494
899.0050055,1.230609977,57.03507693,0.32974084,0.35631
900.005,1.233091161,57.03507693,0.32974084,0.35772
902.0049889,1.238053531,57.03507693,0.32974084,0.35905
903.0049834,1.240534716,57.03507693,0.32974084,0.36058
905.0049724,1.245497086,57.03507693,0.32974084,0.36194
907.0049614,1.250459456,57.03507693,0.32974084,0.36329
908.0049559,1.252940641,57.03507693,0.32974084,0.36476
909.0049505,1.255421826,57.03507693,0.32974084,0.36616
911.0049396,1.260384196,57.03507693,0.32974084,0.36757
914.0049234,1.267827752,57.03507693,0.32974084,0.36902
915.004918,1.270308937,57.07889277,0.329225929,0.37041
917.0049073,1.275271308,57.03507693,0.32974084,0.37188
918.0049019,1.277752493,57.07889277,0.329225929,0.37331
920.0048913,1.282714864,56.08029957,0.340961098,0.37471
922.0048807,1.287677235,56.0357029,0.341485185,0.37613
924.0048701,1.292639606,57.03507693,0.32974084,0.37752
926.0048596,1.297601977,56.08029957,0.340961098,0.3788
927.0048544,1.300083163,56.0357029,0.341485185,0.38023
929.0048439,1.305045534,55.03635162,0.353229262,0.38166
930.0048387,1.30752672,55.03635162,0.353229262,0.38307
932.0048283,1.312489091,56.08029957,0.340961098,0.38438
934.004818,1.317451463,55.03635162,0.353229262,0.38584
936.0048077,1.322413834,55.03635162,0.353229262,0.38723
938.0047974,1.327376206,55.08175742,0.352695667,0.38866
939.0047923,1.329857392,55.03635162,0.353229262,0.39011
941.0047821,1.334819764,55.03635162,0.353229262,0.39156
942.0047771,1.33730095,55.08175742,0.352695667,0.3929
944.0047669,1.342263322,55.08175742,0.352695667,0.39441
945.0047619,1.344744508,55.03635162,0.353229262,0.39577
947.0047518,1.349706881,55.03635162,0.353229262,0.3971
949.0047418,1.354669253,55.08175742,0.352695667,0.39855
951.0047318,1.359631626,55.08175742,0.352695667,0.39998
953.0047219,1.364593998,55.03635162,0.353229262,0.40129
955.004712,1.369556371,55.03635162,0.353229262,0.40266
956.0047071,1.372037557,55.03635162,0.353229262,0.40401
958.0046973,1.37699993,55.03635162,0.353229262,0.40543
960.0046875,1.381962303,55.03635162,0.353229262,0.40686
962.0046777,1.386924676,55.03635162,0.353229262,0.40823
963.0083073,1.38941488,55.08175742,0.352695667,0.40961
965.0046632,1.394368236,55.03635162,0.353229262,0.41103
967.0046536,1.399330609,54.03702434,0.364973057,0.41234
968.0082644,1.401820767,54.03702434,0.364973057,0.41377
970.0082474,1.406783122,54.03702434,0.364973057,0.41511
972.0046296,1.411736543,54.03702434,0.364973057,0.41646
973.008222,1.414226655,54.03702434,0.364973057,0.41779
976.0081967,1.421670188,54.08326913,0.364429602,0.41916
977.0081883,1.424151366,54.03702434,0.364973057,0.42045
979.0081716,1.429113721,54.03702434,0.364973057,0.4218
980.0081632,1.431594899,54.08326913,0.364429602,0.42321
982.0081466,1.436557255,54.03702434,0.364973057,0.42453
985.0081218,1.44400079,54.03702434,0.364973057,0.42587
986.0081136,1.446481968,54.03702434,0.364973057,0.42723
988.0080971,1.451444324,54.03702434,0.364973057,0.42861
989.0080889,1.453925503,54.03702434,0.364973057,0.43
991.0080726,1.458887859,54.03702434,0.364973057,0.43137
992.0080645,1.461369038,54.03702434,0.364973057,0.43274
994.0080483,1.466331395,54.03702434,0.364973057,0.4341
997.008024,1.473774931,54.03702434,0.364973057,0.43548
998.004509,1.476247408,54.03702434,0.364973057,0.43679
1000.008,1.481218467,54.03702434,0.364973057,0.43827
1001.007992,1.483699645,54.08326913,0.364429602,0.43967
1003.004487,1.488653345,54.08326913,0.364429602,0.44097
1006.004473,1.496096908,53.03772242,0.376716554,0.44227
1007.004469,1.498578095,54.08326913,0.364429602,0.44353
1009.00446,1.50354047,54.03702434,0.364973057,0.44493
1011.004451,1.508502846,53.03772242,0.376716554,0.44615
1012.007905,1.510992615,53.03772242,0.376716554,0.44752
1015.007882,1.518436153,53.03772242,0.376716554,0.44884
1016.004429,1.520908785,53.03772242,0.376716554,0.45018
1018.00442,1.52587116,53.03772242,0.376716554,0.45155
1019.004416,1.528352348,53.08483776,0.376162869,0.45302
1021.004407,1.533314724,53.03772242,0.376716554,0.4544
1023.004399,1.5382771,53.03772242,0.376716554,0.45573
1025.00439,1.543239476,53.08483776,0.376162869,0.45707
1027.004382,1.548201852,53.08483776,0.376162869,0.45842
1029.004373,1.553164228,53.03772242,0.376716554,0.45971
1030.004369,1.555645416,53.03772242,0.376716554,0.46102
1032.00436,1.560607792,53.08483776,0.376162869,0.46242
1033.004356,1.56308898,53.08483776,0.376162869,0.46374
1036.004344,1.570532545,53.03772242,0.376716554,0.46505
1038.004335,1.575494921,53.03772242,0.376716554,0.46632
1039.004331,1.577976109,53.03772242,0.376716554,0.46765
1041.004323,1.582938486,53.03772242,0.376716554,0.46895
1043.004314,1.587900863,53.03772242,0.376716554,0.47037
1044.00431,1.590382051,53.08483776,0.376162869,0.47172
1047.004298,1.597825616,53.03772242,0.376716554,0.47305
1048.004294,1.600306805,53.03772242,0.376716554,0.47449
1050.004286,1.605269182,53.08483776,0.376162869,0.47587
1051.004282,1.60775037,53.03772242,0.376716554,0.47721
1053.004273,1.612712747,52.03844733,0.388459736,0.47864
1056.007576,1.620164537,52.03844733,0.388459736,0.48005
1057.004257,1.622637502,52.03844733,0.388459736,0.48136
1059.004249,1.627599879,52.03844733,0.388459736,0.48266
1060.004245,1.630081068,52.03844733,0.388459736,0.48402
1063.004233,1.637524634,52.03844733,0.388459736,0.48536
1065.004225,1.642487011,51.03920062,0.400202584,0.48669
1066.007505,1.644976346,52.03844733,0.388459736,0.48794
1068.004213,1.649930578,51.03920062,0.400202584,0.48919
1070.007477,1.654901071,52.03844733,0.388459736,0.49045
1072.007463,1.659863434,52.08646657,0.387895428,0.49175
1074.007449,1.664825797,51.03920062,0.400202584,0.49307
1076.007435,1.66978816,51.03920062,0.400202584,0.49449
1077.007428,1.672269341,52.03844733,0.388459736,0.49581
1079.007414,1.677231704,51.03920062,0.400202584,0.49717
1080.007407,1.679712886,52.03844733,0.388459736,0.49853
1083.007387,1.687156431,51.03920062,0.400202584,0.4999
1084.00738,1.689637612,51.03920062,0.400202584,0.50119
1086.007366,1.694599976,51.03920062,0.400202584,0.50253
1089.007346,1.702043521,51.03920062,0.400202584,0.50381
1090.007339,1.704524703,51.0881591,0.399627239,0.50511
1092.007326,1.709487067,51.03920062,0.400202584,0.50645
1094.007313,1.714449431,51.03920062,0.400202584,0.50773
1097.007293,1.721892977,51.03920062,0.400202584,0.50912
1098.007286,1.72437416,51.0881591,0.399627239,0.51044
1100.007273,1.729336524,51.03920062,0.400202584,0.51177
1101.007266,1.731817706,50.03998401,0.411945079,0.51315
1103.007253,1.736780071,50.03998401,0.411945079,0.51453
1105.00724,1.741742435,50.08991915,0.411358256,0.5159
1108.00722,1.749185983,50.08991915,0.411358256,0.51721
1109.007214,1.751667165,50.03998401,0.411945079,0.51857
1111.007201,1.75662953,50.08991915,0.411358256,0.51996
1112.007194,1.759110713,50.08991915,0.411358256,0.52138
1115.007175,1.76655426,50.03998401,0.411945079,0.5227
1117.007162,1.771516626,50.03998401,0.411945079,0.52404
1118.007156,1.773997808,50.08991915,0.411358256,0.5254
1120.007143,1.778960174,50.08991915,0.411358256,0.52677
1123.007124,1.786403722,50.03998401,0.411945079,0.52815
1124.007117,1.788884905,50.03998401,0.411945079,0.52947
1126.007105,1.793847271,50.08991915,0.411358256,0.53088
1128.007092,1.798809637,50.03998401,0.411945079,0.53222
1129.007086,1.80129082,50.03998401,0.411945079,0.53349
1131.007073,1.806253186,50.08991915,0.411358256,0.53471
1134.007055,1.813696736,50.03998401,0.411945079,0.53593
1135.007048,1.816177919,50.03998401,0.411945079,0.53711
1137.007036,1.821140285,50.03998401,0.411945079,0.53845
1139.007024,1.826102652,50.03998401,0.411945079,0.5397
1140.007018,1.828583835,50.03998401,0.411945079,0.54103
1143.006999,1.836027386,50.03998401,0.411945079,0.5423
1145.006987,1.840989752,50.08991915,0.411358256,0.54346
1146.006981,1.843470936,50.08991915,0.411358256,0.5446
1148.006969,1.848433303,50.03998401,0.411945079,0.54586
1149.006963,1.850914487,49.04079934,0.423687198,0.54712
1152.006944,1.858358037,49.09175083,0.423088432,0.54837
1154.010832,1.86333008,49.04079934,0.423687198,0.5495
1155.006926,1.865801589,49.09175083,0.423088432,0.55072
1158.010794,1.873254782,49.09175083,0.423088432,0.55197
1159.010785,1.875735957,49.04079934,0.423687198,0.55308
1161.010767,1.880698308,49.04079934,0.423687198,0.55428
1163.010748,1.88566066,49.09175083,0.423088432,0.55549
1165.01073,1.890623011,49.09175083,0.423088432,0.55678
1166.01072,1.893104187,49.04079934,0.423687198,0.55803
1169.010693,1.900547715,49.04079934,0.423687198,0.55925
1170.010684,1.90302889,49.09175083,0.423088432,0.56046
1173.010656,1.910472419,49.09175083,0.423088432,0.56159
1174.010647,1.912953595,49.04079934,0.423687198,0.56288
1177.01062,1.920397123,49.04079934,0.423687198,0.5642
1178.010611,1.922878299,49.09175083,0.423088432,0.56545
1180.010593,1.927840652,49.09175083,0.423088432,0.56663
1181.010584,1.930321828,49.09175083,0.423088432,0.56789
1183.010566,1.935284181,49.04079934,0.423687198,0.56908
1186.01054,1.942727711,49.09175083,0.423088432,0.57051
1187.010531,1.945208887,49.09175083,0.423088432,0.57174
1189.010513,1.950171241,49.04079934,0.423687198,0.57298
1192.010487,1.957614771,49.09175083,0.423088432,0.57413
1193.010478,1.960095948,49.09175083,0.423088432,0.57531
1195.01046,1.965058301,49.04079934,0.423687198,0.57626
1197.010443,1.970020655,49.04079934,0.423687198,0.57723
1198.006678,1.972492512,48.09365863,0.434817713,0.57833
1200.006667,1.977454882,49.09175083,0.423088432,0.57947
1203.010391,1.984907718,49.04079934,0.423687198,0.58071
1204.006644,1.987379621,48.09365863,0.434817713,0.58195
1207.006628,1.994823176,48.09365863,0.434817713,0.58303
1208.006622,1.997304361,48.0416486,0.435428919,0.58424
1210.006612,2.002266731,48.0416486,0.435428919,0.58552
1212.006601,2.007229101,48.09365863,0.434817713,0.58673
1215.006584,2.014672657,48.0416486,0.435428919,0.58788
1215.006584,2.014672657,48.0416486,0.435428919,0.58917
1218.006568,2.022116213,48.09365863,0.434817713,0.59042
1220.006557,2.027078583,48.09365863,0.434817713,0.59161
1221.006552,2.029559768,48.0416486,0.435428919,0.59294
1223.006541,2.034522139,48.0416486,0.435428919,0.59433
1226.006525,2.041965695,48.09365863,0.434817713,0.59568
1228.006515,2.046928066,48.0416486,0.435428919,0.59697
1229.006509,2.049409251,48.09365863,0.434817713,0.59809
1231.006499,2.054371622,48.0416486,0.435428919,0.59937
1233.010138,2.059343049,48.09365863,0.434817713,0.60069
1235.010121,2.064305405,48.0416486,0.435428919,0.60197
1238.010097,2.07174894,48.0416486,0.435428919,0.6032
1240.010081,2.076711297,48.09365863,0.434817713,0.60445
1241.010072,2.079192476,48.09365863,0.434817713,0.60572
1243.010056,2.084154833,48.0416486,0.435428919,0.607
1245.01004,2.08911719,48.0416486,0.435428919,0.6083
1248.010016,2.096560726,48.09365863,0.434817713,0.60963
1248.010016,2.096560726,48.0416486,0.435428919,0.61099
1251.009992,2.104004262,48.0416486,0.435428919,0.61227
1253.009976,2.10896662,48.0416486,0.435428919,0.61355
1254.009968,2.111447799,46.09772229,0.458273359,0.6149
1257.009944,2.118891335,47.09564736,0.446546043,0.61613
1258.009936,2.121372514,47.09564736,0.446546043,0.61733
1260.009921,2.126334873,47.09564736,0.446546043,0.6186
1263.009897,2.13377841,47.09564736,0.446546043,0.61987
1264.009889,2.136259589,47.04253395,0.447170216,0.62122
1266.009874,2.141221948,47.04253395,0.447170216,0.6225
1269.00985,2.148665486,47.09564736,0.446546043,0.62385
1269.00985,2.148665486,46.09772229,0.458273359,0.62521
1271.009835,2.153627844,47.04253395,0.447170216,0.62649
1274.009812,2.161071383,47.04253395,0.447170216,0.62771
1275.009804,2.163552562,46.09772229,0.458273359,0.62894
1277.009789,2.168514921,46.09772229,0.458273359,0.63012
1280.009766,2.17595846,47.09564736,0.446546043,0.63129
1281.009758,2.17843964,46.04345773,0.45891106,0.63254
1283.009743,2.183401999,46.04345773,0.45891106,0.63379
1285.009728,2.188364359,46.04345773,0.45891106,0.63497
1286.00972,2.190845539,46.04345773,0.45891106,0.63612
1289.009697,2.198289079,46.09772229,0.458273359,0.63738
1291.009682,2.203251439,46.09772229,0.458273359,0.63862
1292.009675,2.205732619,46.04345773,0.45891106,0.63982
1295.009652,2.213176159,46.09772229,0.458273359,0.64106
1297.009638,2.218138519,46.09772229,0.458273359,0.64233
1298.00963,2.220619699,46.04345773,0.45891106,0.64347
1300.009615,2.22558206,46.04345773,0.45891106,0.64469
1302.009601,2.23054442,46.09772229,0.458273359,0.64589
1304.009586,2.235506781,46.09772229,0.458273359,0.64704
1306.009571,2.240469142,46.09772229,0.458273359,0.6482
1308.009557,2.245431503,46.04345773,0.45891106,0.64926
1309.009549,2.247912683,45.09988914,0.469999596,0.65042
1312.009527,2.255356225,46.09772229,0.458273359,0.65147
1314.009513,2.260318586,45.04442252,0.470651423,0.65255
1317.009491,2.267762128,45.09988914,0.469999596,0.65364
1318.009484,2.270243309,45.09988914,0.469999596,0.65463
1320.00947,2.275205671,45.04442252,0.470651423,0.65541
1322.009455,2.280168032,45.09988914,0.469999596,0.65637
1324.009441,2.285130394,45.09988914,0.469999596,0.65749
1326.009427,2.290092756,45.04442252,0.470651423,0.65857
1328.009413,2.295055118,45.04442252,0.470651423,0.65963
1329.009406,2.297536299,45.09988914,0.469999596,0.6606
1332.013513,2.304990088,45.09988914,0.469999596,0.6618
1334.00937,2.309942205,45.09988914,0.469999596,0.66291
1336.009356,2.314904567,45.09988914,0.469999596,0.66394
1337.009349,2.317385748,45.09988914,0.469999596,0.66494
1339.013443,2.322358303,45.09988914,0.469999596,0.66615
1342.013413,2.329801824,45.04442252,0.470651423,0.66734
1343.013403,2.332282998,45.09988914,0.469999596,0.66868
1345.009294,2.337235199,45.09988914,0.469999596,0.66982
1347.00928,2.342197562,45.04442252,0.470651423,0.671
1349.009266,2.347159926,45.09988914,0.469999596,0.67226
1351.009252,2.352122289,45.09988914,0.469999596,0.67354
1352.009246,2.35460347,45.09988914,0.469999596,0.67466
1354.009232,2.359565834,45.17742799,0.469088383,0.67588
1357.009211,2.367009379,45.09988914,0.469999596,0.67714
1359.009198,2.371971743,45.09988914,0.469999596,0.67826
1360.009191,2.374452924,45.04442252,0.470651423,0.67945
1362.009178,2.379415288,45.09988914,0.469999596,0.68055
1365.009157,2.386858834,45.09988914,0.469999596,0.68167
1366.009151,2.389340016,45.09988914,0.469999596,0.6829
1368.009137,2.39430238,45.09988914,0.469999596,0.68407
1369.009131,2.396783562,44.10215414,0.481724679,0.68524
1372.009111,2.404227108,45.09988914,0.469999596,0.6864
1374.009097,2.409189473,45.04442252,0.470651423,0.68774
1376.009084,2.414151837,44.10215414,0.481724679,0.68898
1378.009071,2.419114202,44.10215414,0.481724679,0.69017
1380.009058,2.424076566,44.10215414,0.481724679,0.69155
1382.009045,2.429038931,44.10215414,0.481724679,0.69277
1385.009025,2.436482478,44.10215414,0.481724679,0.69415
1385.009025,2.436482478,44.10215414,0.481724679,0.69543
1388.009006,2.443926026,44.10215414,0.481724679,0.69671
1390.008993,2.448888391,44.10215414,0.481724679,0.69798
1391.008986,2.451369573,44.10215414,0.481724679,0.69926
1394.008967,2.458813121,44.10215414,0.481724679,0.70059
1396.008954,2.463775486,44.04543109,0.482391272,0.70176
1398.008941,2.468737852,44.04543109,0.482391272,0.70285
1399.008935,2.471219035,44.10215414,0.481724679,0.704
1401.008922,2.4761814,44.10215414,0.481724679,0.70514
1403.008909,2.481143766,44.10215414,0.481724679,0.70631
1406.00889,2.488587315,44.10215414,0.481724679,0.70756
1407.008884,2.491068498,44.10215414,0.481724679,0.70879
1410.008865,2.498512047,44.10215414,0.481724679,0.70993
1411.008859,2.50099323,44.18144407,0.480792888,0.71102
1413.008846,2.505955596,44.10215414,0.481724679,0.71228
1415.008834,2.510917962,44.10215414,0.481724679,0.71351
1417.008821,2.515880328,44.10215414,0.481724679,0.71458
1420.008803,2.523323878,44.10215414,0.481724679,0.71571
1421.008797,2.525805061,44.10215414,0.481724679,0.7169
1423.008784,2.530767428,44.10215414,0.481724679,0.7181
1424.008778,2.533248611,44.18144407,0.480792888,0.71929
1427.00876,2.540692161,44.04543109,0.482391272,0.72033
1429.008747,2.545654528,44.10215414,0.481724679,0.72145
1431.008735,2.550616895,43.10452412,0.493448529,0.72251
1433.012561,2.555588785,43.0464865,0.49413057,0.72361
1435.012543,2.560551139,43.10452412,0.493448529,0.72462
1437.008699,2.565503996,43.10452412,0.493448529,0.72579
1438.012517,2.567994669,43.10452412,0.493448529,0.72683
1440.0125,2.572957024,43.10452412,0.493448529,0.72801
1443.012474,2.580400555,43.10452412,0.493448529,0.72919
1445.012457,2.585362909,43.10452412,0.493448529,0.73034
1446.012448,2.587844087,43.10452412,0.493448529,0.73147
1449.012422,2.595287618,43.10452412,0.493448529,0.7327
1450.012414,2.597768796,43.10452412,0.493448529,0.73388
1452.012397,2.602731151,43.10452412,0.493448529,0.73506
1454.01238,2.607693506,43.18564576,0.492495212,0.73622
1457.012354,2.615137038,43.10452412,0.493448529,0.73736
1459.012337,2.620099393,43.10452412,0.493448529,0.73853
1460.012329,2.622580571,43.10452412,0.493448529,0.73966
1463.012303,2.630024104,43.10452412,0.493448529,0.74074
1463.012303,2.630024104,43.10452412,0.493448529,0.74192
1466.012278,2.637467638,43.10452412,0.493448529,0.74299
1468.012262,2.642429993,44.10215414,0.481724679,0.74408
1469.012253,2.644911171,43.18564576,0.492495212,0.74528
1472.012228,2.652354705,44.10215414,0.481724679,0.74648
1474.012212,2.657317061,44.10215414,0.481724679,0.74757
1476.012195,2.662279417,43.10452412,0.493448529,0.7487
1477.012187,2.664760595,44.10215414,0.481724679,0.74983
1480.012162,2.67220413,43.10452412,0.493448529,0.75096
1482.012146,2.677166486,44.10215414,0.481724679,0.75213
1483.012138,2.679647665,44.18144407,0.480792888,0.75338
1485.012121,2.684610021,43.10452412,0.493448529,0.75449
1488.008401,2.692044386,43.10452412,0.493448529,0.75556
1490.01208,2.697015914,43.10452412,0.493448529,0.75663
1491.012072,2.699497092,43.10452412,0.493448529,0.75763
1494.008367,2.706931494,43.10452412,0.493448529,0.75854
1496.008356,2.711893863,43.10452412,0.493448529,0.7596
1497.00835,2.714375048,43.0464865,0.49413057,0.76057
1499.008339,2.719337417,43.10452412,0.493448529,0.76171
1501.008328,2.724299787,43.10452412,0.493448529,0.76296
1503.008317,2.729262157,43.18564576,0.492495212,0.76419
1506.0083,2.736705712,43.0464865,0.49413057,0.76532
1508.008289,2.741668082,43.10452412,0.493448529,0.76634
1508.008289,2.741668082,43.10452412,0.493448529,0.76747
1511.008273,2.749111637,43.10452412,0.493448529,0.7685
1513.008262,2.754074007,43.10452412,0.493448529,0.76965
1515.008251,2.759036377,43.10452412,0.493448529,0.77068
1517.00824,2.763998747,43.10452412,0.493448529,0.77182
1520.008224,2.771442303,43.18564576,0.492495212,0.77288
1520.008224,2.771442303,43.10452412,0.493448529,0.77412
1524.008202,2.781367044,43.10452412,0.493448529,0.77519
1525.008197,2.783848229,43.10452412,0.493448529,0.77632
1527.008186,2.788810599,43.10452412,0.493448529,0.77751
1529.008175,2.79377297,43.10452412,0.493448529,0.77869
1531.008165,2.798735341,43.10452412,0.493448529,0.77982
1533.011742,2.803706613,43.18564576,0.492495212,0.78088
1534.011734,2.806187793,43.10452412,0.493448529,0.78201
1536.011719,2.811150152,43.10452412,0.493448529,0.78316
1539.011696,2.818593692,43.10452412,0.493448529,0.78411
1540.011688,2.821074871,43.10452412,0.493448529,0.78519
1542.011673,2.826037231,43.10452412,0.493448529,0.78629
1544.011658,2.830999591,43.18564576,0.492495212,0.78738
1546.011643,2.83596195,43.18564576,0.492495212,0.78857
1548.011628,2.84092431,42.04759208,0.505869278,0.78965
1550.011613,2.84588667,42.10700654,0.505171057,0.79064
1553.01159,2.853330211,42.10700654,0.505171057,0.79176
1554.011583,2.855811391,42.10700654,0.505171057,0.79275
1556.011568,2.860773751,42.10700654,0.505171057,0.79378
1558.011553,2.865736111,42.10700654,0.505171057,0.79482
1561.011531,2.873179652,42.10700654,0.505171057,0.79587
1562.011524,2.875660832,42.10700654,0.505171057,0.7968
1565.011502,2.883104373,43.10452412,0.493448529,0.79796
1566.011494,2.885585554,42.04759208,0.505869278,0.79907
1568.01148,2.890547915,42.10700654,0.505171057,0.80017
1570.011465,2.895510276,42.10700654,0.505171057,0.80124
1572.01145,2.900472637,42.10700654,0.505171057,0.80231
1574.011436,2.905434998,42.19004622,0.504195199,0.8034
1576.011421,2.910397359,42.19004622,0.504195199,0.80444
1578.011407,2.91535972,42.10700654,0.505171057,0.80559
1580.011392,2.920322082,42.10700654,0.505171057,0.80655
1582.011378,2.925284443,42.10700654,0.505171057,0.80762
1585.011356,2.932727986,42.19004622,0.504195199,0.80872
1586.011349,2.935209167,42.19004622,0.504195199,0.80983
1588.011335,2.940171528,42.10700654,0.505171057,0.81099
1590.011321,2.94513389,42.19004622,0.504195199,0.81208
1592.011306,2.950096252,42.19004622,0.504195199,0.81331
1595.011285,2.957539795,42.10700654,0.505171057,0.81451
1596.011278,2.960020976,42.10700654,0.505171057,0.81572
1598.011264,2.964983339,42.19004622,0.504195199,0.81695
1600.01125,2.969945701,42.19004622,0.504195199,0.81813
1602.011236,2.974908063,42.10700654,0.505171057,0.81931
1604.011222,2.979870426,42.10700654,0.505171057,0.82048
1606.011208,2.984832788,42.10700654,0.505171057,0.82151
1608.011194,2.989795151,42.10700654,0.505171057,0.82258
1610.015217,2.994767531,42.10700654,0.505171057,0.82366
1611.011173,2.997238695,41.0487515,0.517607354,0.82478
1613.011159,3.002201058,41.19465985,0.515892682,0.82589
1616.011139,3.009644602,41.19465985,0.515892682,0.82713
1619.011118,3.017088147,41.10960958,0.516892168,0.82844
1619.011118,3.017088147,41.10960958,0.516892168,0.82958
1622.011097,3.024531692,41.10960958,0.516892168,0.83078
1623.011091,3.027012873,41.10960958,0.516892168,0.83189
1625.011077,3.031975237,41.10960958,0.516892168,0.83301
1627.011063,3.0369376,41.10960958,0.516892168,0.83406
1630.011043,3.044381146,41.10960958,0.516892168,0.83503
1631.011036,3.046862327,41.10960958,0.516892168,0.83611
1634.011016,3.054305873,41.10960958,0.516892168,0.83704
1636.011002,3.059268237,41.10960958,0.516892168,0.83803
1638.010989,3.064230601,41.10960958,0.516892168,0.83904
1639.010982,3.066711783,41.10960958,0.516892168,0.83994
1641.010969,3.071674147,41.19465985,0.515892682,0.84084
1644.010949,3.079117693,41.19465985,0.515892682,0.84171
1646.010936,3.084080057,41.10960958,0.516892168,0.84278
1648.010922,3.089042421,41.19465985,0.515892682,0.844
1649.010916,3.091523604,41.10960958,0.516892168,0.84507
1651.010902,3.096485968,41.10960958,0.516892168,0.84621
1652.010896,3.09896715,41.19465985,0.515892682,0.84744
1655.010876,3.106410697,41.19465985,0.515892682,0.84882
1657.010863,3.111373062,41.10960958,0.516892168,0.84996
1659.01085,3.116335427,41.19465985,0.515892682,0.8513
1660.010843,3.118816609,41.10960958,0.516892168,0.85256
1662.01083,3.123778974,40.19950248,0.527587474,0.85379
1665.010811,3.131222521,41.10960958,0.516892168,0.85504
1667.010798,3.136184886,41.19465985,0.515892682,0.85625
1669.010785,3.141147251,40.19950248,0.527587474,0.85731
1671.010772,3.146109617,42.19004622,0.504195199,0.85833
1673.010759,3.151071982,40.19950248,0.527587474,0.85931
1674.010753,3.153553165,40.19950248,0.527587474,0.86035
1676.01074,3.15851553,41.10960958,0.516892168,0.86143
1678.010727,3.163477895,41.19465985,0.515892682,0.86267
1680.010714,3.168440261,41.10960958,0.516892168,0.86371
1682.010702,3.173402627,41.10960958,0.516892168,0.86463
1683.010695,3.175883809,40.19950248,0.527587474,0.8655
1687.01067,3.185808541,41.10960958,0.516892168,0.86614
1688.014514,3.188299278,41.10960958,0.516892168,0.86669
1690.014497,3.193261633,41.19465985,0.515892682,0.86717
1691.014488,3.19574281,41.10960958,0.516892168,0.86772
1694.014463,3.203186342,41.10960958,0.516892168,0.86815
1696.010613,3.208139188,41.10960958,0.516892168,0.86879
1698.010601,3.213101554,41.19465985,0.515892682,0.8696
1700.010588,3.218063921,41.19465985,0.515892682,0.87066
1701.010582,3.220545104,41.19465985,0.515892682,0.87176
1704.010563,3.227988653,41.10960958,0.516892168,0.87263
1706.010551,3.23295102,41.10960958,0.516892168,0.87367
1707.010545,3.235432203,41.19465985,0.515892682,0.87485
1710.010526,3.242875753,41.10960958,0.516892168,0.876
1712.010514,3.24783812,41.10960958,0.516892168,0.87701
1713.010508,3.250319303,41.19465985,0.515892682,0.8783
1715.010496,3.25528167,40.11234224,0.528611755,0.87946
1717.010483,3.260244037,40.11234224,0.528611755,0.88054
1720.010465,3.267687587,40.19950248,0.527587474,0.88176
1721.010459,3.270168771,40.11234224,0.528611755,0.88278
1723.010447,3.275131138,40.11234224,0.528611755,0.8838
1725.010435,3.280093505,40.11234224,0.528611755,0.88482
1726.010429,3.282574689,40.11234224,0.528611755,0.88583
1729.010411,3.29001824,40.19950248,0.527587474,0.887
1731.010399,3.294980607,40.11234224,0.528611755,0.88804
1732.010393,3.297461791,40.19950248,0.527587474,0.88894
1735.010375,3.304905342,40.19950248,0.527587474,0.8899
1737.010363,3.30986771,40.11234224,0.528611755,0.8907
1739.014088,3.314839352,40.19950248,0.527587474,0.8916
1740.01408,3.31732053,40.19950248,0.527587474,0.89232
1742.014064,3.322282887,40.19950248,0.527587474,0.89315
1745.010315,3.329717181,40.11234224,0.528611755,0.89395
1746.014032,3.332207602,40.19950248,0.527587474,0.89488
1749.014008,3.339651138,40.19950248,0.527587474,0.89588
1750.010286,3.342123101,40.19950248,0.527587474,0.89675
1753.010268,3.349566653,40.19950248,0.527587474,0.89757
1754.010262,3.352047837,40.19950248,0.527587474,0.89853
1755.010256,3.354529021,39.20459157,0.539279369,0.89954
1758.010239,3.361972574,39.11521443,0.540329703,0.90066
1759.010233,3.364453758,39.20459157,0.539279369,0.90166
1761.010221,3.369416126,40.11234224,0.528611755,0.90261
1764.010204,3.376859679,40.19950248,0.527587474,0.90336
1766.010192,3.381822047,40.19950248,0.527587474,0.90416
1767.010187,3.384303232,40.19950248,0.527587474,0.90515
1769.010175,3.3892656,40.19950248,0.527587474,0.90604
1771.010164,3.394227969,40.11234224,0.528611755,0.90686
1773.010152,3.399190338,40.19950248,0.527587474,0.90758
1775.010141,3.404152707,40.31128874,0.526273795,0.90877
1776.010135,3.406633891,40.19950248,0.527587474,0.90984
1779.010118,3.414077445,40.19950248,0.527587474,0.91094
1780.010112,3.416558629,40.31128874,0.526273795,0.91173
1782.010101,3.421520998,40.11234224,0.528611755,0.91243
1785.010084,3.428964552,40.19950248,0.527587474,0.91348
1786.010078,3.431445737,40.19950248,0.527587474,0.91474
1789.006987,3.438881663,39.20459157,0.539279369,0.91614
1790.010056,3.441370475,39.11521443,0.540329703,0.91764
1792.010045,3.446332845,39.20459157,0.539279369,0.91901
1794.010033,3.451295214,39.20459157,0.539279369,0.92046
1796.010022,3.456257584,39.20459157,0.539279369,0.92175
1798.010011,3.461219953,39.20459157,0.539279369,0.92286
1800.01,3.466182323,39.20459157,0.539279369,0.92395
1801.009994,3.468663508,39.20459157,0.539279369,0.92512
1803.009983,3.473625877,39.20459157,0.539279369,0.92624
1805.009972,3.478588247,40.19950248,0.527587474,0.92731
1807.009961,3.483550617,39.11521443,0.540329703,0.92826
1809.00995,3.488512987,40.19950248,0.527587474,0.92926
1811.009939,3.493475357,40.19950248,0.527587474,0.93055
1814.009923,3.500918912,40.19950248,0.527587474,0.93179
1815.009917,3.503400097,40.19950248,0.527587474,0.93303
1817.009906,3.508362467,40.19950248,0.527587474,0.93409
1819.009896,3.513324837,39.11521443,0.540329703,0.9353
1822.009879,3.520768393,39.20459157,0.539279369,0.93654
1823.009874,3.523249578,39.11521443,0.540329703,0.93792
1825.009863,3.528211948,39.20459157,0.539279369,0.93909
1827.009852,3.533174319,39.20459157,0.539279369,0.93987
1830.006831,3.540610417,39.20459157,0.539279369,0.94059
1831.006827,3.543091607,39.20459157,0.539279369,0.94114
1833.006819,3.548053986,39.20459157,0.539279369,0.94162
1835.009809,3.553023801,39.20459157,0.539279369,0.94217
1836.009804,3.555504986,39.3192065,0.537932449,0.94284
1837.009799,3.557986172,39.20459157,0.539279369,0.94361
1841.009777,3.567910913,39.20459157,0.539279369,0.94459
1842.009772,3.570392099,39.3192065,0.537932449,0.94572
1845.009756,3.577835655,39.11521443,0.540329703,0.94698
1846.009751,3.580316841,39.20459157,0.539279369,0.94795
1849.009735,3.587760397,39.20459157,0.539279369,0.94901
1850.00973,3.590241583,39.3192065,0.537932449,0.95005
1853.009714,3.59768514,39.20459157,0.539279369,0.95121
1854.009709,3.600166325,39.20459157,0.539279369,0.95239
1857.009693,3.607609882,39.20459157,0.539279369,0.95359
1858.009688,3.610091068,38.20994635,0.550968142,0.9549
1861.009672,3.617534625,38.20994635,0.550968142,0.95629
1862.009667,3.620015811,38.20994635,0.550968142,0.95754
1863.009662,3.622496997,38.20994635,0.550968142,0.95876
1865.009651,3.627459368,38.20994635,0.550968142,0.95984
1869.009631,3.637384111,39.11521443,0.540329703,0.96093
1870.009626,3.639865297,38.20994635,0.550968142,0.96204
1871.006681,3.642339189,39.11521443,0.540329703,0.96309
1874.00667,3.649782759,39.20459157,0.539279369,0.96408
1876.006663,3.654745138,39.20459157,0.539279369,0.96509
1877.00666,3.657226328,39.3192065,0.537932449,0.96603
1879.00958,3.66219597,39.20459157,0.539279369,0.96715
1880.009574,3.664677156,39.20459157,0.539279369,0.96835
1883.009559,3.672120714,39.11521443,0.540329703,0.96925
1885.009549,3.677083086,39.20459157,0.539279369,0.97033
1887.009539,3.682045459,39.20459157,0.539279369,0.97159
1889.009529,3.687007831,39.11521443,0.540329703,0.97263
1891.009519,3.691970203,39.11521443,0.540329703,0.97362
1893.009509,3.696932575,38.11823711,0.552045882,0.97482
1895.009499,3.701894948,39.20459157,0.539279369,0.97616
1896.009494,3.704376134,39.11521443,0.540329703,0.97754
1898.009484,3.709338506,38.20994635,0.550968142,0.97886
1901.009469,3.716782065,38.20994635,0.550968142,0.98013
1902.009464,3.719263251,38.20994635,0.550968142,0.98129
1904.009454,3.724225624,38.20994635,0.550968142,0.98257
1906.009444,3.729187996,38.32753579,0.549586266,0.98383
1907.009439,3.731669183,38.20994635,0.550968142,0.98518
1908.009434,3.734150369,38.20994635,0.550968142,0.98653
1912.009414,3.744075114,38.20994635,0.550968142,0.98777
1913.009409,3.746556301,38.20994635,0.550968142,0.98895
1915.009399,3.751518674,38.20994635,0.550968142,0.99008
1916.009395,3.75399986,38.20994635,0.550968142,0.99124
1918.006517,3.758955118,38.20994635,0.550968142,0.99231
1920.00651,3.763917499,38.11823711,0.552045882,0.99354
1922.006504,3.768879879,38.20994635,0.550968142,0.99474
1924.006497,3.773842259,38.11823711,0.552045882,0.99597
1926.009346,3.778811725,38.20994635,0.550968142,0.99726
1928.006483,3.78376702,38.11823711,0.552045882,0.99836
1931.009322,3.791217658,38.11823711,0.552045882,0.99951
1932.00647,3.793691782,38.32753579,0.549586266,1.0006
1933.009312,3.796180032,38.20994635,0.550968142,1.00159
1935.00646,3.801135353,38.32753579,0.549586266,1.00271
1938.009288,3.808585965,37.21558813,0.562653543,1.00387
1940.009278,3.813548339,38.20994635,0.550968142,1.00515
1941.009274,3.816029525,37.21558813,0.562653543,1.00639
1943.009264,3.820991899,37.33630941,0.561234862,1.00766
1945.009254,3.825954273,37.21558813,0.562653543,1.0086
1948.00924,3.833397833,38.32753579,0.549586266,1.00953
1950.009231,3.838360207,37.21558813,0.562653543,1.0105
1951.009226,3.840841394,38.20994635,0.550968142,1.01145
1953.009217,3.845803767,38.20994635,0.550968142,1.01253
1955.009207,3.850766141,38.20994635,0.550968142,1.0134
1956.009202,3.853247328,38.20994635,0.550968142,1.01415
1958.009193,3.858209702,38.20994635,0.550968142,1.01479
1960.009184,3.863172076,38.32753579,0.549586266,1.01535
1962.009174,3.86813445,38.20994635,0.550968142,1.01584
1964.009165,3.873096824,38.20994635,0.550968142,1.0164
1966.009156,3.878059198,38.20994635,0.550968142,1.01693
1968.009146,3.883021572,38.32753579,0.549586266,1.0173
1970.009137,3.887983947,38.32753579,0.549586266,1.01779
1972.009128,3.892946321,38.32753579,0.549586266,1.01816
1973.009123,3.895427508,38.20994635,0.550968142,1.01894
1975.009114,3.900389882,38.32753579,0.549586266,1.01955
1977.009105,3.905352257,38.32753579,0.549586266,1.02037
1979.006316,3.910307735,38.20994635,0.550968142,1.02129
1980.009091,3.912795818,38.20994635,0.550968142,1.02236
1983.006304,3.920232498,38.20994635,0.550968142,1.02349
1985.006297,3.92519488,38.20994635,0.550968142,1.02472
1986.006294,3.92767607,37.33630941,0.561234862,1.02616
1988.006288,3.932638452,37.33630941,0.561234862,1.02745
1989.006285,3.935119643,37.33630941,0.561234862,1.02886
1991.009041,3.940088878,37.21558813,0.562653543,1.0299
1994.009027,3.947532441,37.12142239,0.56376015,1.03092
1993.009032,3.945051253,37.33630941,0.561234862,1.03107