File: PVC P2 Test_4.csv
Axial Displacement (mm),Axial Strain (pxl/pxl),Transverse Displacement (mm),Transverse Strain (pxl/pxl),Stress (MPa)
455.00989000240423,0.0,76.16429609731846,0.0,3e-05
457.0098467210526,0.004395413731859344,76.16429609731846,0.0,0.00166
460.00978250467676,0.010988535880497259,76.23647421018367,0.0009476633614914745,0.00321
464.00969817451016,0.01977936825078324,76.16429609731846,0.0,0.00493
466.00429182572987,0.024162995277459878,76.10519036176179,0.0007760294335438804,0.00653
469.00959478458435,0.03076791315921978,74.16872656315464,0.026200853108574573,0.00808
472.00953380201975,0.037361042414980665,75.16648189186454,0.013100813065730557,0.00976
475.009473589738,0.04395417336363407,74.10802925459562,0.026997779118124485,0.01143
478.0041840821061,0.050535811605282664,74.10802925459562,0.026997779118124485,0.01293
481.01663172909105,0.05715643175700949,74.16872656315464,0.026200853108574573,0.01447
484.0041322137653,0.06372222417233137,74.10802925459562,0.026997779118124485,0.01605
486.00411520891464,0.06811769565348709,74.10802925459562,0.026997779118124485,0.01763
490.0091835874099,0.07691985241204477,74.10802925459562,0.026997779118124485,0.01918
492.0040650238573,0.08130411191997962,73.10950690573696,0.04010788976081724,0.02077
496.0040322416744,0.09009505758007491,73.10950690573696,0.04010788976081724,0.02235
499.0040079999358,0.09668826758314886,72.11102550927978,0.05321746271848466,0.0239
502.008964063392,0.10329242307401149,72.17340230306452,0.052398485888382605,0.02556
504.0039682383463,0.10767695233104319,72.17340230306452,0.052398485888382605,0.02713
507.0039447578293,0.11427016400709515,72.17340230306452,0.052398485888382605,0.0286
510.0039215535504,0.12086337629025073,72.17340230306452,0.052398485888382605,0.03017
513.0038986206634,0.1274565891698591,72.17340230306452,0.052398485888382605,0.03171
516.0038759544351,0.1340498026355176,72.11102550927978,0.05321746271848466,0.03324
518.0086871858425,0.1384558853942832,71.11258679024411,0.06632647534245649,0.03474
521.0086371644908,0.1450490387400982,71.11258679024411,0.06632647534245649,0.03628
524.0085877158884,0.15164219334467569,71.11258679024411,0.06632647534245649,0.03779
527.0037950527491,0.1582249235285071,71.11258679024411,0.06632647534245649,0.03932
529.0037807048263,0.16262040084893786,71.11258679024411,0.06632647534245649,0.04088
533.0037523320075,0.17141135619973258,71.11258679024411,0.06632647534245649,0.04236
535.0084111488342,0.17581710398867864,71.11258679024411,0.06632647534245649,0.04393
538.0083642472484,0.18241026419097317,70.178344238091,0.0785926236563513,0.04548
540.0037036910024,0.18679553028649357,69.18092222571191,0.09168828741860337,0.04707
544.0036764581652,0.1955864881426878,70.178344238091,0.0785926236563513,0.04864
545.0036697124158,0.197784227744008,69.18092222571191,0.09168828741860337,0.05005
549.0036429751627,0.2065751866893747,69.18092222571191,0.09168828741860337,0.05169
551.0036297521098,0.21097066648199295,69.18092222571191,0.09168828741860337,0.05324
554.0036100965408,0.21756388656434147,69.1158447825099,0.09254272245623389,0.05481
557.0035906526995,0.22415710711201534,69.1158447825099,0.09254272245623389,0.05628
560.003571417183,0.23075032811753612,69.1158447825099,0.09254272245623389,0.0579
562.0035587075939,0.23514580903862187,68.11754546370561,0.10564990482326732,0.05943
565.0035398119201,0.2417390307910332,69.18092222571191,0.09168828741860337,0.06102
568.0035211158466,0.24833225298211728,69.18092222571191,0.09168828741860337,0.06256
571.0035026162274,0.2549254756049593,68.18357573492314,0.10478295961926834,0.06419
573.0034903907654,0.2593209575900376,67.1863081289633,0.11787659610066616,0.06569
576.0034722117567,0.2659141809175031,67.1863081289633,0.11787659610066616,0.06736
579.0034542211298,0.2725074046589853,67.1863081289633,0.11787659610066616,0.06884
581.0034423305941,0.27690288738014934,67.1863081289633,0.11787659610066616,0.07049
584.0034246474929,0.2834961117974976,67.1863081289633,0.11787659610066616,0.07203
587.0034071451374,0.2900893366120806,67.1863081289633,0.11787659610066616,0.0737
589.0033955759508,0.29448482003949084,67.1863081289633,0.11787659610066616,0.0753
592.0033783687387,0.3010780455027266,67.1863081289633,0.11787659610066616,0.07694
594.0008417502453,0.30546797949184495,67.1863081289633,0.11787659610066616,0.07851
596.0033556952511,0.30986901337925177,66.18912297349165,0.13096915004743287,0.08022
599.0033388888579,0.31646223972338894,66.27216610312357,0.12987883432356917,0.08184
602.003322249969,0.3230554664356593,66.18912297349165,0.13096915004743287,0.08346
604.0008278140023,0.32744549313161253,65.19202405202648,0.1440605717838214,0.08508
607.0074134637896,0.3340532300530483,65.19202405202648,0.1440605717838214,0.08671
609.0032840633949,0.33843966349869214,65.19202405202648,0.1440605717838214,0.08837
613.0073409022114,0.347239597141443,65.19202405202648,0.1440605717838214,0.09003
615.0032520239222,0.3516261196447237,65.19202405202648,0.1440605717838214,0.09172
617.0032414825712,0.3560216053310643,65.19202405202648,0.1440605717838214,0.09337
620.0032257980598,0.36261483414082224,65.19202405202648,0.1440605717838214,0.09503
622.0032154257725,0.36701032019872337,65.19202405202648,0.1440605717838214,0.09673
624.0032051199737,0.3714058064027499,65.19202405202648,0.1440605717838214,0.09846
627.0031897845497,0.3779990359797161,65.19202405202648,0.1440605717838214,0.10014
629.0031796422018,0.3823945225429675,64.19501538281614,0.15715080855219413,0.10182
632.0031645490393,0.38898775265236507,64.28063471995279,0.15602666848232136,0.10354
635.0031495984882,0.39558098307518746,64.28063471995279,0.15602666848232136,0.10522
637.0031397096877,0.3999764701956739,64.19501538281614,0.15715080855219413,0.10699
639.0031298827886,0.4043719574522043,64.28063471995279,0.15602666848232136,0.10872
642.0031152572392,0.41096518858930053,64.28063471995279,0.15602666848232136,0.11045
645.0031007677405,0.41755842002540294,63.28506932918696,0.16909795570978747,0.11215
647.0030911827238,0.4219539078135314,63.28506932918696,0.16909795570978747,0.11389
649.0030816567822,0.42634939573149266,63.198101237299845,0.17023980427064062,0.11564
651.0069124056979,0.4307533236305216,63.28506932918696,0.16909795570978747,0.11736
654.0068806977492,0.43734651722469925,63.198101237299845,0.17023980427064062,0.11921
656.0030487734032,0.44173360444964593,64.19501538281614,0.15715080855219413,0.12093
659.0068284926948,0.44833517462491346,64.19501538281614,0.15715080855219413,0.12275
661.0068078318104,0.45273063807100483,63.28506932918696,0.16909795570978747,0.12454
664.0030120413611,0.45931555913620375,62.289646009589745,0.1821673776122143,0.1263
666.0067567224825,0.46371929787935673,62.289646009589745,0.1821673776122143,0.1281
668.0067364929788,0.468114762273517,62.289646009589745,0.1821673776122143,0.12993
670.0067163842464,0.47251022693310274,62.289646009589745,0.1821673776122143,0.13168
674.0066765247952,0.4813011570391005,62.289646009589745,0.1821673776122143,0.13349
676.0066567719581,0.4856966224808567,62.289646009589745,0.1821673776122143,0.13528
678.0066371356552,0.4900920881787265,62.289646009589745,0.1821673776122143,0.13716
681.0066078974564,0.496685287200808,62.289646009589745,0.1821673776122143,0.139
683.0029282514095,0.5010727090960606,62.289646009589745,0.1821673776122143,0.1409
685.006569311565,0.5054762201057773,62.289646009589745,0.1821673776122143,0.14282
688.0029069706028,0.5120614344601773,62.289646009589745,0.1821673776122143,0.14471
690.0028985446365,0.516456924795614,62.289646009589745,0.1821673776122143,0.14646
692.002890167375,0.5208524152380918,62.289646009589745,0.1821673776122143,0.14831
696.0028735572864,0.5296433964404791,62.289646009589745,0.1821673776122143,0.1502
697.0028694345526,0.5318411418065434,62.289646009589745,0.1821673776122143,0.15206
699.0028612244731,0.5362366326164463,61.29437168288782,0.1952348433107119,0.15396
702.0028489970679,0.5428298690240745,60.29925372672534,0.2083002559404167,0.15583
705.002836873725,0.5494231056604062,60.29925372672534,0.2083002559404167,0.15775
707.0028288486546,0.5538185968769138,60.29925372672534,0.2083002559404167,0.15972
709.0028208688594,0.5582140881929251,60.29925372672534,0.2083002559404167,0.16153
711.0063290857544,0.5626173072457776,60.29925372672534,0.2083002559404167,0.16346
713.0028050435707,0.5670050711201096,60.29925372672534,0.2083002559404167,0.16538
716.0027932906407,0.573598308570518,60.29925372672534,0.2083002559404167,0.16732
718.0062673821169,0.5780014526240803,60.29925372672534,0.2083002559404167,0.16921
720.0027777724194,0.5823892921725614,60.29925372672534,0.2083002559404167,0.17124
723.0062240395998,0.5889901295019753,60.29925372672534,0.2083002559404167,0.17324
723.0110649222459,0.5890007685732402,60.29925372672534,0.2083002559404167,0.17526
724.0062154429339,0.5911878650354354,60.29925372672534,0.2083002559404167,0.17716
727.0061897948325,0.5977810719476692,59.413803110051795,0.2199257899772857,0.1791
730.0061643575348,0.6043742793231978,59.30430001273095,0.22136351215069003,0.18103
732.0061475151695,0.6087697511614563,59.413803110051795,0.2199257899772857,0.18286
734.0108991016414,0.6131757028353009,59.413803110051795,0.2199257899772857,0.18485
737.0061058091717,0.6197584316360187,59.413803110051795,0.2199257899772857,0.18689
739.010825360495,0.6241643129044736,59.413803110051795,0.2199257899772857,0.18886
741.0060728496089,0.6285493769062768,59.413803110051795,0.2199257899772857,0.19081
743.0060565029063,0.6329448498338801,59.413803110051795,0.2199257899772857,0.19283
745.0060402439701,0.6373403229543726,59.413803110051795,0.2199257899772857,0.191
748.010695110705,0.6439438164888077,59.413803110051795,0.2199257899772857,0.1932
750.0059999760002,0.6483290065893672,59.413803110051795,0.2199257899772857,0.19536
752.0106382226252,0.6527347091700614,59.413803110051795,0.2199257899772857,0.19744
754.0059681461414,0.6571199543424371,59.413803110051795,0.2199257899772857,0.19956
758.0105540162353,0.6659210506660198,58.309518948453004,0.23442450155452918,0.20168
760.0105262428935,0.6703164984806763,58.309518948453004,0.23442450155452918,0.20381
762.0104986153406,0.674711946615741,58.309518948453004,0.23442450155452918,0.20579
764.0058900296515,0.6790973269297829,58.309518948453004,0.23442450155452918,0.20788
767.0104301768001,0.6857005683387394,58.309518948453004,0.23442450155452918,0.20995
769.0058517332621,0.6900860148978274,58.309518948453004,0.23442450155452918,0.21199
771.0103760650695,0.6944914671217269,58.309518948453004,0.23442450155452918,0.21403
773.0103492192068,0.6988869169747547,58.309518948453004,0.23442450155452918,0.21604
775.0103225119004,0.7032823671322954,58.309518948453004,0.23442450155452918,0.21813
778.0102827083971,0.7098755429344319,58.309518948453004,0.23442450155452918,0.22025
781.0102432106764,0.7164687194086037,58.42088667591412,0.2329622976982917,0.22232
783.0102170470063,0.7208641707609235,58.42088667591412,0.2329622976982917,0.22442
786.0101780511496,0.727457348338069,58.42088667591412,0.2329622976982917,0.22641
788.0101522188658,0.7318528004186942,58.42088667591412,0.2329622976982917,0.2284
790.0101265173757,0.7362482527867722,58.42088667591412,0.2329622976982917,0.2305
792.0101009456887,0.7406437054401253,57.42821606144492,0.24599557792713825,0.23256
795.0100628293959,0.7472368849503362,57.42821606144492,0.24599557792713825,0.23457
797.0100375779467,0.7516323383074934,56.43580423808985,0.2590254603550809,0.23658
799.0100124529104,0.756027791942475,56.43580423808985,0.2590254603550809,0.23868
803.0099625782983,0.7648187000376085,56.43580423808985,0.2590254603550809,0.24071
805.0099378268569,0.7692141544936602,56.43580423808985,0.2590254603550809,0.24276
807.0099131980969,0.7736096092193353,56.43580423808985,0.2590254603550809,0.24487
809.0098886911087,0.7780050642126349,56.43580423808985,0.2590254603550809,0.24696
812.0098521569797,0.7845982472000534,56.43580423808985,0.2590254603550809,0.24907
814.0098279504984,0.7889937028537936,56.568542494923804,0.2572826718881023,0.25113
816.0098038626742,0.7933891587683126,56.568542494923804,0.2572826718881023,0.25321
819.0097679515184,0.7999823431248732,56.43580423808985,0.2590254603550809,0.2553
821.0097441565478,0.8043777996830126,56.43580423808985,0.2590254603550809,0.25738
824.0097086806684,0.8109709849962039,56.43580423808985,0.2590254603550809,0.25943
826.009685173243,0.8153664421862973,56.43580423808985,0.2590254603550809,0.26146
828.009661779378,0.8197618996259682,56.43580423808985,0.2590254603550809,0.26343
831.0096268997129,0.826355086249492,56.43580423808985,0.2590254603550809,0.26546
833.0096037861748,0.830750544305253,56.43580423808985,0.2590254603550809,0.26749
835.0095807833584,0.8351460026043528,56.43580423808985,0.2590254603550809,0.26956
839.0095351067233,0.8439369199256088,55.44366510251645,0.2720517625256636,0.27161
841.0095124313399,0.8483323789443259,55.44366510251645,0.2720517625256636,0.27356
843.0094898635483,0.8527278381995036,55.44366510251645,0.2720517625256636,0.27572
845.0094674025847,0.8571232976894629,55.44366510251645,0.2720517625256636,0.2778
848.0094339097885,0.8637164873609839,55.44366510251645,0.2720517625256636,0.27984
850.0094117125998,0.8681119474306557,55.44366510251645,0.2720517625256636,0.28192
853.0093786119822,0.8747051379640891,55.44366510251645,0.2720517625256636,0.28391
856.0093457433744,0.881298329007423,55.57877292636101,0.27027786280141575,0.28604
858.0093239586619,0.885693789983616,55.57877292636101,0.27027786280141575,0.28816
860.0093022752719,0.8900892511824913,55.326304774492215,0.2735926462997915,0.29025
863.0092699386258,0.8966824433949464,55.57877292636101,0.27027786280141575,0.29241
865.0144507463444,0.9010893383916859,55.57877292636101,0.27027786280141575,0.29442
867.0092271711991,0.9054733671099279,55.57877292636101,0.27027786280141575,0.29641
870.0091953537043,0.91206656046335,55.57877292636101,0.27027786280141575,0.29844
873.0091637548829,0.9186597542973627,55.57877292636101,0.27027786280141575,0.30055
875.0142855976695,0.9230665197036619,55.44366510251645,0.2720517625256636,0.3026
878.0142367866252,0.9296596757094354,55.44366510251645,0.2720517625256636,0.30469
880.0142044308149,0.9340551134529514,54.45181356024793,0.2850742887366482,0.30662
882.0141722217393,0.9384505515189544,54.589376255824725,0.28326815774580927,0.30869
886.014108239818,0.9472414286096867,53.46026561849464,0.2980928288211826,0.31057
888.0140764650074,0.9516368676300975,53.46026561849464,0.2980928288211826,0.31268
890.0140448330015,0.956032306964358,53.600373133029585,0.29625328560061737,0.31472
893.0139976506528,0.9626254665496043,53.46026561849464,0.2980928288211826,0.31688
895.0139663714751,0.9670209066592947,53.600373133029585,0.29625328560061737,0.31896
898.013919713943,0.9736140673979591,53.600373133029585,0.29625328560061737,0.32109
901.0138733671085,0.9802072288194608,53.600373133029585,0.29625328560061737,0.3231
903.0138426402997,0.984602670143122,53.600373133029585,0.29625328560061737,0.32521
905.0138120492968,0.9889981117652515,53.600373133029585,0.29625328560061737,0.32711
908.0137664154657,0.9955912747537594,53.600373133029585,0.29625328560061737,0.32917
910.0137361600648,0.9999867171134597,53.600373133029585,0.29625328560061737,0.33119
914.0136760464802,1.008777602705846,53.46026561849464,0.2980928288211826,0.33318
916.013646186562,1.01317304593472,53.600373133029585,0.29625328560061737,0.33531
918.0136164567496,1.0175684894495345,53.600373133029585,0.29625328560061737,0.33724
921.0135721041248,1.0241616552538193,53.600373133029585,0.29625328560061737,0.3393
924.0135280394979,1.0307548216910527,52.46903848937962,0.31110715679249984,0.34145
926.0134988216964,1.0351502663311416,52.46903848937962,0.31110715679249984,0.34348
929.0134552308701,1.0417434338096723,52.61178575186362,0.30923295497093234,0.34565
931.0134263263876,1.0461388791383595,52.61178575186362,0.30923295497093234,0.34771
934.0133832017611,1.052732047641483,52.46903848937962,0.31110715679249984,0.34964
937.0133403532737,1.0593252167514922,52.61178575186362,0.30923295497093234,0.35168
939.013311939719,1.0637206631591178,52.61178575186362,0.30923295497093234,0.35371
941.0085015556448,1.0681055999698656,52.61178575186362,0.30923295497093234,0.3557
945.0084655705472,1.076896538590741,52.61178575186362,0.30923295497093234,0.35765
946.0084566218211,1.0790942733504594,52.61178575186362,0.30923295497093234,0.35952
950.013157803617,1.0878956231008456,52.61178575186362,0.30923295497093234,0.36154
952.0084033242564,1.092280682776425,52.61178575186362,0.30923295497093234,0.36351
955.008376926611,1.0988738880413453,52.61178575186362,0.30923295497093234,0.36557
957.0130615618576,1.103279692572838,52.61178575186362,0.30923295497093234,0.36765
960.0083332971647,1.1098625642886402,52.61178575186362,0.30923295497093234,0.36969
963.0083073369617,1.1164557705149514,52.61178575186362,0.30923295497093234,0.37163
965.008290119831,1.1208512415295677,52.61178575186362,0.30923295497093234,0.37369
967.0082729739182,1.1252467127007033,51.62363799656123,0.3222068522684245,0.37568
971.0128732411326,1.1340478406656211,51.62363799656123,0.3222068522684245,0.37767
973.0128467805552,1.1384432913654117,51.62363799656123,0.3222068522684245,0.3797
975.0082050936802,1.1428285989311757,51.62363799656123,0.3222068522684245,0.38169
979.0081715695737,1.151619542960705,51.62363799656123,0.3222068522684245,0.38364
981.0127420171463,1.156025096535732,51.62363799656123,0.3222068522684245,0.38573
984.0127031700353,1.162618274439784,51.478150704935004,0.3241170293340712,0.38768
986.0126774032877,1.167013726664442,51.78802950489621,0.3200484720724738,0.38973
988.012651740857,1.1714091791183627,51.62363799656123,0.3222068522684245,0.39164
992.0126007264222,1.1802000847084457,51.478150704935004,0.3241170293340712,0.39368
994.012575373169,1.1845955378418627,51.62363799656123,0.3222068522684245,0.3957
997.0125375340072,1.1911887179611391,51.62363799656123,0.3222068522684245,0.39767
999.0125124341537,1.1955841716514666,51.62363799656123,0.3222068522684245,0.39966
1003.0124625347383,1.204375079692089,51.62363799656123,0.3222068522684245,0.40168
1005.0124377339815,1.2087705340397572,51.62363799656123,0.3222068522684245,0.4035
1007.0124130317362,1.2131659886039297,51.62363799656123,0.3222068522684245,0.40551
1011.0123639204419,1.2219568983766478,51.62363799656123,0.3222068522684245,0.40756
1013.0123395102352,1.2263523535826497,50.635955604688654,0.33517463957142235,0.40957
1016.0123030751154,1.2329455367876658,50.635955604688654,0.33517463957142235,0.41152
1019.0122668545262,1.2395387204641677,50.635955604688654,0.33517463957142235,0.41349
1022.0122308465785,1.246131904608004,50.635955604688654,0.33517463957142235,0.41547
1024.0122069584913,1.2505273609614957,50.635955604688654,0.33517463957142235,0.41741
1027.012171300808,1.2571205458751264,50.635955604688654,0.33517463957142235,0.41938
1030.0121358508354,1.2637137312452547,50.635955604688654,0.33517463957142235,0.42124
1033.0121006067645,1.270306917067904,50.635955604688654,0.33517463957142235,0.4231
1035.0120772242226,1.2747023745324604,50.635955604688654,0.33517463957142235,0.42514
1038.0120423193557,1.281295561100597,50.635955604688654,0.33517463957142235,0.42728
1041.0120076156663,1.2878887481108723,50.635955604688654,0.33517463957142235,0.42922
1043.0119845907811,1.2922842063614703,50.80354318352215,0.3329742965311694,0.43123
1046.0119502185432,1.2988773941001945,50.635955604688654,0.33517463957142235,0.43331
1049.0119160429017,1.3054705822709893,50.80354318352215,0.3329742965311694,0.43524
1052.0118820621751,1.3120637708701592,50.80354318352215,0.3329742965311694,0.43702
1054.0118595158215,1.316459230172452,50.80354318352215,0.3329742965311694,0.439
1058.0118146788343,1.325250149339048,50.48762224545735,0.3371221841143637,0.4409
1060.0117923872356,1.3296456092012297,49.64876634922564,0.3481359522342695,0.44291
1062.0117701795964,1.3340410692479339,49.49747468305833,0.35012233790208946,0.4448
1066.0168854197386,1.3428433289968835,49.49747468305833,0.35012233790208946,0.44663
1068.016853799602,1.3472387683572296,49.64876634922564,0.3481359522342695,0.44851
1071.016806590821,1.3538319278843847,49.64876634922564,0.3481359522342695,0.45033
1073.0167752649536,1.3582273678914623,50.48762224545735,0.3371221841143637,0.45217
1077.0167129622455,1.3670182486726927,49.49747468305833,0.35012233790208946,0.45406
1079.0166819841108,1.3714136894440017,49.64876634922564,0.3481359522342695,0.45585
1083.016620371082,1.3802045717409774,50.48762224545735,0.3371221841143637,0.4578
1085.016589734922,1.384600013263863,49.49747468305833,0.35012233790208946,0.45956
1088.0165439918642,1.3911931760123173,50.35871324805669,0.33881469627565186,0.46153
1090.016513636376,1.3955886181520503,49.64876634922564,0.3481359522342695,0.46349
1094.0164532583594,1.40437950316328,50.48762224545735,0.3371221841143637,0.46553
1096.0164232346156,1.4087749460321055,50.48762224545735,0.3371221841143637,0.46746
1099.016378403889,1.4153681107856397,50.35871324805669,0.33881469627565186,0.46933
1102.0163338172442,1.4219612760756062,50.35871324805669,0.33881469627565186,0.47125
1105.0162894726936,1.4285544418976361,49.49747468305833,0.35012233790208946,0.47311
1107.0162600431847,1.4329498860724441,49.49747468305833,0.35012233790208946,0.47487
1110.016216097765,1.4395430527716655,49.36598018878993,0.3518487963741848,0.47684
1113.0161723892425,1.4461362199915289,49.49747468305833,0.35012233790208946,0.47864
1116.016128915707,1.452729387727836,48.507731342539614,0.36311718445399715,0.4804
1119.0160856752686,1.4593225559764333,49.49747468305833,0.35012233790208946,0.48216
1122.0160426660575,1.4659157247332115,49.36598018878993,0.3518487963741848,0.48399
1124.0160141207953,1.4703111708513765,49.49747468305833,0.35012233790208946,0.48571
1126.0159856769353,1.4747066171923988,49.36598018878993,0.3518487963741848,0.48753
1130.0159290912673,1.4834975105382793,49.36598018878993,0.3518487963741848,0.48928
1133.0158869142126,1.490090681123933,49.36598018878993,0.3518487963741848,0.49105
1135.0158589200416,1.4944861284532611,49.36598018878993,0.3518487963741848,0.49286
1139.0158032266277,1.503277023760097,49.36598018878993,0.3518487963741848,0.49472
1141.0157755263508,1.5076724717353325,49.36598018878993,0.3518487963741848,0.49662
1143.0157479230108,1.5120679199236113,49.36598018878993,0.3518487963741848,0.49849
1147.0156930051132,1.5208588169348416,49.36598018878993,0.3518487963741848,0.50033
1150.0156520673968,1.5274519902442563,49.36598018878993,0.3518487963741848,0.50218
1153.01084123264,1.534034680491335,49.36598018878993,0.3518487963741848,0.50411
1156.0155708293898,1.5406383382639914,49.49747468305833,0.35012233790208946,0.50585
1158.010794422919,1.545023349749167,49.36598018878993,0.3518487963741848,0.50777
1162.0154904303126,1.553824688127488,49.36598018878993,0.3518487963741848,0.50954
1164.015463814807,1.558220138486784,48.373546489791295,0.36487896601864084,0.51139
1167.0154240625957,1.5648133144016478,48.507731342539614,0.36311718445399715,0.51315
1170.0209399835544,1.5714187003218152,48.373546489791295,0.36487896601864084,0.51494
1173.0153451681695,1.5779996675719978,48.373546489791295,0.36487896601864084,0.51673
1175.0153190490753,1.5823951190222845,48.507731342539614,0.36311718445399715,0.5187
1179.0152670767245,1.5911860225071035,48.507731342539614,0.36311718445399715,0.52071
1181.0152412225677,1.5955814745396573,48.373546489791295,0.36487896601864084,0.5227
1185.0151897760636,1.604372379180158,48.373546489791295,0.36487896601864084,0.52449
1187.0151641828338,1.6087678317861656,48.373546489791295,0.36487896601864084,0.52621
1191.0151132542358,1.6175587375648965,48.373546489791295,0.36487896601864084,0.52787
1193.0150879180028,1.62195419073572,48.373546489791295,0.36487896601864084,0.52956
1196.0150500725315,1.62854737084113,48.373546489791295,0.36487896601864084,0.53128
1198.015024947517,1.63294282447616,48.373546489791295,0.36487896601864084,0.53295
1202.0149749483157,1.6417337322974768,48.373546489791295,0.36487896601864084,0.5347
1204.0149500732955,1.6461291864819323,48.373546489791295,0.36487896601864084,0.53641
1207.0149129153292,1.6527223680983096,48.507731342539614,0.36311718445399715,0.53813
1211.0148636577505,1.661513277549531,48.373546489791295,0.36487896601864084,0.53992
1213.014839150783,1.665908732542876,48.373546489791295,0.36487896601864084,0.54168
1217.01479037849,1.6746996430606362,47.38143096192854,0.3779049582315156,0.54346
1219.0147661123715,1.6790950985833082,47.51841748206689,0.37610639214271047,0.54521
1221.0147419257476,1.68349055428069,47.38143096192854,0.3779049582315156,0.54698
1224.0147057940112,1.6900837381524687,47.51841748206689,0.37610639214271047,0.54873
1227.0146698389551,1.696676922412547,47.38143096192854,0.3779049582315156,0.55045
1230.0146340592862,1.7032701070580836,47.51841748206689,0.37610639214271047,0.55213
1233.0145984537246,1.7098632920862653,47.51841748206689,0.37610639214271047,0.55389
1236.0145630210027,1.716456477494306,47.51841748206689,0.37610639214271047,0.55558
1238.0145394945894,1.7208519346426685,47.38143096192854,0.3779049582315156,0.55716
1242.014492669067,1.7296428494389524,47.38143096192854,0.3779049582315156,0.55886
1245.0144577473789,1.7362360359701199,47.51841748206689,0.37610639214271047,0.56065
1247.0144345596004,1.7406314938627185,47.38143096192854,0.3779049582315156,0.56232
1251.0143884064644,1.7494224101367424,47.38143096192854,0.3779049582315156,0.56414
1253.0143654403967,1.753817868516607,47.51841748206689,0.37610639214271047,0.56578
1257.0143197275042,1.7626087857581783,47.51841748206689,0.37610639214271047,0.56752
1259.0142969799826,1.7670042446183534,47.38143096192854,0.3779049582315156,0.56918
1262.0142629938855,1.77359743320572,46.52956049652737,0.3890896012867432,0.57091
1265.0193674406728,1.7802019148067056,47.38143096192854,0.3779049582315156,0.57261
1268.0141955041356,1.786783811440748,46.389654018972806,0.3909265049899665,0.57444
1271.0192760143334,1.793388240434988,46.389654018972806,0.3909265049899665,0.5763
1274.0192306240906,1.799981403958843,46.52956049652737,0.3890896012867432,0.57797
1277.01918544711,1.806574567951396,46.52956049652737,0.3890896012867432,0.57957
1280.0191404818913,1.81316773240935,46.52956049652737,0.3890896012867432,0.58122
1283.01909572695,1.8197608973294415,46.52956049652737,0.3890896012867432,0.58285
1285.0190660064154,1.8241563408646468,46.52956049652737,0.3890896012867432,0.58448
1288.019021598672,1.8307495065477943,46.52956049652737,0.3890896012867432,0.5862
1291.0189773973116,1.837342672684521,46.52956049652737,0.3890896012867432,0.5879
1294.018933400899,1.8439358392716725,46.52956049652737,0.3890896012867432,0.58956
1298.0188750553668,1.852726728749804,46.389654018972806,0.3909265049899665,0.59129
1300.0188460172415,1.857122173784777,46.389654018972806,0.3909265049899665,0.59314
1303.0188026271915,1.8637153417045647,46.389654018972806,0.3909265049899665,0.59482
1306.018759436479,1.8703085100624475,46.389654018972806,0.3909265049899665,0.59648
1309.0187164437336,1.8769016788554131,46.389654018972806,0.3909265049899665,0.59815
1312.018673647597,1.8834948480804767,46.389654018972806,0.3909265049899665,0.59972
1315.018631046724,1.8900880177346817,46.389654018972806,0.3909265049899665,0.60142
1317.0186027539626,1.8944834644077813,46.389654018972806,0.3909265049899665,0.60309
1321.013625970603,1.9032635443674044,46.52956049652737,0.3890896012867432,0.60459
1323.018518388915,1.907669805555049,45.5411901469428,0.40206642113841856,0.60627
1326.0184764926921,1.9142629767579018,46.52956049652737,0.3890896012867432,0.60787
1330.0184209250638,1.9230538723411836,45.5411901469428,0.40206642113841856,0.60947
1333.0183794681902,1.9296470445096185,45.5411901469428,0.40206642113841856,0.61117
1335.01348307798,1.9340317923,45.5411901469428,0.40206642113841856,0.61286
1338.0183107865153,1.940635665698267,45.5411901469428,0.40206642113841856,0.61454
1342.013412749664,1.9494159187233773,45.5411901469428,0.40206642113841856,0.61614
1345.0133828330484,1.956009116254465,45.5411901469428,0.40206642113841856,0.61771
1348.0181749516585,1.9626129114348165,45.5411901469428,0.40206642113841856,0.61928
1351.0133233984038,1.9691955121926363,45.5411901469428,0.40206642113841856,0.62077
1353.0181077871796,1.9736015359578893,45.39823785126467,0.4039433149456623,0.62229
1357.0132644893342,1.9823819092858923,45.5411901469428,0.40206642113841856,0.62372
1359.013244968569,1.9867773752376858,45.39823785126467,0.4039433149456623,0.62544
1363.013206098899,1.9955683075189792,45.39823785126467,0.4039433149456623,0.62702
1365.0131867494906,1.9999637738473728,45.5411901469428,0.40206642113841856,0.62865
1368.0131578314588,2.0065569735731024,45.5411901469428,0.40206642113841856,0.6302
1372.0131194708015,2.015347906973081,45.39823785126467,0.4039433149456623,0.63167
1374.0131003742285,2.019743373857145,45.5411901469428,0.40206642113841856,0.63335
1378.0130623473785,2.02853430799075,45.5411901469428,0.40206642113841856,0.63511
1380.0130434166192,2.0329297752392312,45.5411901469428,0.40206642113841856,0.63679
1383.0130151231406,2.0395229763375755,45.5411901469428,0.40206642113841856,0.63843
1385.0129963289153,2.043918443886125,45.5411901469428,0.40206642113841856,0.64012
1389.0129589028318,2.0527093793400675,45.5411901469428,0.40206642113841856,0.64173
1392.0129309744216,2.0593025812407424,45.5411901469428,0.40206642113841856,0.6433
1395.012903166132,2.0658957834054132,45.5411901469428,0.40206642113841856,0.64481
1397.0128846936236,2.0702912516610175,45.5411901469428,0.40206642113841856,0.6464
1400.0128570838199,2.0768844542619114,45.70557952810576,0.39990806887119734,0.64805
1404.0128204542864,2.085675391466475,45.70557952810576,0.39990806887119734,0.64964
1407.0127931188117,2.0922685946702764,44.553338819890925,0.41503642647779254,0.65139
1409.0127749598298,2.096664063614935,44.553338819890925,0.41503642647779254,0.653
1412.0127478178092,2.1032572672439014,44.721359549995796,0.4128303963729494,0.65473
1415.0127207908768,2.109850471125803,43.73785545725808,0.42574332464948794,0.65641
1418.0126938783023,2.1164436752590357,44.721359549995796,0.4128303963729494,0.65805
1421.0126670793613,2.1230368796420067,43.73785545725808,0.42574332464948794,0.65956
1424.012640393336,2.1296300842731384,43.56604182158393,0.4279991537515466,0.66111
1427.0126138195135,2.136223289150865,43.73785545725808,0.42574332464948794,0.66283
1429.012596165618,2.1406187592055796,44.553338819890925,0.41503642647779254,0.66427
1433.0125610056598,2.1494096996399086,44.553338819890925,0.41503642647779254,0.66591
1436.0125347642338,2.1560029052481604,43.56604182158393,0.4279991537515466,0.66769
1438.0170374512259,2.1604083099020714,43.73785545725808,0.42574332464948794,0.66938
1442.0124826089404,2.169189317184558,43.56604182158393,0.4279991537515466,0.67114
1445.0124566937131,2.175782523509715,43.56604182158393,0.4279991537515466,0.67267
1447.0169314835262,2.180187866852477,43.73785545725808,0.42574332464948794,0.67421
1451.0168848087192,2.1889787819799964,43.73785545725808,0.42574332464948794,0.67571
1454.012379589665,2.195562143895338,43.73785545725808,0.42574332464948794,0.67723
1457.0168152770234,2.2021651557273283,43.56604182158393,0.4279991537515466,0.67869
1460.016780725482,2.2087583430719877,43.56604182158393,0.4279991537515466,0.68027
1463.0167463156395,2.215351530728066,43.73785545725808,0.42574332464948794,0.68173
1466.016712046626,2.2219447186936523,43.73785545725808,0.42574332464948794,0.68329
1469.016677917579,2.2285379069668503,43.56604182158393,0.4279991537515466,0.68475
1472.0166439276425,2.235131095545779,43.73785545725808,0.42574332464948794,0.68623
1474.016621344549,2.239526554767327,43.56604182158393,0.4279991537515466,0.68779
1478.0165763617133,2.2483174736133833,42.579337712087536,0.4409540966848554,0.68931
1481.0165427840434,2.254910663098373,42.579337712087536,0.4409540966848554,0.69089
1484.01650934213,2.261503852881722,42.579337712087536,0.4409540966848554,0.69238
1486.0164871225352,2.2658993129021505,42.7551166528639,0.43864620506393426,0.69392
1489.0164539050602,2.27249250317876,42.579337712087536,0.4409540966848554,0.69542
1492.0164208211652,2.2790856937489457,42.7551166528639,0.43864620506393426,0.69693
1495.016387870046,2.2856788846109395,42.7551166528639,0.43864620506393426,0.69843
1498.0163550509053,2.29227207576299,42.7551166528639,0.43864620506393426,0.69993
1501.0163223629515,2.2988652672033574,42.7551166528639,0.43864620506393426,0.70141
1505.016278981726,2.3076561895693595,42.7551166528639,0.43864620506393426,0.70298
1507.016257377471,2.3120516509421543,42.7551166528639,0.43864620506393426,0.70452
1510.016225078393,2.318644843237175,42.7551166528639,0.43864620506393426,0.70607
1513.016192907399,2.3252380358136926,42.95346318982906,0.43604201192976905,0.70742
1516.016160863729,2.3318312286700373,42.7551166528639,0.43864620506393426,0.70901
1519.0161289466284,2.3384244218045502,42.7551166528639,0.43864620506393426,0.71053
1521.011834273488,2.3428104920212856,42.95346318982906,0.43604201192976905,0.71207
1524.0118109778546,2.349403704103666,42.95346318982906,0.43604201192976905,0.71379
1528.011780059303,2.3581946538595657,42.95346318982906,0.43604201192976905,0.71535
1530.0160129880994,2.3625994656512077,42.95346318982906,0.43604201192976905,0.71691
1533.0159816518549,2.3691926600623,42.7551166528639,0.43864620506393426,0.71838
1536.0117187052967,2.375776554433093,42.95346318982906,0.43604201192976905,0.7199
1538.0117034665243,2.380172029795655,42.95346318982906,0.43604201192976905,0.72125
1541.0116806825313,2.3867652430024955,41.773197148410844,0.4515383284703977,0.72281
1545.0116504415105,2.395556194247441,42.7551166528639,0.43864620506393426,0.72426
1549.0158165751568,2.4043563680933877,41.773197148410844,0.4515383284703977,0.72585
1551.015796180039,2.408751832123569,41.773197148410844,0.4515383284703977,0.72734
1554.0115829684153,2.415335835799534,41.773197148410844,0.4515383284703977,0.72897
1558.015725209473,2.424135957135438,41.773197148410844,0.4515383284703977,0.73056
1560.0157050491512,2.4285314216816434,41.97618372363071,0.44887321390069823,0.73199
1564.0156648831878,2.4373223511140023,41.97618372363071,0.44887321390069823,0.7334
1566.0156448771513,2.4417178159992887,41.97618372363071,0.44887321390069823,0.73484
1569.0156149637262,2.4483110135373884,41.97618372363071,0.44887321390069823,0.7361
1572.015585164473,2.4549042113264097,41.97618372363071,0.44887321390069823,0.73746
1575.0155554787389,2.4614974093649185,41.97618372363071,0.44887321390069823,0.73872
1578.0155259058765,2.4680906076514915,41.97618372363071,0.44887321390069823,0.74015
1581.0154964452436,2.4746838061847174,41.97618372363071,0.44887321390069823,0.74164
1584.0154670962024,2.4812770049631943,41.97618372363071,0.44887321390069823,0.74321
1587.0154378581199,2.487870203985531,41.97618372363071,0.44887321390069823,0.74472
1591.0153990455278,2.496661136392268,41.97618372363071,0.44887321390069823,0.74615
1593.0153797123241,2.5010566027562757,41.97618372363071,0.44887321390069823,0.74763
1597.0153411911858,2.5098475358035564,42.20189569201838,0.4459097260205074,0.74917
1598.0153315910334,2.5120452691315998,41.97618372363071,0.44887321390069823,0.75062
1602.015293310273,2.520836202707172,41.0,0.4616900293070062,0.75222
1605.0152647249183,2.5274294031640445,41.0,0.4616900293070062,0.75372
1608.015236246224,2.5340226038553304,41.23105625617661,0.4586563735389364,0.75524
1611.0152078735941,2.5406158047797196,41.23105625617661,0.4586563735389364,0.75674
1614.0111523778266,2.5472001550764056,41.0,0.4616900293070062,0.75838
1618.011124807243,2.5559911121903163,41.23105625617661,0.4586563735389364,0.75995
1620.0111110730074,2.5603865908594807,41.23105625617661,0.4586563735389364,0.76181
1623.01109053512,2.56697980900271,41.23105625617661,0.4586563735389364,0.76346
1626.0110700730177,2.5735730273124964,41.0,0.4616900293070062,0.76501
1628.0110564735119,2.5779685062777635,41.0,0.4616900293070062,0.76633
1632.015012185856,2.5867682176693623,41.23105625617661,0.4586563735389364,0.768
1635.0149846408135,2.5933614204125854,41.0,0.4616900293070062,0.76977
1639.0109822694906,2.6021436418905752,41.23105625617661,0.4586563735389364,0.77127
1640.0149389563499,2.6043500921434566,41.0,0.4616900293070062,0.77271
1644.014902608854,2.6131410299678697,41.0,0.4616900293070062,0.77431
1646.0148845013523,2.617536499025669,41.48493702538308,0.45532304306500826,0.77608
1649.0148574224552,2.624129702793365,40.024992192379,0.47449140551056473,0.77789
1652.0148304419063,2.6307229067772067,40.26164427839479,0.4713842792303795,0.77972
1656.0147946199031,2.6395138457565235,40.26164427839479,0.4713842792303795,0.78135
1658.0147767737174,2.6439093153886315,40.26164427839479,0.4713842792303795,0.78311
1660.0147589705339,2.6483047851152475,40.024992192379,0.47449140551056473,0.78477
1666.0147058174487,2.6614911948587436,40.26164427839479,0.4713842792303795,0.78614
1666.0147058174487,2.6614911948587436,40.26164427839479,0.4713842792303795,0.78737
1670.0146705942436,2.6702821351540718,41.23105625617661,0.4586563735389364,0.78864
1674.0146355393672,2.679073075819345,40.26164427839479,0.4713842792303795,0.78979
1676.0107398223915,2.6834600228437573,40.26164427839479,0.4713842792303795,0.79081
1679.0107206328373,2.6900532439502918,40.26164427839479,0.4713842792303795,0.79203
1682.0107015117353,2.6966464652072677,41.23105625617661,0.4586563735389364,0.79325
1685.0106824587197,2.7032396866138804,41.23105625617661,0.4586563735389364,0.79439
1689.0106571599838,2.7120306487207544,41.23105625617661,0.4586563735389364,0.79553
1691.0106445554977,2.716426129872831,41.23105625617661,0.4586563735389364,0.79679
1693.0106319807917,2.7208216110903565,40.26164427839479,0.4713842792303795,0.79801
1697.0106069202986,2.72961257372083,39.293765408777,0.48409205596058247,0.79944
1699.010594434302,2.734008055133317,40.26164427839479,0.4713842792303795,0.80095
1702.01439476874,2.740609670615614,39.56008088970496,0.4805954637963526,0.80225
1705.0143694409146,2.7472028782317355,40.26164427839479,0.4713842792303795,0.8037
1708.014344202062,2.7537960860433977,40.52159917870962,0.46797119838233125,0.80497
1712.0143106878518,2.762587030094677,40.26164427839479,0.4713842792303795,0.80632
1714.0142939894054,2.766982502249234,40.52159917870962,0.46797119838233125,0.80769
1718.014260709148,2.7757734468146835,40.52159917870962,0.46797119838233125,0.80923
1720.0142441270655,2.78016891922498,40.26164427839479,0.4713842792303795,0.81067
1724.0142110783195,2.788959864299235,40.52159917870962,0.46797119838233125,0.81205
1726.0141946113886,2.7933553369626063,40.52159917870962,0.46797119838233125,0.81363
1729.014169982421,2.799948546114646,40.52159917870962,0.46797119838233125,0.81539
1731.014153610536,2.8043440189869044,40.52159917870962,0.46797119838233125,0.81705
1735.0141209799995,2.8131349649802817,40.52159917870962,0.46797119838233125,0.81863
1738.0140966056633,2.8197281746919387,40.52159917870962,0.46797119838233125,0.82008
1740.0103447968347,2.8241154379911184,40.52159917870962,0.46797119838233125,0.82139
1743.0103269917824,2.8307086621404483,40.52159917870962,0.46797119838233125,0.82287
1746.010309247915,2.8373018864242474,39.293765408777,0.48409205596058247,0.82432
1749.0102915649181,2.843895110841825,39.84971769034255,0.4767926740972591,0.82573
1752.010273942479,2.8504883353924932,39.56008088970496,0.4805954637963526,0.82706
1755.0102563802868,2.85708156007557,39.84971769034255,0.4767926740972591,0.82832
1757.010244705477,2.8614770432708463,39.56008088970496,0.4805954637963526,0.82959
1761.013912494731,2.8702761218781987,39.84971769034255,0.4767926740972591,0.83086
1763.010209839977,2.874663493205964,39.56008088970496,0.4805954637963526,0.83221
1766.0101924960682,2.8812567183687734,39.84971769034255,0.4767926740972591,0.83369
1770.013841753787,2.8900557562483624,39.56008088970496,0.4805954637963526,0.83514
1773.010152255198,2.896640910916968,39.56008088970496,0.4805954637963526,0.83664
1775.0101408161024,2.9010363946302866,39.56008088970496,0.4805954637963526,0.83803
1778.0137794741636,2.9076376547876106,39.56008088970496,0.4805954637963526,0.83952
1781.01375626355,2.914230867056844,39.56008088970496,0.4805954637963526,0.841
1783.0137408331996,2.9186263419983645,39.56008088970496,0.4805954637963526,0.84239
1787.0137100761146,2.9274172921091277,39.84971769034255,0.4767926740972591,0.8439
1790.0136870985093,2.9340105048904563,39.56008088970496,0.4805954637963526,0.84524
1793.013664197794,2.9406037178407702,38.897300677553446,0.48929744420072285,0.84684
1795.013648973177,2.944999193234442,38.897300677553446,0.48929744420072285,0.84832
1799.0136186254956,2.953790144244974,38.897300677553446,0.48929744420072285,0.84993
1801.0099944197977,2.958177687984499,38.897300677553446,0.48929744420072285,0.85146
1804.0099777994578,2.9647709147375356,38.897300677553446,0.48929744420072285,0.85292
1807.0135583331964,2.9713720471518723,38.600518131237564,0.49319405404973493,0.85441
1810.0099447240614,2.977957368606861,38.600518131237564,0.49319405404973493,0.85587
1814.0099227953524,2.986748338120227,38.897300677553446,0.48929744420072285,0.85727
1816.0099118672233,2.9911438229565244,39.21734310225516,0.48509544351141326,0.85863
1819.0098955200876,2.997737050309997,39.21734310225516,0.48509544351141326,0.86005
1821.0098846519202,3.002132535278075,39.21734310225516,0.48509544351141326,0.86141
1826.0098575856593,3.013121247927184,39.21734310225516,0.48509544351141326,0.86296
1828.0098468006129,3.017516733077942,39.21734310225516,0.48509544351141326,0.86449
1832.0098253011636,3.026307703534715,38.897300677553446,0.48929744420072285,0.86599
1834.013358729974,3.0307109779971664,39.21734310225516,0.48509544351141326,0.86772
1836.0133441780863,3.0351064548693323,39.56008088970496,0.4805954637963526,0.86942
1839.0133224096012,3.04169967030801,38.897300677553446,0.48929744420072285,0.87108
1842.0133007120226,3.048292885902523,39.21734310225516,0.48509544351141326,0.87287
1845.0132790850043,3.05488610165211,38.897300677553446,0.48929744420072285,0.87481
1848.013257528203,3.0614793175560164,38.62641583165593,0.4928540298947781,0.87652
1852.0132288944374,3.0702702723333144,37.94733192202055,0.5017700698824343,0.87814
1854.0132146238873,3.074665749823791,38.27531841800928,0.49746376741796144,0.8797
1857.0131932756967,3.0812589661861733,37.94733192202055,0.5017700698824343,0.88108
1860.0131719963706,3.087852182699902,38.27531841800928,0.49746376741796144,0.88264
1862.0131578482467,3.0922476604594418,38.27531841800928,0.49746376741796144,0.88427
1866.013129642983,3.101038616178481,37.94733192202055,0.5017700698824343,0.88583
1868.0131155856482,3.105434094137553,38.27531841800928,0.49746376741796144,0.88717
1871.0130945559947,3.112027311200001,38.27531841800928,0.49746376741796144,0.88842
1874.0130735936716,3.118620528410425,38.27531841800928,0.49746376741796144,0.88951
1877.0095897464137,3.1252061350501537,38.27531841800928,0.49746376741796144,0.89102
1879.0095795391785,3.129601621470799,39.21734310225516,0.48509544351141326,0.89242
1883.0095591897561,3.138392594455049,39.21734310225516,0.48509544351141326,0.89383
1886.009543984335,3.1449858243177298,38.62641583165593,0.4928540298947781,0.89545
1888.0095338742333,3.14938131095185,38.62641583165593,0.4928540298947781,0.89719
1891.0095187491786,3.1559745409911564,38.27531841800928,0.49746376741796144,0.89875
1894.0095036720381,3.1625677711357665,38.62641583165593,0.4928540298947781,0.90027
1897.0094886425845,3.1691610013851803,38.897300677553446,0.48929744420072285,0.90177
1900.012894693086,3.1757617503282103,38.62641583165593,0.4928540298947781,0.90323
1902.0128811340894,3.180157229382507,38.62641583165593,0.4928540298947781,0.90458
1906.0128541014617,3.188948187678713,38.27531841800928,0.49746376741796144,0.90593
1908.0128406276515,3.193343666920228,38.62641583165593,0.4928540298947781,0.9072
1911.0128204698158,3.1999368858987176,38.62641583165593,0.4928540298947781,0.90871
1913.0128070663825,3.2043323652949045,38.27531841800928,0.49746376741796144,0.91021
1917.0127803434175,3.2131233242716726,38.62641583165593,0.4928540298947781,0.91165
1919.0127670237111,3.2175188038518705,38.27531841800928,0.49746376741796144,0.91308
1923.0127404674156,3.2263097631949376,38.62641583165593,0.4928540298947781,0.91439
1925.0127272306538,3.230705242957427,38.62641583165593,0.4928540298947781,0.91575
1927.0127140213683,3.235100722780303,38.62641583165593,0.4928540298947781,0.91705
1931.0126876848842,3.243891682606461,38.62641583165593,0.4928540298947781,0.91817
1933.0126745575158,3.248287162609371,38.62641583165593,0.4928540298947781,0.91957
1936.0126549173174,3.2548803827254997,38.62641583165593,0.4928540298947781,0.92096
1940.0126288248744,3.2636713430880007,38.62641583165593,0.4928540298947781,0.92232
1942.01261581896,3.2680668233578363,38.62641583165593,0.4928540298947781,0.92382
1945.0125963602395,3.2746600438728093,39.0,0.48794905226764007,0.92506
1947.0125834210728,3.27905552428934,39.0,0.48794905226764007,0.9264
1951.0125576223234,3.2878464852973073,38.62641583165593,0.4928540298947781,0.92756
1953.0092165681144,3.2922346513342706,39.0,0.48794905226764007,0.92894
1957.0091977300465,3.301025627640106,37.69615364994153,0.505067917889302,0.93014
1959.012506340886,3.3054284080078666,38.62641583165593,0.4928540298947781,0.93158
1961.0091789688288,3.30981660411484,38.07886552931954,0.5000430978753547,0.93278
1963.0124808569099,3.3142193697076285,38.07886552931954,0.5000430978753547,0.93403
1966.009155624663,3.3208053249442,38.07886552931954,0.5000430978753547,0.93555
1970.0091370346483,3.329596301795196,37.33630940518894,0.5097924970319071,0.93711
1972.0091277679219,3.333991790282848,38.07886552931954,0.5000430978753547,0.93869
1975.009113903022,3.3405850230916654,37.69615364994153,0.505067917889302,0.94004
1978.009100080179,3.347178255992913,37.69615364994153,0.505067917889302,0.94133
1981.0090862992022,3.3537714889861725,37.69615364994153,0.505067917889302,0.94278
1984.0123487518922,3.3603719223364767,37.69615364994153,0.505067917889302,0.94406
1987.0123301076922,3.366965144641566,37.69615364994153,0.505067917889302,0.94564
1989.0123177094706,3.371360626246961,37.69615364994153,0.505067917889302,0.94733
1992.012299158818,3.3779538487576444,37.69615364994153,0.505067917889302,0.94879
1995.0122806639563,3.384547071390942,37.69615364994153,0.505067917889302,0.9503
1998.012262224634,3.3911402941463025,37.69615364994153,0.505067917889302,0.95171
2000.0122499624847,3.395535776050751,37.69615364994153,0.505067917889302,0.95321
2003.0122316151742,3.40212899900833,37.69615364994153,0.505067917889302,0.95454
2006.0122133227405,3.4087222220865154,38.07886552931954,0.5000430978753547,0.95581
2009.0121950849377,3.4153154452847656,38.07886552931954,0.5000430978753547,0.95696
2011.0121829566324,3.4197109274833704,37.16180835212409,0.5120836106114495,0.95823
2013.0121708524268,3.4241064097349403,36.76955262170047,0.5172337367272665,0.95981
2016.008928551657,3.4306925472345324,37.69615364994153,0.505067917889302,0.96121
2020.0089108714346,3.4394835260850285,37.69615364994153,0.505067917889302,0.96269
2021.0089064623144,3.441681270821686,36.76955262170047,0.5172337367272665,0.96412
2024.0061758799059,3.448268532952572,37.69615364994153,0.505067917889302,0.96574
2028.0088757202222,3.457065484245862,36.76955262170047,0.5172337367272665,0.96734
2030.006157626129,3.461455019396177,37.69615364994153,0.505067917889302,0.96877
2032.0061515654918,3.4658505149300267,38.07886552931954,0.5000430978753547,0.97019
2034.006145516773,3.470246010490069,37.69615364994153,0.505067917889302,0.97166
2036.006139479938,3.47464150607623,37.69615364994153,0.505067917889302,0.97305
2039.00613044689,3.4812347495042713,37.16180835212409,0.5120836106114495,0.97453
2040.0039215648583,3.4834276493508285,38.07886552931954,0.5000430978753547,0.97599